{"_local_timestamp": "2026-01-25T23:33:16.896782+00:00", "data": [{"market": "0x22ac5f75af18fdb453497fbf7ac0606a09a6fd55b78b2d08aace6b946ad62038", "asset_id": "97449340182256366014320155718265676486703217567849039806162053075113517266910", "timestamp": "1769383983388", "hash": "342d24683a8dd817d154df76023f556b92d24a38", "bids": [{"price": "0.001", "size": "265.37"}, {"price": "0.002", "size": "81.25"}, {"price": "0.003", "size": "339.25"}, {"price": "0.004", "size": "21.39"}, {"price": "0.008", "size": "20.23"}, {"price": "0.009", "size": "133.06"}, {"price": "0.01", "size": "284.45"}, {"price": "0.011", "size": "198.88"}, {"price": "0.013", "size": "8.33"}, {"price": "0.02", "size": "283"}, {"price": "0.023", "size": "6.31"}, {"price": "0.024", "size": "139.3"}, {"price": "0.065", "size": "70"}], "asks": [{"price": "0.999", "size": "3641.69"}, {"price": "0.998", "size": "1250"}, {"price": "0.997", "size": "1406.75"}, {"price": "0.994", "size": "200"}, {"price": "0.993", "size": "15.91"}, {"price": "0.99", "size": "23"}, {"price": "0.989", "size": "21.36"}, {"price": "0.95", "size": "40"}, {"price": "0.91", "size": "400"}, {"price": "0.909", "size": "6.9"}, {"price": "0.86", "size": "242.85"}, {"price": "0.81", "size": "168.42"}, {"price": "0.8", "size": "5"}, {"price": "0.777", "size": "165"}, {"price": "0.77", "size": "121.73"}, {"price": "0.72", "size": "92.85"}, {"price": "0.67", "size": "72.72"}, {"price": "0.63", "size": "54.05"}, {"price": "0.5", "size": "22.72"}, {"price": "0.477", "size": "149"}, {"price": "0.47", "size": "900"}, {"price": "0.469", "size": "5"}, {"price": "0.38", "size": "25.2"}, {"price": "0.35", "size": "107.01"}, {"price": "0.277", "size": "89"}, {"price": "0.215", "size": "5"}, {"price": "0.177", "size": "189"}, {"price": "0.16", "size": "21.21"}, {"price": "0.089", "size": "47.14"}, {"price": "0.076", "size": "16.73"}, {"price": "0.075", "size": "108.9"}, {"price": "0.074", "size": "15.67"}, {"price": "0.07", "size": "254.35"}, {"price": "0.069", "size": "33"}], "event_type": "book", "last_trade_price": "0.931"}, {"market": "0x22ac5f75af18fdb453497fbf7ac0606a09a6fd55b78b2d08aace6b946ad62038", "asset_id": "59259495934562596318644973716893809974860301509869285036503555129962149752635", "timestamp": "1769383983388", "hash": "b961a0280260c4233b06c9942b731e8e11edc690", "bids": [{"price": "0.001", "size": "3641.69"}, {"price": "0.002", "size": "1250"}, {"price": "0.003", "size": "1406.75"}, {"price": "0.006", "size": "200"}, {"price": "0.007", "size": "15.91"}, {"price": "0.01", "size": "23"}, {"price": "0.011", "size": "21.36"}, {"price": "0.05", "size": "40"}, {"price": "0.09", "size": "400"}, {"price": "0.091", "size": "6.9"}, {"price": "0.14", "size": "242.85"}, {"price": "0.19", "size": "168.42"}, {"price": "0.2", "size": "5"}, {"price": "0.223", "size": "165"}, {"price": "0.23", "size": "121.73"}, {"price": "0.28", "size": "92.85"}, {"price": "0.33", "size": "72.72"}, {"price": "0.37", "size": "54.05"}, {"price": "0.5", "size": "22.72"}, {"price": "0.523", "size": "149"}, {"price": "0.53", "size": "900"}, {"price": "0.531", "size": "5"}, {"price": "0.62", "size": "25.2"}, {"price": "0.65", "size": "107.01"}, {"price": "0.723", "size": "89"}, {"price": "0.785", "size": "5"}, {"price": "0.823", "size": "189"}, {"price": "0.84", "size": "21.21"}, {"price": "0.911", "size": "47.14"}, {"price": "0.924", "size": "16.73"}, {"price": "0.925", "size": "108.9"}, {"price": "0.926", "size": "15.67"}, {"price": "0.93", "size": "254.35"}, {"price": "0.931", "size": "33"}], "asks": [{"price": "0.999", "size": "265.37"}, {"price": "0.998", "size": "81.25"}, {"price": "0.997", "size": "339.25"}, {"price": "0.996", "size": "21.39"}, {"price": "0.992", "size": "20.23"}, {"price": "0.991", "size": "133.06"}, {"price": "0.99", "size": "284.45"}, {"price": "0.989", "size": "198.88"}, {"price": "0.987", "size": "8.33"}, {"price": "0.98", "size": "283"}, {"price": "0.977", "size": "6.31"}, {"price": "0.976", "size": "139.3"}, {"price": "0.935", "size": "70"}], "event_type": "book", "last_trade_price": "0.931"}]}
{"_local_timestamp": "2026-01-25T23:33:22.117511+00:00", "data": {"market": "0x22ac5f75af18fdb453497fbf7ac0606a09a6fd55b78b2d08aace6b946ad62038", "price_changes": [{"asset_id": "97449340182256366014320155718265676486703217567849039806162053075113517266910", "price": "0.013", "size": "0", "side": "BUY", "hash": "bb6914b44bc9b14af5474c69ac2147f695debf6a", "best_bid": "0.065", "best_ask": "0.069"}, {"asset_id": "59259495934562596318644973716893809974860301509869285036503555129962149752635", "price": "0.987", "size": "0", "side": "SELL", "hash": "2796b9f2298d55b5d2774cd597246238aa6116e7", "best_bid": "0.931", "best_ask": "0.935"}], "timestamp": "1769384002006", "event_type": "price_change"}}
{"_local_timestamp": "2026-01-25T23:33:22.385468+00:00", "data": {"market": "0x22ac5f75af18fdb453497fbf7ac0606a09a6fd55b78b2d08aace6b946ad62038", "price_changes": [{"asset_id": "97449340182256366014320155718265676486703217567849039806162053075113517266910", "price": "0.025", "size": "22.23", "side": "BUY", "hash": "2f55fbae97ae35f7a3d92e4d640f0cb54acb461a", "best_bid": "0.065", "best_ask": "0.069"}, {"asset_id": "59259495934562596318644973716893809974860301509869285036503555129962149752635", "price": "0.975", "size": "22.23", "side": "SELL", "hash": "c1bfd0509d6d2d81949107941360382ad5339dc9", "best_bid": "0.931", "best_ask": "0.935"}], "timestamp": "1769384002318", "event_type": "price_change"}}
{"_local_timestamp": "2026-01-25T23:33:22.389488+00:00", "data": {"market": "0x22ac5f75af18fdb453497fbf7ac0606a09a6fd55b78b2d08aace6b946ad62038", "price_changes": [{"asset_id": "97449340182256366014320155718265676486703217567849039806162053075113517266910", "price": "0.009", "size": "138.32", "side": "BUY", "hash": "1b0f6f782cc6451c3668f032657ab3f6e11a0fe6", "best_bid": "0.065", "best_ask": "0.069"}, {"asset_id": "59259495934562596318644973716893809974860301509869285036503555129962149752635", "price": "0.991", "size": "138.32", "side": "SELL", "hash": "34d7873e7bfe848e8c6b0e4235f41ad67692e881", "best_bid": "0.931", "best_ask": "0.935"}], "timestamp": "1769384002320", "event_type": "price_change"}}
{"_local_timestamp": "2026-01-25T23:33:22.391290+00:00", "data": {"market": "0x22ac5f75af18fdb453497fbf7ac0606a09a6fd55b78b2d08aace6b946ad62038", "price_changes": [{"asset_id": "97449340182256366014320155718265676486703217567849039806162053075113517266910", "price": "0.012", "size": "16.44", "side": "BUY", "hash": "6bf244b190ba56730ebb1dc4a1e865e2b2e332dd", "best_bid": "0.065", "best_ask": "0.069"}, {"asset_id": "59259495934562596318644973716893809974860301509869285036503555129962149752635", "price": "0.988", "size": "16.44", "side": "SELL", "hash": "d2f1905ee7fba4bdb168bc0824c4c37d4122b834", "best_bid": "0.931", "best_ask": "0.935"}], "timestamp": "1769384002321", "event_type": "price_change"}}
{"_local_timestamp": "2026-01-25T23:33:22.691113+00:00", "data": {"market": "0x22ac5f75af18fdb453497fbf7ac0606a09a6fd55b78b2d08aace6b946ad62038", "price_changes": [{"asset_id": "59259495934562596318644973716893809974860301509869285036503555129962149752635", "price": "0.989", "size": "0", "side": "SELL", "hash": "600d2742e74424d55fc1e4d9fe8b45cc6e976ef4", "best_bid": "0.931", "best_ask": "0.935"}, {"asset_id": "97449340182256366014320155718265676486703217567849039806162053075113517266910", "price": "0.011", "size": "0", "side": "BUY", "hash": "b8f4b2f3ddf5a26a70c03cec5a29a308e87194da", "best_bid": "0.065", "best_ask": "0.069"}], "timestamp": "1769384002623", "event_type": "price_change"}}
{"_local_timestamp": "2026-01-25T23:33:22.938845+00:00", "data": {"market": "0x22ac5f75af18fdb453497fbf7ac0606a09a6fd55b78b2d08aace6b946ad62038", "price_changes": [{"asset_id": "59259495934562596318644973716893809974860301509869285036503555129962149752635", "price": "0.987", "size": "198.88", "side": "SELL", "hash": "48c305ceeccd43a7fb932e942d40ffa5e17233be", "best_bid": "0.931", "best_ask": "0.935"}, {"asset_id": "97449340182256366014320155718265676486703217567849039806162053075113517266910", "price": "0.013", "size": "198.88", "side": "BUY", "hash": "3301919263ff1be00c67f37a064ed11b68d2410d", "best_bid": "0.065", "best_ask": "0.069"}], "timestamp": "1769384002864", "event_type": "price_change"}}
{"_local_timestamp": "2026-01-25T23:33:23.914414+00:00", "data": {"market": "0x22ac5f75af18fdb453497fbf7ac0606a09a6fd55b78b2d08aace6b946ad62038", "price_changes": [{"asset_id": "97449340182256366014320155718265676486703217567849039806162053075113517266910", "price": "0.009", "size": "133.06", "side": "BUY", "hash": "e38f55228f880fea027e323ddc17b556eecc64b3", "best_bid": "0.065", "best_ask": "0.069"}, {"asset_id": "59259495934562596318644973716893809974860301509869285036503555129962149752635", "price": "0.991", "size": "133.06", "side": "SELL", "hash": "1b427e9991ae62d92bd3375f1e300716662837b1", "best_bid": "0.931", "best_ask": "0.935"}], "timestamp": "1769384003813", "event_type": "price_change"}}
{"_local_timestamp": "2026-01-25T23:33:23.914856+00:00", "data": {"market": "0x22ac5f75af18fdb453497fbf7ac0606a09a6fd55b78b2d08aace6b946ad62038", "price_changes": [{"asset_id": "97449340182256366014320155718265676486703217567849039806162053075113517266910", "price": "0.012", "size": "0", "side": "BUY", "hash": "e38f55228f880fea027e323ddc17b556eecc64b3", "best_bid": "0.065", "best_ask": "0.069"}, {"asset_id": "59259495934562596318644973716893809974860301509869285036503555129962149752635", "price": "0.988", "size": "0", "side": "SELL", "hash": "1b427e9991ae62d92bd3375f1e300716662837b1", "best_bid": "0.931", "best_ask": "0.935"}], "timestamp": "1769384003813", "event_type": "price_change"}}
{"_local_timestamp": "2026-01-25T23:33:24.268007+00:00", "data": {"market": "0x22ac5f75af18fdb453497fbf7ac0606a09a6fd55b78b2d08aace6b946ad62038", "price_changes": [{"asset_id": "97449340182256366014320155718265676486703217567849039806162053075113517266910", "price": "0.014", "size": "12.68", "side": "BUY", "hash": "99b03a107be10b3ecad2b7a6217e82c28713a88d", "best_bid": "0.065", "best_ask": "0.069"}, {"asset_id": "59259495934562596318644973716893809974860301509869285036503555129962149752635", "price": "0.986", "size": "12.68", "side": "SELL", "hash": "7ea9e7635b5ed006b05e16114b4f9fd401d24d53", "best_bid": "0.931", "best_ask": "0.935"}], "timestamp": "1769384004198", "event_type": "price_change"}}
{"_local_timestamp": "2026-01-25T23:33:24.281240+00:00", "data": {"market": "0x22ac5f75af18fdb453497fbf7ac0606a09a6fd55b78b2d08aace6b946ad62038", "price_changes": [{"asset_id": "97449340182256366014320155718265676486703217567849039806162053075113517266910", "price": "0.01", "size": "291.15", "side": "BUY", "hash": "06816c9b59ff6f390d6116cf1871f18f877d1be8", "best_bid": "0.065", "best_ask": "0.069"}, {"asset_id": "59259495934562596318644973716893809974860301509869285036503555129962149752635", "price": "0.99", "size": "291.15", "side": "SELL", "hash": "8825146b3436cb2a1e03227134eb7943af198bfb", "best_bid": "0.931", "best_ask": "0.935"}], "timestamp": "1769384004204", "event_type": "price_change"}}
{"_local_timestamp": "2026-01-25T23:33:24.437304+00:00", "data": {"market": "0x22ac5f75af18fdb453497fbf7ac0606a09a6fd55b78b2d08aace6b946ad62038", "price_changes": [{"asset_id": "59259495934562596318644973716893809974860301509869285036503555129962149752635", "price": "0.987", "size": "0", "side": "SELL", "hash": "dc343aefe984f465d8d9de681e8b183c0948cab8", "best_bid": "0.931", "best_ask": "0.935"}, {"asset_id": "97449340182256366014320155718265676486703217567849039806162053075113517266910", "price": "0.013", "size": "0", "side": "BUY", "hash": "3d128aa7b0fb5ed6db14e4ad32300e39ba2fc14a", "best_bid": "0.065", "best_ask": "0.069"}], "timestamp": "1769384004364", "event_type": "price_change"}}
{"_local_timestamp": "2026-01-25T23:33:24.747477+00:00", "data": {"market": "0x22ac5f75af18fdb453497fbf7ac0606a09a6fd55b78b2d08aace6b946ad62038", "price_changes": [{"asset_id": "97449340182256366014320155718265676486703217567849039806162053075113517266910", "price": "0.002", "size": "74.89", "side": "BUY", "hash": "e2d7f99c8e4766284e9e7d05e47e6a2504c8a6dc", "best_bid": "0.065", "best_ask": "0.069"}, {"asset_id": "59259495934562596318644973716893809974860301509869285036503555129962149752635", "price": "0.998", "size": "74.89", "side": "SELL", "hash": "1463e0491d55052aef3e7d9b062c3394c87221aa", "best_bid": "0.931", "best_ask": "0.935"}], "timestamp": "1769384004666", "event_type": "price_change"}}
{"_local_timestamp": "2026-01-25T23:33:24.791385+00:00", "data": {"market": "0x22ac5f75af18fdb453497fbf7ac0606a09a6fd55b78b2d08aace6b946ad62038", "price_changes": [{"asset_id": "59259495934562596318644973716893809974860301509869285036503555129962149752635", "price": "0.989", "size": "198.88", "side": "SELL", "hash": "e2e3d9829ffa7a131dd2b60e454deabf0e8be41e", "best_bid": "0.931", "best_ask": "0.935"}, {"asset_id": "97449340182256366014320155718265676486703217567849039806162053075113517266910", "price": "0.011", "size": "198.88", "side": "BUY", "hash": "fe58cb756778bf9dc21f4edf53df61419a134876", "best_bid": "0.065", "best_ask": "0.069"}], "timestamp": "1769384004724", "event_type": "price_change"}}
{"_local_timestamp": "2026-01-25T23:33:25.198630+00:00", "data": {"market": "0x22ac5f75af18fdb453497fbf7ac0606a09a6fd55b78b2d08aace6b946ad62038", "price_changes": [{"asset_id": "97449340182256366014320155718265676486703217567849039806162053075113517266910", "price": "0.011", "size": "204.58", "side": "BUY", "hash": "547675b29d0b9363a5251b07362cd64740276943", "best_bid": "0.065", "best_ask": "0.069"}, {"asset_id": "59259495934562596318644973716893809974860301509869285036503555129962149752635", "price": "0.989", "size": "204.58", "side": "SELL", "hash": "62efce55bea858395b99fde1e7b63bc00d9b3523", "best_bid": "0.931", "best_ask": "0.935"}], "timestamp": "1769384005124", "event_type": "price_change"}}
{"_local_timestamp": "2026-01-25T23:33:25.199183+00:00", "data": {"market": "0x22ac5f75af18fdb453497fbf7ac0606a09a6fd55b78b2d08aace6b946ad62038", "price_changes": [{"asset_id": "97449340182256366014320155718265676486703217567849039806162053075113517266910", "price": "0.015", "size": "11.08", "side": "BUY", "hash": "69538d06f867fd9df9f17caffd84fde400f6934c", "best_bid": "0.065", "best_ask": "0.069"}, {"asset_id": "59259495934562596318644973716893809974860301509869285036503555129962149752635", "price": "0.985", "size": "11.08", "side": "SELL", "hash": "a57948b3cdaaf28e8d3caf9d97c099be42f9ba87", "best_bid": "0.931", "best_ask": "0.935"}], "timestamp": "1769384005125", "event_type": "price_change"}}
{"_local_timestamp": "2026-01-25T23:33:25.199748+00:00", "data": {"market": "0x22ac5f75af18fdb453497fbf7ac0606a09a6fd55b78b2d08aace6b946ad62038", "price_changes": [{"asset_id": "97449340182256366014320155718265676486703217567849039806162053075113517266910", "price": "0.026", "size": "20.94", "side": "BUY", "hash": "9cc545c3cf84fdd512f385d7e615782a82923b7a", "best_bid": "0.065", "best_ask": "0.069"}, {"asset_id": "59259495934562596318644973716893809974860301509869285036503555129962149752635", "price": "0.974", "size": "20.94", "side": "SELL", "hash": "ec8034670ee2bb3b54c09f85539f8e2cc39f003e", "best_bid": "0.931", "best_ask": "0.935"}], "timestamp": "1769384005126", "event_type": "price_change"}}
{"_local_timestamp": "2026-01-25T23:33:25.201827+00:00", "data": {"market": "0x22ac5f75af18fdb453497fbf7ac0606a09a6fd55b78b2d08aace6b946ad62038", "price_changes": [{"asset_id": "97449340182256366014320155718265676486703217567849039806162053075113517266910", "price": "0.004", "size": "28.07", "side": "BUY", "hash": "40d3a59d3c1f73aff1889e417b9dd5e9d8949788", "best_bid": "0.065", "best_ask": "0.069"}, {"asset_id": "59259495934562596318644973716893809974860301509869285036503555129962149752635", "price": "0.996", "size": "28.07", "side": "SELL", "hash": "b7d79c9a7d95744e166d361e319e032764efd770", "best_bid": "0.931", "best_ask": "0.935"}], "timestamp": "1769384005128", "event_type": "price_change"}}
{"_local_timestamp": "2026-01-25T23:33:25.675216+00:00", "data": {"market": "0x22ac5f75af18fdb453497fbf7ac0606a09a6fd55b78b2d08aace6b946ad62038", "price_changes": [{"asset_id": "59259495934562596318644973716893809974860301509869285036503555129962149752635", "price": "0.989", "size": "5.7", "side": "SELL", "hash": "1622265c47b9cdfb842c57af7dad468a00ea5ef8", "best_bid": "0.931", "best_ask": "0.935"}, {"asset_id": "97449340182256366014320155718265676486703217567849039806162053075113517266910", "price": "0.011", "size": "5.7", "side": "BUY", "hash": "04092eefd1d04c255a7f5dd952367bf3c4cee335", "best_bid": "0.065", "best_ask": "0.069"}], "timestamp": "1769384005607", "event_type": "price_change"}}
{"_local_timestamp": "2026-01-25T23:33:26.108635+00:00", "data": {"market": "0x22ac5f75af18fdb453497fbf7ac0606a09a6fd55b78b2d08aace6b946ad62038", "price_changes": [{"asset_id": "59259495934562596318644973716893809974860301509869285036503555129962149752635", "price": "0.988", "size": "198.88", "side": "SELL", "hash": "f967ee90dba5adfc8c71ce21581b567bd497190a", "best_bid": "0.931", "best_ask": "0.935"}, {"asset_id": "97449340182256366014320155718265676486703217567849039806162053075113517266910", "price": "0.012", "size": "198.88", "side": "BUY", "hash": "0b909693822abfbc22d51cd2099af948fb07044d", "best_bid": "0.065", "best_ask": "0.069"}], "timestamp": "1769384006039", "event_type": "price_change"}}
{"_local_timestamp": "2026-01-25T23:33:48.282024+00:00", "data": {"market": "0x22ac5f75af18fdb453497fbf7ac0606a09a6fd55b78b2d08aace6b946ad62038", "price_changes": [{"asset_id": "97449340182256366014320155718265676486703217567849039806162053075113517266910", "price": "0.004", "size": "0", "side": "BUY", "hash": "3b53a8b100cb035d5fb100b8af4a67509a966e2a", "best_bid": "0.065", "best_ask": "0.069"}, {"asset_id": "59259495934562596318644973716893809974860301509869285036503555129962149752635", "price": "0.996", "size": "0", "side": "SELL", "hash": "5a35c63c7d807d16eff3dd0058345a51f646870b", "best_bid": "0.931", "best_ask": "0.935"}], "timestamp": "1769384028206", "event_type": "price_change"}}
{"_local_timestamp": "2026-01-25T23:33:48.283927+00:00", "data": {"market": "0x22ac5f75af18fdb453497fbf7ac0606a09a6fd55b78b2d08aace6b946ad62038", "price_changes": [{"asset_id": "97449340182256366014320155718265676486703217567849039806162053075113517266910", "price": "0.026", "size": "0", "side": "BUY", "hash": "3b53a8b100cb035d5fb100b8af4a67509a966e2a", "best_bid": "0.065", "best_ask": "0.069"}, {"asset_id": "59259495934562596318644973716893809974860301509869285036503555129962149752635", "price": "0.974", "size": "0", "side": "SELL", "hash": "5a35c63c7d807d16eff3dd0058345a51f646870b", "best_bid": "0.931", "best_ask": "0.935"}], "timestamp": "1769384028206", "event_type": "price_change"}}
{"_local_timestamp": "2026-01-25T23:33:48.284352+00:00", "data": {"market": "0x22ac5f75af18fdb453497fbf7ac0606a09a6fd55b78b2d08aace6b946ad62038", "price_changes": [{"asset_id": "97449340182256366014320155718265676486703217567849039806162053075113517266910", "price": "0.015", "size": "0", "side": "BUY", "hash": "3b53a8b100cb035d5fb100b8af4a67509a966e2a", "best_bid": "0.065", "best_ask": "0.069"}, {"asset_id": "59259495934562596318644973716893809974860301509869285036503555129962149752635", "price": "0.985", "size": "0", "side": "SELL", "hash": "5a35c63c7d807d16eff3dd0058345a51f646870b", "best_bid": "0.931", "best_ask": "0.935"}], "timestamp": "1769384028206", "event_type": "price_change"}}
{"_local_timestamp": "2026-01-25T23:33:48.284723+00:00", "data": {"market": "0x22ac5f75af18fdb453497fbf7ac0606a09a6fd55b78b2d08aace6b946ad62038", "price_changes": [{"asset_id": "97449340182256366014320155718265676486703217567849039806162053075113517266910", "price": "0.011", "size": "0", "side": "BUY", "hash": "3b53a8b100cb035d5fb100b8af4a67509a966e2a", "best_bid": "0.065", "best_ask": "0.069"}, {"asset_id": "59259495934562596318644973716893809974860301509869285036503555129962149752635", "price": "0.989", "size": "0", "side": "SELL", "hash": "5a35c63c7d807d16eff3dd0058345a51f646870b", "best_bid": "0.931", "best_ask": "0.935"}], "timestamp": "1769384028206", "event_type": "price_change"}}
{"_local_timestamp": "2026-01-25T23:33:48.285092+00:00", "data": {"market": "0x22ac5f75af18fdb453497fbf7ac0606a09a6fd55b78b2d08aace6b946ad62038", "price_changes": [{"asset_id": "97449340182256366014320155718265676486703217567849039806162053075113517266910", "price": "0.01", "size": "284.45", "side": "BUY", "hash": "3b53a8b100cb035d5fb100b8af4a67509a966e2a", "best_bid": "0.065", "best_ask": "0.069"}, {"asset_id": "59259495934562596318644973716893809974860301509869285036503555129962149752635", "price": "0.99", "size": "284.45", "side": "SELL", "hash": "5a35c63c7d807d16eff3dd0058345a51f646870b", "best_bid": "0.931", "best_ask": "0.935"}], "timestamp": "1769384028206", "event_type": "price_change"}}
{"_local_timestamp": "2026-01-25T23:33:48.285467+00:00", "data": {"market": "0x22ac5f75af18fdb453497fbf7ac0606a09a6fd55b78b2d08aace6b946ad62038", "price_changes": [{"asset_id": "97449340182256366014320155718265676486703217567849039806162053075113517266910", "price": "0.014", "size": "0", "side": "BUY", "hash": "3b53a8b100cb035d5fb100b8af4a67509a966e2a", "best_bid": "0.065", "best_ask": "0.069"}, {"asset_id": "59259495934562596318644973716893809974860301509869285036503555129962149752635", "price": "0.986", "size": "0", "side": "SELL", "hash": "5a35c63c7d807d16eff3dd0058345a51f646870b", "best_bid": "0.931", "best_ask": "0.935"}], "timestamp": "1769384028206", "event_type": "price_change"}}
{"_local_timestamp": "2026-01-25T23:33:48.285804+00:00", "data": {"market": "0x22ac5f75af18fdb453497fbf7ac0606a09a6fd55b78b2d08aace6b946ad62038", "price_changes": [{"asset_id": "97449340182256366014320155718265676486703217567849039806162053075113517266910", "price": "0.025", "size": "0", "side": "BUY", "hash": "3b53a8b100cb035d5fb100b8af4a67509a966e2a", "best_bid": "0.065", "best_ask": "0.069"}, {"asset_id": "59259495934562596318644973716893809974860301509869285036503555129962149752635", "price": "0.975", "size": "0", "side": "SELL", "hash": "5a35c63c7d807d16eff3dd0058345a51f646870b", "best_bid": "0.931", "best_ask": "0.935"}], "timestamp": "1769384028206", "event_type": "price_change"}}
{"_local_timestamp": "2026-01-25T23:33:48.286134+00:00", "data": {"market": "0x22ac5f75af18fdb453497fbf7ac0606a09a6fd55b78b2d08aace6b946ad62038", "price_changes": [{"asset_id": "97449340182256366014320155718265676486703217567849039806162053075113517266910", "price": "0.002", "size": "64.41", "side": "BUY", "hash": "3b53a8b100cb035d5fb100b8af4a67509a966e2a", "best_bid": "0.065", "best_ask": "0.069"}, {"asset_id": "59259495934562596318644973716893809974860301509869285036503555129962149752635", "price": "0.998", "size": "64.41", "side": "SELL", "hash": "5a35c63c7d807d16eff3dd0058345a51f646870b", "best_bid": "0.931", "best_ask": "0.935"}], "timestamp": "1769384028206", "event_type": "price_change"}}
{"_local_timestamp": "2026-01-25T23:33:48.286455+00:00", "data": {"market": "0x22ac5f75af18fdb453497fbf7ac0606a09a6fd55b78b2d08aace6b946ad62038", "price_changes": [{"asset_id": "97449340182256366014320155718265676486703217567849039806162053075113517266910", "price": "0.003", "size": "332", "side": "BUY", "hash": "3b53a8b100cb035d5fb100b8af4a67509a966e2a", "best_bid": "0.065", "best_ask": "0.069"}, {"asset_id": "59259495934562596318644973716893809974860301509869285036503555129962149752635", "price": "0.997", "size": "332", "side": "SELL", "hash": "5a35c63c7d807d16eff3dd0058345a51f646870b", "best_bid": "0.931", "best_ask": "0.935"}], "timestamp": "1769384028206", "event_type": "price_change"}}
{"_local_timestamp": "2026-01-25T23:33:50.517664+00:00", "data": {"market": "0x22ac5f75af18fdb453497fbf7ac0606a09a6fd55b78b2d08aace6b946ad62038", "price_changes": [{"asset_id": "59259495934562596318644973716893809974860301509869285036503555129962149752635", "price": "0.988", "size": "0", "side": "SELL", "hash": "c65c5b29542a55a56b050790d25cc56de903a8d2", "best_bid": "0.931", "best_ask": "0.935"}, {"asset_id": "97449340182256366014320155718265676486703217567849039806162053075113517266910", "price": "0.012", "size": "0", "side": "BUY", "hash": "a48e3a7b4a6031a048fd678961628e417d415300", "best_bid": "0.065", "best_ask": "0.069"}], "timestamp": "1769384030449", "event_type": "price_change"}}
{"_local_timestamp": "2026-01-25T23:33:52.142773+00:00", "data": {"market": "0x22ac5f75af18fdb453497fbf7ac0606a09a6fd55b78b2d08aace6b946ad62038", "price_changes": [{"asset_id": "97449340182256366014320155718265676486703217567849039806162053075113517266910", "price": "0.003", "size": "337.54", "side": "BUY", "hash": "92e41edab33b881ff20728595fb38b6d957c9464", "best_bid": "0.065", "best_ask": "0.069"}, {"asset_id": "59259495934562596318644973716893809974860301509869285036503555129962149752635", "price": "0.997", "size": "337.54", "side": "SELL", "hash": "a6af9ff3a735be30eb32de60ff8adbbefef93141", "best_bid": "0.931", "best_ask": "0.935"}], "timestamp": "1769384032062", "event_type": "price_change"}}
{"_local_timestamp": "2026-01-25T23:33:52.143979+00:00", "data": {"market": "0x22ac5f75af18fdb453497fbf7ac0606a09a6fd55b78b2d08aace6b946ad62038", "price_changes": [{"asset_id": "97449340182256366014320155718265676486703217567849039806162053075113517266910", "price": "0.002", "size": "72.76", "side": "BUY", "hash": "8c06ac7a7f6a1d0949ead0ecdc8db1d1d28a3c8d", "best_bid": "0.065", "best_ask": "0.069"}, {"asset_id": "59259495934562596318644973716893809974860301509869285036503555129962149752635", "price": "0.998", "size": "72.76", "side": "SELL", "hash": "139d63505c8ebfb6cc4af7101cd74f4b3adca278", "best_bid": "0.931", "best_ask": "0.935"}], "timestamp": "1769384032063", "event_type": "price_change"}}
{"_local_timestamp": "2026-01-25T23:33:53.005410+00:00", "data": {"market": "0x22ac5f75af18fdb453497fbf7ac0606a09a6fd55b78b2d08aace6b946ad62038", "price_changes": [{"asset_id": "97449340182256366014320155718265676486703217567849039806162053075113517266910", "price": "0.011", "size": "5.76", "side": "BUY", "hash": "4e48e63024cc50c8310c9e0646effdbede8ffb3b", "best_bid": "0.065", "best_ask": "0.069"}, {"asset_id": "59259495934562596318644973716893809974860301509869285036503555129962149752635", "price": "0.989", "size": "5.76", "side": "SELL", "hash": "022fef5bdf39082ab9a2129e03aa5d8f02977a0c", "best_bid": "0.931", "best_ask": "0.935"}], "timestamp": "1769384032920", "event_type": "price_change"}}
{"_local_timestamp": "2026-01-25T23:33:53.008143+00:00", "data": {"market": "0x22ac5f75af18fdb453497fbf7ac0606a09a6fd55b78b2d08aace6b946ad62038", "price_changes": [{"asset_id": "97449340182256366014320155718265676486703217567849039806162053075113517266910", "price": "0.004", "size": "28.52", "side": "BUY", "hash": "8130fee26b9c6a858997d0893790a87fd89c947b", "best_bid": "0.065", "best_ask": "0.069"}, {"asset_id": "59259495934562596318644973716893809974860301509869285036503555129962149752635", "price": "0.996", "size": "28.52", "side": "SELL", "hash": "eaf8a5793583684137279b273974bd17e64c3d28", "best_bid": "0.931", "best_ask": "0.935"}], "timestamp": "1769384032921", "event_type": "price_change"}}
{"_local_timestamp": "2026-01-25T23:33:53.009416+00:00", "data": {"market": "0x22ac5f75af18fdb453497fbf7ac0606a09a6fd55b78b2d08aace6b946ad62038", "price_changes": [{"asset_id": "97449340182256366014320155718265676486703217567849039806162053075113517266910", "price": "0.026", "size": "21.15", "side": "BUY", "hash": "9540af8e055336a43baf4c40bda80d174418756e", "best_bid": "0.065", "best_ask": "0.069"}, {"asset_id": "59259495934562596318644973716893809974860301509869285036503555129962149752635", "price": "0.974", "size": "21.15", "side": "SELL", "hash": "304d868164504ae2d9768c0f8d6faeb13bb157ca", "best_bid": "0.931", "best_ask": "0.935"}], "timestamp": "1769384032922", "event_type": "price_change"}}
{"_local_timestamp": "2026-01-25T23:33:53.009852+00:00", "data": {"market": "0x22ac5f75af18fdb453497fbf7ac0606a09a6fd55b78b2d08aace6b946ad62038", "price_changes": [{"asset_id": "97449340182256366014320155718265676486703217567849039806162053075113517266910", "price": "0.015", "size": "11.19", "side": "BUY", "hash": "bf9ddc4f75adedd7cf6a346a5d78e2d0771a0a99", "best_bid": "0.065", "best_ask": "0.069"}, {"asset_id": "59259495934562596318644973716893809974860301509869285036503555129962149752635", "price": "0.985", "size": "11.19", "side": "SELL", "hash": "9666de6303ea7ad0dc59049fa2e4f37e1bd38fee", "best_bid": "0.931", "best_ask": "0.935"}], "timestamp": "1769384032923", "event_type": "price_change"}}
{"_local_timestamp": "2026-01-25T23:33:53.717556+00:00", "data": {"market": "0x22ac5f75af18fdb453497fbf7ac0606a09a6fd55b78b2d08aace6b946ad62038", "price_changes": [{"asset_id": "59259495934562596318644973716893809974860301509869285036503555129962149752635", "price": "0.989", "size": "204.64", "side": "SELL", "hash": "9c3b572d4a6cfe24f241fb66a97e922132a5c81f", "best_bid": "0.931", "best_ask": "0.935"}, {"asset_id": "97449340182256366014320155718265676486703217567849039806162053075113517266910", "price": "0.011", "size": "204.64", "side": "BUY", "hash": "e5f399839949b0cf22b36065f0fe40ab4223c7c6", "best_bid": "0.065", "best_ask": "0.069"}], "timestamp": "1769384033651", "event_type": "price_change"}}
{"_local_timestamp": "2026-01-25T23:33:56.383916+00:00", "data": {"market": "0x22ac5f75af18fdb453497fbf7ac0606a09a6fd55b78b2d08aace6b946ad62038", "price_changes": [{"asset_id": "59259495934562596318644973716893809974860301509869285036503555129962149752635", "price": "0.989", "size": "5.76", "side": "SELL", "hash": "75db5986895ceedaa65b33414521a88bfcac64ce", "best_bid": "0.931", "best_ask": "0.935"}, {"asset_id": "97449340182256366014320155718265676486703217567849039806162053075113517266910", "price": "0.011", "size": "5.76", "side": "BUY", "hash": "e0e427a861b9a1b45e64fee85be9d1525e4dac1a", "best_bid": "0.065", "best_ask": "0.069"}], "timestamp": "1769384036316", "event_type": "price_change"}}
{"_local_timestamp": "2026-01-25T23:33:59.337746+00:00", "data": {"market": "0x22ac5f75af18fdb453497fbf7ac0606a09a6fd55b78b2d08aace6b946ad62038", "price_changes": [{"asset_id": "59259495934562596318644973716893809974860301509869285036503555129962149752635", "price": "0.988", "size": "198.88", "side": "SELL", "hash": "541b640d28b97ac53116e4f3207812db06a3e1e9", "best_bid": "0.931", "best_ask": "0.935"}, {"asset_id": "97449340182256366014320155718265676486703217567849039806162053075113517266910", "price": "0.012", "size": "198.88", "side": "BUY", "hash": "6e169b7613822b34eeb8a5de75b8fd953961dd19", "best_bid": "0.065", "best_ask": "0.069"}], "timestamp": "1769384039261", "event_type": "price_change"}}
{"_local_timestamp": "2026-01-25T23:33:59.804761+00:00", "data": {"market": "0x22ac5f75af18fdb453497fbf7ac0606a09a6fd55b78b2d08aace6b946ad62038", "price_changes": [{"asset_id": "59259495934562596318644973716893809974860301509869285036503555129962149752635", "price": "0.785", "size": "0", "side": "BUY", "hash": "051fb3d3e912f2690043ea01d82e240ab34e1413", "best_bid": "0.931", "best_ask": "0.935"}, {"asset_id": "97449340182256366014320155718265676486703217567849039806162053075113517266910", "price": "0.215", "size": "0", "side": "SELL", "hash": "66b384d8fe41ccbd9adfa05690bee88505c2d21e", "best_bid": "0.065", "best_ask": "0.069"}], "timestamp": "1769384039731", "event_type": "price_change"}}
{"_local_timestamp": "2026-01-25T23:34:01.194685+00:00", "data": {"market": "0x22ac5f75af18fdb453497fbf7ac0606a09a6fd55b78b2d08aace6b946ad62038", "price_changes": [{"asset_id": "59259495934562596318644973716893809974860301509869285036503555129962149752635", "price": "0.785", "size": "5", "side": "BUY", "hash": "cb590cc8bfe56d347b2557bb3e4c01aa97d4f9a3", "best_bid": "0.931", "best_ask": "0.935"}, {"asset_id": "97449340182256366014320155718265676486703217567849039806162053075113517266910", "price": "0.215", "size": "5", "side": "SELL", "hash": "b4d322bfebc0cc98546fc975f943daa34ed4b564", "best_bid": "0.065", "best_ask": "0.069"}], "timestamp": "1769384041120", "event_type": "price_change"}}
{"_local_timestamp": "2026-01-25T23:36:02.683525+00:00", "data": {"market": "0x22ac5f75af18fdb453497fbf7ac0606a09a6fd55b78b2d08aace6b946ad62038", "price_changes": [{"asset_id": "97449340182256366014320155718265676486703217567849039806162053075113517266910", "price": "0.004", "size": "0", "side": "BUY", "hash": "6098e49f5b624c7201723e943f3427dc6e513c86", "best_bid": "0.065", "best_ask": "0.069"}, {"asset_id": "59259495934562596318644973716893809974860301509869285036503555129962149752635", "price": "0.996", "size": "0", "side": "SELL", "hash": "5d67b44a62d779f5fdd64e3c4048e28d5d61f53c", "best_bid": "0.931", "best_ask": "0.935"}], "timestamp": "1769384162577", "event_type": "price_change"}}
{"_local_timestamp": "2026-01-25T23:36:02.685952+00:00", "data": {"market": "0x22ac5f75af18fdb453497fbf7ac0606a09a6fd55b78b2d08aace6b946ad62038", "price_changes": [{"asset_id": "97449340182256366014320155718265676486703217567849039806162053075113517266910", "price": "0.011", "size": "0", "side": "BUY", "hash": "6098e49f5b624c7201723e943f3427dc6e513c86", "best_bid": "0.065", "best_ask": "0.069"}, {"asset_id": "59259495934562596318644973716893809974860301509869285036503555129962149752635", "price": "0.989", "size": "0", "side": "SELL", "hash": "5d67b44a62d779f5fdd64e3c4048e28d5d61f53c", "best_bid": "0.931", "best_ask": "0.935"}], "timestamp": "1769384162577", "event_type": "price_change"}}
{"_local_timestamp": "2026-01-25T23:36:02.686588+00:00", "data": {"market": "0x22ac5f75af18fdb453497fbf7ac0606a09a6fd55b78b2d08aace6b946ad62038", "price_changes": [{"asset_id": "97449340182256366014320155718265676486703217567849039806162053075113517266910", "price": "0.015", "size": "0", "side": "BUY", "hash": "6098e49f5b624c7201723e943f3427dc6e513c86", "best_bid": "0.065", "best_ask": "0.069"}, {"asset_id": "59259495934562596318644973716893809974860301509869285036503555129962149752635", "price": "0.985", "size": "0", "side": "SELL", "hash": "5d67b44a62d779f5fdd64e3c4048e28d5d61f53c", "best_bid": "0.931", "best_ask": "0.935"}], "timestamp": "1769384162577", "event_type": "price_change"}}
{"_local_timestamp": "2026-01-25T23:36:02.687027+00:00", "data": {"market": "0x22ac5f75af18fdb453497fbf7ac0606a09a6fd55b78b2d08aace6b946ad62038", "price_changes": [{"asset_id": "97449340182256366014320155718265676486703217567849039806162053075113517266910", "price": "0.026", "size": "0", "side": "BUY", "hash": "6098e49f5b624c7201723e943f3427dc6e513c86", "best_bid": "0.065", "best_ask": "0.069"}, {"asset_id": "59259495934562596318644973716893809974860301509869285036503555129962149752635", "price": "0.974", "size": "0", "side": "SELL", "hash": "5d67b44a62d779f5fdd64e3c4048e28d5d61f53c", "best_bid": "0.931", "best_ask": "0.935"}], "timestamp": "1769384162577", "event_type": "price_change"}}
{"_local_timestamp": "2026-01-25T23:36:03.296648+00:00", "data": {"market": "0x22ac5f75af18fdb453497fbf7ac0606a09a6fd55b78b2d08aace6b946ad62038", "price_changes": [{"asset_id": "97449340182256366014320155718265676486703217567849039806162053075113517266910", "price": "0.003", "size": "342.96", "side": "BUY", "hash": "d84e3501273552d5aa38a566019dfced4195fd8a", "best_bid": "0.065", "best_ask": "0.069"}, {"asset_id": "59259495934562596318644973716893809974860301509869285036503555129962149752635", "price": "0.997", "size": "342.96", "side": "SELL", "hash": "ad0baf9ef26e569ce30a82833fc7577993fa0981", "best_bid": "0.931", "best_ask": "0.935"}], "timestamp": "1769384163206", "event_type": "price_change"}}
{"_local_timestamp": "2026-01-25T23:36:03.297284+00:00", "data": {"market": "0x22ac5f75af18fdb453497fbf7ac0606a09a6fd55b78b2d08aace6b946ad62038", "price_changes": [{"asset_id": "97449340182256366014320155718265676486703217567849039806162053075113517266910", "price": "0.027", "size": "19.82", "side": "BUY", "hash": "5cae6728dc77f99b3c45d33be99a7b64d317d7e6", "best_bid": "0.065", "best_ask": "0.069"}, {"asset_id": "59259495934562596318644973716893809974860301509869285036503555129962149752635", "price": "0.973", "size": "19.82", "side": "SELL", "hash": "2ad3c2e72afc597761123e1c1e2c835375ff80cf", "best_bid": "0.931", "best_ask": "0.935"}], "timestamp": "1769384163209", "event_type": "price_change"}}
{"_local_timestamp": "2026-01-25T23:36:03.299828+00:00", "data": {"market": "0x22ac5f75af18fdb453497fbf7ac0606a09a6fd55b78b2d08aace6b946ad62038", "price_changes": [{"asset_id": "97449340182256366014320155718265676486703217567849039806162053075113517266910", "price": "0.005", "size": "13.07", "side": "BUY", "hash": "4426d234235b66d8bc5733df2b659492dfb8367f", "best_bid": "0.065", "best_ask": "0.069"}, {"asset_id": "59259495934562596318644973716893809974860301509869285036503555129962149752635", "price": "0.995", "size": "13.07", "side": "SELL", "hash": "f2f509dfeda7f0899f9836bcbc303dab0e81ef48", "best_bid": "0.931", "best_ask": "0.935"}], "timestamp": "1769384163214", "event_type": "price_change"}}
{"_local_timestamp": "2026-01-25T23:36:03.300986+00:00", "data": {"market": "0x22ac5f75af18fdb453497fbf7ac0606a09a6fd55b78b2d08aace6b946ad62038", "price_changes": [{"asset_id": "97449340182256366014320155718265676486703217567849039806162053075113517266910", "price": "0.016", "size": "10.44", "side": "BUY", "hash": "c42b362b33afa6dcb1849f7d0231ec3cfa8a9a20", "best_bid": "0.065", "best_ask": "0.069"}, {"asset_id": "59259495934562596318644973716893809974860301509869285036503555129962149752635", "price": "0.984", "size": "10.44", "side": "SELL", "hash": "2e4dafc19ccbcd9886aa687ca1f881370c083116", "best_bid": "0.931", "best_ask": "0.935"}], "timestamp": "1769384163218", "event_type": "price_change"}}
{"_local_timestamp": "2026-01-25T23:36:03.321703+00:00", "data": {"market": "0x22ac5f75af18fdb453497fbf7ac0606a09a6fd55b78b2d08aace6b946ad62038", "price_changes": [{"asset_id": "97449340182256366014320155718265676486703217567849039806162053075113517266910", "price": "0.009", "size": "138.41", "side": "BUY", "hash": "195a4800c5e7bf1ed26bbdc2b96aa2cfd863bfbd", "best_bid": "0.065", "best_ask": "0.069"}, {"asset_id": "59259495934562596318644973716893809974860301509869285036503555129962149752635", "price": "0.991", "size": "138.41", "side": "SELL", "hash": "e58f680be68ddaa8f49ebaa645dee9477dd66590", "best_bid": "0.931", "best_ask": "0.935"}], "timestamp": "1769384163222", "event_type": "price_change"}}
{"_local_timestamp": "2026-01-25T23:36:03.322198+00:00", "data": {"market": "0x22ac5f75af18fdb453497fbf7ac0606a09a6fd55b78b2d08aace6b946ad62038", "price_changes": [{"asset_id": "97449340182256366014320155718265676486703217567849039806162053075113517266910", "price": "0.012", "size": "204.13", "side": "BUY", "hash": "a757475371bbe44bd9d25e2c197eeaf8f372f6a8", "best_bid": "0.065", "best_ask": "0.069"}, {"asset_id": "59259495934562596318644973716893809974860301509869285036503555129962149752635", "price": "0.988", "size": "204.13", "side": "SELL", "hash": "08c3c4e7d45e22edb28d1c8108665ac8d7edbf5f", "best_bid": "0.931", "best_ask": "0.935"}], "timestamp": "1769384163225", "event_type": "price_change"}}
{"_local_timestamp": "2026-01-25T23:36:04.655590+00:00", "data": {"market": "0x22ac5f75af18fdb453497fbf7ac0606a09a6fd55b78b2d08aace6b946ad62038", "price_changes": [{"asset_id": "97449340182256366014320155718265676486703217567849039806162053075113517266910", "price": "0.003", "size": "337.42", "side": "BUY", "hash": "e2079c909ad4b6400d7b84849847fabbbfc6b8ba", "best_bid": "0.065", "best_ask": "0.069"}, {"asset_id": "59259495934562596318644973716893809974860301509869285036503555129962149752635", "price": "0.997", "size": "337.42", "side": "SELL", "hash": "6aa9611f260821600dd339b59a12ffacbc98d5b7", "best_bid": "0.931", "best_ask": "0.935"}], "timestamp": "1769384164585", "event_type": "price_change"}}
{"_local_timestamp": "2026-01-25T23:36:04.656183+00:00", "data": {"market": "0x22ac5f75af18fdb453497fbf7ac0606a09a6fd55b78b2d08aace6b946ad62038", "price_changes": [{"asset_id": "97449340182256366014320155718265676486703217567849039806162053075113517266910", "price": "0.005", "size": "0", "side": "BUY", "hash": "e2079c909ad4b6400d7b84849847fabbbfc6b8ba", "best_bid": "0.065", "best_ask": "0.069"}, {"asset_id": "59259495934562596318644973716893809974860301509869285036503555129962149752635", "price": "0.995", "size": "0", "side": "SELL", "hash": "6aa9611f260821600dd339b59a12ffacbc98d5b7", "best_bid": "0.931", "best_ask": "0.935"}], "timestamp": "1769384164585", "event_type": "price_change"}}
{"_local_timestamp": "2026-01-25T23:36:04.656613+00:00", "data": {"market": "0x22ac5f75af18fdb453497fbf7ac0606a09a6fd55b78b2d08aace6b946ad62038", "price_changes": [{"asset_id": "97449340182256366014320155718265676486703217567849039806162053075113517266910", "price": "0.012", "size": "198.88", "side": "BUY", "hash": "e2079c909ad4b6400d7b84849847fabbbfc6b8ba", "best_bid": "0.065", "best_ask": "0.069"}, {"asset_id": "59259495934562596318644973716893809974860301509869285036503555129962149752635", "price": "0.988", "size": "198.88", "side": "SELL", "hash": "6aa9611f260821600dd339b59a12ffacbc98d5b7", "best_bid": "0.931", "best_ask": "0.935"}], "timestamp": "1769384164585", "event_type": "price_change"}}
{"_local_timestamp": "2026-01-25T23:36:04.657020+00:00", "data": {"market": "0x22ac5f75af18fdb453497fbf7ac0606a09a6fd55b78b2d08aace6b946ad62038", "price_changes": [{"asset_id": "97449340182256366014320155718265676486703217567849039806162053075113517266910", "price": "0.016", "size": "0", "side": "BUY", "hash": "e2079c909ad4b6400d7b84849847fabbbfc6b8ba", "best_bid": "0.065", "best_ask": "0.069"}, {"asset_id": "59259495934562596318644973716893809974860301509869285036503555129962149752635", "price": "0.984", "size": "0", "side": "SELL", "hash": "6aa9611f260821600dd339b59a12ffacbc98d5b7", "best_bid": "0.931", "best_ask": "0.935"}], "timestamp": "1769384164585", "event_type": "price_change"}}
{"_local_timestamp": "2026-01-25T23:36:04.657478+00:00", "data": {"market": "0x22ac5f75af18fdb453497fbf7ac0606a09a6fd55b78b2d08aace6b946ad62038", "price_changes": [{"asset_id": "97449340182256366014320155718265676486703217567849039806162053075113517266910", "price": "0.027", "size": "0", "side": "BUY", "hash": "e2079c909ad4b6400d7b84849847fabbbfc6b8ba", "best_bid": "0.065", "best_ask": "0.069"}, {"asset_id": "59259495934562596318644973716893809974860301509869285036503555129962149752635", "price": "0.973", "size": "0", "side": "SELL", "hash": "6aa9611f260821600dd339b59a12ffacbc98d5b7", "best_bid": "0.931", "best_ask": "0.935"}], "timestamp": "1769384164585", "event_type": "price_change"}}
{"_local_timestamp": "2026-01-25T23:36:04.815113+00:00", "data": {"market": "0x22ac5f75af18fdb453497fbf7ac0606a09a6fd55b78b2d08aace6b946ad62038", "price_changes": [{"asset_id": "59259495934562596318644973716893809974860301509869285036503555129962149752635", "price": "0.988", "size": "0", "side": "SELL", "hash": "0fa266ae48b64006970f38d50924099330de2339", "best_bid": "0.931", "best_ask": "0.935"}, {"asset_id": "97449340182256366014320155718265676486703217567849039806162053075113517266910", "price": "0.012", "size": "0", "side": "BUY", "hash": "4a353902b887e9cea2b69fbaae4cf628fc271eff", "best_bid": "0.065", "best_ask": "0.069"}], "timestamp": "1769384164743", "event_type": "price_change"}}
{"_local_timestamp": "2026-01-25T23:36:05.127896+00:00", "data": {"market": "0x22ac5f75af18fdb453497fbf7ac0606a09a6fd55b78b2d08aace6b946ad62038", "price_changes": [{"asset_id": "97449340182256366014320155718265676486703217567849039806162053075113517266910", "price": "0.013", "size": "14.47", "side": "BUY", "hash": "026c85978e48c7a648df3eebb81a0c74a562b68e", "best_bid": "0.065", "best_ask": "0.069"}, {"asset_id": "59259495934562596318644973716893809974860301509869285036503555129962149752635", "price": "0.987", "size": "14.47", "side": "SELL", "hash": "c4504d629da715323a6a1474e9f19bc33f39f280", "best_bid": "0.931", "best_ask": "0.935"}], "timestamp": "1769384165060", "event_type": "price_change"}}
{"_local_timestamp": "2026-01-25T23:36:05.128444+00:00", "data": {"market": "0x22ac5f75af18fdb453497fbf7ac0606a09a6fd55b78b2d08aace6b946ad62038", "price_changes": [{"asset_id": "97449340182256366014320155718265676486703217567849039806162053075113517266910", "price": "0.004", "size": "20.87", "side": "BUY", "hash": "4c702b5103e0b64c738d9548e90c5314cce1dec3", "best_bid": "0.065", "best_ask": "0.069"}, {"asset_id": "59259495934562596318644973716893809974860301509869285036503555129962149752635", "price": "0.996", "size": "20.87", "side": "SELL", "hash": "b9ce7c29e6f870c86606b3ac45f00a8e3cb4467b", "best_bid": "0.931", "best_ask": "0.935"}], "timestamp": "1769384165062", "event_type": "price_change"}}
{"_local_timestamp": "2026-01-25T23:36:05.128870+00:00", "data": {"market": "0x22ac5f75af18fdb453497fbf7ac0606a09a6fd55b78b2d08aace6b946ad62038", "price_changes": [{"asset_id": "97449340182256366014320155718265676486703217567849039806162053075113517266910", "price": "0.025", "size": "23.03", "side": "BUY", "hash": "072124b2ec379b6a7940ec7deec226309aeee97f", "best_bid": "0.065", "best_ask": "0.069"}, {"asset_id": "59259495934562596318644973716893809974860301509869285036503555129962149752635", "price": "0.975", "size": "23.03", "side": "SELL", "hash": "00ea6753b25f225ca62b85f11c156ec485181ff4", "best_bid": "0.931", "best_ask": "0.935"}], "timestamp": "1769384165063", "event_type": "price_change"}}
{"_local_timestamp": "2026-01-25T23:36:05.984199+00:00", "data": {"market": "0x22ac5f75af18fdb453497fbf7ac0606a09a6fd55b78b2d08aace6b946ad62038", "price_changes": [{"asset_id": "59259495934562596318644973716893809974860301509869285036503555129962149752635", "price": "0.785", "size": "0", "side": "BUY", "hash": "fcb9f06792dfe489081cf8456038b32a9ff6f343", "best_bid": "0.931", "best_ask": "0.935"}, {"asset_id": "97449340182256366014320155718265676486703217567849039806162053075113517266910", "price": "0.215", "size": "0", "side": "SELL", "hash": "f43739c2bd9ea189f738ab6a06654318b75a3bd7", "best_bid": "0.065", "best_ask": "0.069"}], "timestamp": "1769384165919", "event_type": "price_change"}}
{"_local_timestamp": "2026-01-25T23:36:06.285390+00:00", "data": {"market": "0x22ac5f75af18fdb453497fbf7ac0606a09a6fd55b78b2d08aace6b946ad62038", "price_changes": [{"asset_id": "59259495934562596318644973716893809974860301509869285036503555129962149752635", "price": "0.785", "size": "5", "side": "BUY", "hash": "036ebc69c0e6d448718e96a6876a6dd49062e142", "best_bid": "0.931", "best_ask": "0.935"}, {"asset_id": "97449340182256366014320155718265676486703217567849039806162053075113517266910", "price": "0.215", "size": "5", "side": "SELL", "hash": "833c7a5905d2adbbf3f4773ca70e2e9af01b73fa", "best_bid": "0.065", "best_ask": "0.069"}], "timestamp": "1769384166217", "event_type": "price_change"}}
{"_local_timestamp": "2026-01-25T23:36:06.441080+00:00", "data": {"market": "0x22ac5f75af18fdb453497fbf7ac0606a09a6fd55b78b2d08aace6b946ad62038", "price_changes": [{"asset_id": "97449340182256366014320155718265676486703217567849039806162053075113517266910", "price": "0.009", "size": "133.06", "side": "BUY", "hash": "39703f9cc55ef9be34453f028c0046f3df1b32a8", "best_bid": "0.065", "best_ask": "0.069"}, {"asset_id": "59259495934562596318644973716893809974860301509869285036503555129962149752635", "price": "0.991", "size": "133.06", "side": "SELL", "hash": "cb87080e4fb4842404171573e862d31528c8704e", "best_bid": "0.931", "best_ask": "0.935"}], "timestamp": "1769384166376", "event_type": "price_change"}}
{"_local_timestamp": "2026-01-25T23:36:06.441632+00:00", "data": {"market": "0x22ac5f75af18fdb453497fbf7ac0606a09a6fd55b78b2d08aace6b946ad62038", "price_changes": [{"asset_id": "97449340182256366014320155718265676486703217567849039806162053075113517266910", "price": "0.013", "size": "0", "side": "BUY", "hash": "39703f9cc55ef9be34453f028c0046f3df1b32a8", "best_bid": "0.065", "best_ask": "0.069"}, {"asset_id": "59259495934562596318644973716893809974860301509869285036503555129962149752635", "price": "0.987", "size": "0", "side": "SELL", "hash": "cb87080e4fb4842404171573e862d31528c8704e", "best_bid": "0.931", "best_ask": "0.935"}], "timestamp": "1769384166376", "event_type": "price_change"}}
{"_local_timestamp": "2026-01-25T23:36:07.061181+00:00", "data": {"market": "0x22ac5f75af18fdb453497fbf7ac0606a09a6fd55b78b2d08aace6b946ad62038", "price_changes": [{"asset_id": "97449340182256366014320155718265676486703217567849039806162053075113517266910", "price": "0.011", "size": "18.95", "side": "BUY", "hash": "ad3025c0a14dc1a9d6f401d510f3b54b906db5ee", "best_bid": "0.065", "best_ask": "0.069"}, {"asset_id": "59259495934562596318644973716893809974860301509869285036503555129962149752635", "price": "0.989", "size": "18.95", "side": "SELL", "hash": "61cdd09c0a5ed8b4d7b896c20e8bb821f3c55136", "best_bid": "0.931", "best_ask": "0.935"}], "timestamp": "1769384166999", "event_type": "price_change"}}
{"_local_timestamp": "2026-01-25T23:36:07.069118+00:00", "data": {"market": "0x22ac5f75af18fdb453497fbf7ac0606a09a6fd55b78b2d08aace6b946ad62038", "price_changes": [{"asset_id": "97449340182256366014320155718265676486703217567849039806162053075113517266910", "price": "0.004", "size": "27.87", "side": "BUY", "hash": "623f5a7a4cbb8bb18569367f5a1b326400cdbd47", "best_bid": "0.065", "best_ask": "0.069"}, {"asset_id": "59259495934562596318644973716893809974860301509869285036503555129962149752635", "price": "0.996", "size": "27.87", "side": "SELL", "hash": "1d60bc56fd480482cfae00d5f920984a3565f374", "best_bid": "0.931", "best_ask": "0.935"}], "timestamp": "1769384167000", "event_type": "price_change"}}
{"_local_timestamp": "2026-01-25T23:36:07.798132+00:00", "data": {"market": "0x22ac5f75af18fdb453497fbf7ac0606a09a6fd55b78b2d08aace6b946ad62038", "price_changes": [{"asset_id": "59259495934562596318644973716893809974860301509869285036503555129962149752635", "price": "0.989", "size": "217.83", "side": "SELL", "hash": "3ef2762d7a16d65051498480bd41022b7a466f96", "best_bid": "0.931", "best_ask": "0.935"}, {"asset_id": "97449340182256366014320155718265676486703217567849039806162053075113517266910", "price": "0.011", "size": "217.83", "side": "BUY", "hash": "87fe31a41545a6f05babb6c2b19a81d8c135c6bb", "best_bid": "0.065", "best_ask": "0.069"}], "timestamp": "1769384167731", "event_type": "price_change"}}
{"_local_timestamp": "2026-01-25T23:36:08.573049+00:00", "data": {"market": "0x22ac5f75af18fdb453497fbf7ac0606a09a6fd55b78b2d08aace6b946ad62038", "price_changes": [{"asset_id": "97449340182256366014320155718265676486703217567849039806162053075113517266910", "price": "0.004", "size": "7", "side": "BUY", "hash": "8dab7295c624d5dd9e418fedc8349709f55dce34", "best_bid": "0.065", "best_ask": "0.069"}, {"asset_id": "59259495934562596318644973716893809974860301509869285036503555129962149752635", "price": "0.996", "size": "7", "side": "SELL", "hash": "f7cc74117c38c087433cf189fb90a569e79f809a", "best_bid": "0.931", "best_ask": "0.935"}], "timestamp": "1769384168495", "event_type": "price_change"}}
{"_local_timestamp": "2026-01-25T23:36:08.573675+00:00", "data": {"market": "0x22ac5f75af18fdb453497fbf7ac0606a09a6fd55b78b2d08aace6b946ad62038", "price_changes": [{"asset_id": "97449340182256366014320155718265676486703217567849039806162053075113517266910", "price": "0.011", "size": "198.88", "side": "BUY", "hash": "8dab7295c624d5dd9e418fedc8349709f55dce34", "best_bid": "0.065", "best_ask": "0.069"}, {"asset_id": "59259495934562596318644973716893809974860301509869285036503555129962149752635", "price": "0.989", "size": "198.88", "side": "SELL", "hash": "f7cc74117c38c087433cf189fb90a569e79f809a", "best_bid": "0.931", "best_ask": "0.935"}], "timestamp": "1769384168495", "event_type": "price_change"}}
{"_local_timestamp": "2026-01-25T23:36:08.945068+00:00", "data": {"market": "0x22ac5f75af18fdb453497fbf7ac0606a09a6fd55b78b2d08aace6b946ad62038", "price_changes": [{"asset_id": "97449340182256366014320155718265676486703217567849039806162053075113517266910", "price": "0.012", "size": "16.15", "side": "BUY", "hash": "22c1513f08b9590b1f9cbe7acebfb6583cf907af", "best_bid": "0.065", "best_ask": "0.069"}, {"asset_id": "59259495934562596318644973716893809974860301509869285036503555129962149752635", "price": "0.988", "size": "16.15", "side": "SELL", "hash": "04f66f13fa724245de034fddf6e9399e32fdfeef", "best_bid": "0.931", "best_ask": "0.935"}], "timestamp": "1769384168872", "event_type": "price_change"}}
{"_local_timestamp": "2026-01-25T23:36:08.945741+00:00", "data": {"market": "0x22ac5f75af18fdb453497fbf7ac0606a09a6fd55b78b2d08aace6b946ad62038", "price_changes": [{"asset_id": "97449340182256366014320155718265676486703217567849039806162053075113517266910", "price": "0.009", "size": "138.23", "side": "BUY", "hash": "fded722acf103dcbfdc09922e533c7c598ef71c9", "best_bid": "0.065", "best_ask": "0.069"}, {"asset_id": "59259495934562596318644973716893809974860301509869285036503555129962149752635", "price": "0.991", "size": "138.23", "side": "SELL", "hash": "24f998b297e440eaf0789f7045445f309a6cb379", "best_bid": "0.931", "best_ask": "0.935"}], "timestamp": "1769384168873", "event_type": "price_change"}}
{"_local_timestamp": "2026-01-25T23:36:08.946408+00:00", "data": {"market": "0x22ac5f75af18fdb453497fbf7ac0606a09a6fd55b78b2d08aace6b946ad62038", "price_changes": [{"asset_id": "97449340182256366014320155718265676486703217567849039806162053075113517266910", "price": "0.004", "size": "19.9", "side": "BUY", "hash": "ae9c7e5028ad8e3c32f907e519bf55b6b0f4dcd7", "best_bid": "0.065", "best_ask": "0.069"}, {"asset_id": "59259495934562596318644973716893809974860301509869285036503555129962149752635", "price": "0.996", "size": "19.9", "side": "SELL", "hash": "00d676255ecff71eea902f6fbda1c3d9fd18f6c2", "best_bid": "0.931", "best_ask": "0.935"}], "timestamp": "1769384168874", "event_type": "price_change"}}
{"_local_timestamp": "2026-01-25T23:36:09.881787+00:00", "data": {"market": "0x22ac5f75af18fdb453497fbf7ac0606a09a6fd55b78b2d08aace6b946ad62038", "price_changes": [{"asset_id": "59259495934562596318644973716893809974860301509869285036503555129962149752635", "price": "0.989", "size": "0", "side": "SELL", "hash": "c83fc3d7c0cbcc5c6ee50686aa4b64d219e36c65", "best_bid": "0.931", "best_ask": "0.935"}, {"asset_id": "97449340182256366014320155718265676486703217567849039806162053075113517266910", "price": "0.011", "size": "0", "side": "BUY", "hash": "5b52eea3e1ddc24d8f2fd8a29db0f822934c91d7", "best_bid": "0.065", "best_ask": "0.069"}], "timestamp": "1769384169812", "event_type": "price_change"}}
{"_local_timestamp": "2026-01-25T23:36:10.296800+00:00", "data": {"market": "0x22ac5f75af18fdb453497fbf7ac0606a09a6fd55b78b2d08aace6b946ad62038", "price_changes": [{"asset_id": "97449340182256366014320155718265676486703217567849039806162053075113517266910", "price": "0.009", "size": "133.06", "side": "BUY", "hash": "9afb6f1823227f02067711c3f4bd65b77f1c3091", "best_bid": "0.065", "best_ask": "0.069"}, {"asset_id": "59259495934562596318644973716893809974860301509869285036503555129962149752635", "price": "0.991", "size": "133.06", "side": "SELL", "hash": "76f9f29951370118dd2b92498462c4744ed2b704", "best_bid": "0.931", "best_ask": "0.935"}], "timestamp": "1769384170232", "event_type": "price_change"}}
{"_local_timestamp": "2026-01-25T23:36:10.297369+00:00", "data": {"market": "0x22ac5f75af18fdb453497fbf7ac0606a09a6fd55b78b2d08aace6b946ad62038", "price_changes": [{"asset_id": "97449340182256366014320155718265676486703217567849039806162053075113517266910", "price": "0.012", "size": "0", "side": "BUY", "hash": "9afb6f1823227f02067711c3f4bd65b77f1c3091", "best_bid": "0.065", "best_ask": "0.069"}, {"asset_id": "59259495934562596318644973716893809974860301509869285036503555129962149752635", "price": "0.988", "size": "0", "side": "SELL", "hash": "76f9f29951370118dd2b92498462c4744ed2b704", "best_bid": "0.931", "best_ask": "0.935"}], "timestamp": "1769384170232", "event_type": "price_change"}}
{"_local_timestamp": "2026-01-25T23:36:10.669244+00:00", "data": {"market": "0x22ac5f75af18fdb453497fbf7ac0606a09a6fd55b78b2d08aace6b946ad62038", "price_changes": [{"asset_id": "97449340182256366014320155718265676486703217567849039806162053075113517266910", "price": "0.004", "size": "27.86", "side": "BUY", "hash": "b2d0da87962eda5e258f871e45fee3b0ee02381c", "best_bid": "0.065", "best_ask": "0.069"}, {"asset_id": "59259495934562596318644973716893809974860301509869285036503555129962149752635", "price": "0.996", "size": "27.86", "side": "SELL", "hash": "e6b6ac9108560b72c1b1b909279343fdc4a9c250", "best_bid": "0.931", "best_ask": "0.935"}], "timestamp": "1769384170578", "event_type": "price_change"}}
{"_local_timestamp": "2026-01-25T23:36:10.675033+00:00", "data": {"market": "0x22ac5f75af18fdb453497fbf7ac0606a09a6fd55b78b2d08aace6b946ad62038", "price_changes": [{"asset_id": "97449340182256366014320155718265676486703217567849039806162053075113517266910", "price": "0.011", "size": "18.95", "side": "BUY", "hash": "6cb65f98fece028d5ca46d9fcf4fb393704a666e", "best_bid": "0.065", "best_ask": "0.069"}, {"asset_id": "59259495934562596318644973716893809974860301509869285036503555129962149752635", "price": "0.989", "size": "18.95", "side": "SELL", "hash": "4239c5f7edc44a5391d2cd6e83a64540dc1bc72d", "best_bid": "0.931", "best_ask": "0.935"}], "timestamp": "1769384170579", "event_type": "price_change"}}
{"_local_timestamp": "2026-01-25T23:36:11.659310+00:00", "data": {"market": "0x22ac5f75af18fdb453497fbf7ac0606a09a6fd55b78b2d08aace6b946ad62038", "price_changes": [{"asset_id": "59259495934562596318644973716893809974860301509869285036503555129962149752635", "price": "0.988", "size": "198.88", "side": "SELL", "hash": "b97e2087b2ba75d5b438253ff31fd502d7168edd", "best_bid": "0.931", "best_ask": "0.935"}, {"asset_id": "97449340182256366014320155718265676486703217567849039806162053075113517266910", "price": "0.012", "size": "198.88", "side": "BUY", "hash": "b2bbb2808abca3e213c0e5cd6506d5ea3d7579d7", "best_bid": "0.065", "best_ask": "0.069"}], "timestamp": "1769384171589", "event_type": "price_change"}}
{"_local_timestamp": "2026-01-25T23:36:11.934142+00:00", "data": {"market": "0x22ac5f75af18fdb453497fbf7ac0606a09a6fd55b78b2d08aace6b946ad62038", "price_changes": [{"asset_id": "97449340182256366014320155718265676486703217567849039806162053075113517266910", "price": "0.004", "size": "14.96", "side": "BUY", "hash": "af246698f9f445ddddfb8b02abc539a140d253ea", "best_bid": "0.065", "best_ask": "0.069"}, {"asset_id": "59259495934562596318644973716893809974860301509869285036503555129962149752635", "price": "0.996", "size": "14.96", "side": "SELL", "hash": "c2241d6341703c5d901606c8bf52aab7bc6fec2c", "best_bid": "0.931", "best_ask": "0.935"}], "timestamp": "1769384171868", "event_type": "price_change"}}
{"_local_timestamp": "2026-01-25T23:36:11.934789+00:00", "data": {"market": "0x22ac5f75af18fdb453497fbf7ac0606a09a6fd55b78b2d08aace6b946ad62038", "price_changes": [{"asset_id": "97449340182256366014320155718265676486703217567849039806162053075113517266910", "price": "0.011", "size": "0", "side": "BUY", "hash": "af246698f9f445ddddfb8b02abc539a140d253ea", "best_bid": "0.065", "best_ask": "0.069"}, {"asset_id": "59259495934562596318644973716893809974860301509869285036503555129962149752635", "price": "0.989", "size": "0", "side": "SELL", "hash": "c2241d6341703c5d901606c8bf52aab7bc6fec2c", "best_bid": "0.931", "best_ask": "0.935"}], "timestamp": "1769384171868", "event_type": "price_change"}}
{"_local_timestamp": "2026-01-25T23:36:12.282080+00:00", "data": {"market": "0x22ac5f75af18fdb453497fbf7ac0606a09a6fd55b78b2d08aace6b946ad62038", "price_changes": [{"asset_id": "97449340182256366014320155718265676486703217567849039806162053075113517266910", "price": "0.004", "size": "20.02", "side": "BUY", "hash": "5a85a4d07e3d9962ecf617b440529844d978d06e", "best_bid": "0.065", "best_ask": "0.069"}, {"asset_id": "59259495934562596318644973716893809974860301509869285036503555129962149752635", "price": "0.996", "size": "20.02", "side": "SELL", "hash": "f405a962b39fb8963ad8037ad8456ed29fd30577", "best_bid": "0.931", "best_ask": "0.935"}], "timestamp": "1769384172215", "event_type": "price_change"}}
{"_local_timestamp": "2026-01-25T23:36:12.282685+00:00", "data": {"market": "0x22ac5f75af18fdb453497fbf7ac0606a09a6fd55b78b2d08aace6b946ad62038", "price_changes": [{"asset_id": "97449340182256366014320155718265676486703217567849039806162053075113517266910", "price": "0.013", "size": "13.69", "side": "BUY", "hash": "528eb750f75d8a64c883f35ac174f2848e909c2d", "best_bid": "0.065", "best_ask": "0.069"}, {"asset_id": "59259495934562596318644973716893809974860301509869285036503555129962149752635", "price": "0.987", "size": "13.69", "side": "SELL", "hash": "ae1f94ec5f0b0bbee987bedf9f56b1294cad9cb1", "best_bid": "0.931", "best_ask": "0.935"}], "timestamp": "1769384172216", "event_type": "price_change"}}
{"_local_timestamp": "2026-01-25T23:36:12.283203+00:00", "data": {"market": "0x22ac5f75af18fdb453497fbf7ac0606a09a6fd55b78b2d08aace6b946ad62038", "price_changes": [{"asset_id": "97449340182256366014320155718265676486703217567849039806162053075113517266910", "price": "0.009", "size": "139.92", "side": "BUY", "hash": "1b37eb24a49207536af3b4fb011c1f703e1b43ee", "best_bid": "0.065", "best_ask": "0.069"}, {"asset_id": "59259495934562596318644973716893809974860301509869285036503555129962149752635", "price": "0.991", "size": "139.92", "side": "SELL", "hash": "4b0dc3d9b782140f026ed6560f69780ec6097518", "best_bid": "0.931", "best_ask": "0.935"}], "timestamp": "1769384172217", "event_type": "price_change"}}
{"_local_timestamp": "2026-01-25T23:36:13.007967+00:00", "data": {"market": "0x22ac5f75af18fdb453497fbf7ac0606a09a6fd55b78b2d08aace6b946ad62038", "price_changes": [{"asset_id": "59259495934562596318644973716893809974860301509869285036503555129962149752635", "price": "0.988", "size": "0", "side": "SELL", "hash": "f3843566efbd1f91761011decc0c531b8ef4b164", "best_bid": "0.931", "best_ask": "0.935"}, {"asset_id": "97449340182256366014320155718265676486703217567849039806162053075113517266910", "price": "0.012", "size": "0", "side": "BUY", "hash": "4d1128f9686bdc95f2757509f3ff181f978c225d", "best_bid": "0.065", "best_ask": "0.069"}], "timestamp": "1769384172944", "event_type": "price_change"}}
{"_local_timestamp": "2026-01-25T23:36:13.404097+00:00", "data": {"market": "0x22ac5f75af18fdb453497fbf7ac0606a09a6fd55b78b2d08aace6b946ad62038", "price_changes": [{"asset_id": "97449340182256366014320155718265676486703217567849039806162053075113517266910", "price": "0.009", "size": "133.06", "side": "BUY", "hash": "f364a82868ce6f825de24468a78e86b8ee15deae", "best_bid": "0.065", "best_ask": "0.069"}, {"asset_id": "59259495934562596318644973716893809974860301509869285036503555129962149752635", "price": "0.991", "size": "133.06", "side": "SELL", "hash": "5f11f40b4b13aa71b338c1c134922fa13f96bb29", "best_bid": "0.931", "best_ask": "0.935"}], "timestamp": "1769384173329", "event_type": "price_change"}}
{"_local_timestamp": "2026-01-25T23:36:13.405007+00:00", "data": {"market": "0x22ac5f75af18fdb453497fbf7ac0606a09a6fd55b78b2d08aace6b946ad62038", "price_changes": [{"asset_id": "97449340182256366014320155718265676486703217567849039806162053075113517266910", "price": "0.013", "size": "0", "side": "BUY", "hash": "f364a82868ce6f825de24468a78e86b8ee15deae", "best_bid": "0.065", "best_ask": "0.069"}, {"asset_id": "59259495934562596318644973716893809974860301509869285036503555129962149752635", "price": "0.987", "size": "0", "side": "SELL", "hash": "5f11f40b4b13aa71b338c1c134922fa13f96bb29", "best_bid": "0.931", "best_ask": "0.935"}], "timestamp": "1769384173329", "event_type": "price_change"}}
{"_local_timestamp": "2026-01-25T23:36:13.405569+00:00", "data": {"market": "0x22ac5f75af18fdb453497fbf7ac0606a09a6fd55b78b2d08aace6b946ad62038", "price_changes": [{"asset_id": "59259495934562596318644973716893809974860301509869285036503555129962149752635", "price": "0.785", "size": "0", "side": "BUY", "hash": "1dabf911b7be57248b4b30ebd6b358437775c3e6", "best_bid": "0.931", "best_ask": "0.935"}, {"asset_id": "97449340182256366014320155718265676486703217567849039806162053075113517266910", "price": "0.215", "size": "0", "side": "SELL", "hash": "d6963d11a323bc7a37c400f0161923f7f490e50a", "best_bid": "0.065", "best_ask": "0.069"}], "timestamp": "1769384173329", "event_type": "price_change"}}
{"_local_timestamp": "2026-01-25T23:36:13.902383+00:00", "data": {"market": "0x22ac5f75af18fdb453497fbf7ac0606a09a6fd55b78b2d08aace6b946ad62038", "price_changes": [{"asset_id": "59259495934562596318644973716893809974860301509869285036503555129962149752635", "price": "0.785", "size": "5", "side": "BUY", "hash": "cd66c605a59c6d39aad4135accc7ebdd8bd840ca", "best_bid": "0.931", "best_ask": "0.935"}, {"asset_id": "97449340182256366014320155718265676486703217567849039806162053075113517266910", "price": "0.215", "size": "5", "side": "SELL", "hash": "5948044c6a35452e7fd2c2a48ae3523b231be2b4", "best_bid": "0.065", "best_ask": "0.069"}], "timestamp": "1769384173826", "event_type": "price_change"}}
{"_local_timestamp": "2026-01-25T23:36:13.903907+00:00", "data": {"market": "0x22ac5f75af18fdb453497fbf7ac0606a09a6fd55b78b2d08aace6b946ad62038", "price_changes": [{"asset_id": "97449340182256366014320155718265676486703217567849039806162053075113517266910", "price": "0.004", "size": "27.86", "side": "BUY", "hash": "b8949eb7c3bf4e4456b13247e661f196e42cbfa0", "best_bid": "0.065", "best_ask": "0.069"}, {"asset_id": "59259495934562596318644973716893809974860301509869285036503555129962149752635", "price": "0.996", "size": "27.86", "side": "SELL", "hash": "2919d946e79714421ccb03d7dcee40df608404bd", "best_bid": "0.931", "best_ask": "0.935"}], "timestamp": "1769384173827", "event_type": "price_change"}}
{"_local_timestamp": "2026-01-25T23:36:13.906640+00:00", "data": {"market": "0x22ac5f75af18fdb453497fbf7ac0606a09a6fd55b78b2d08aace6b946ad62038", "price_changes": [{"asset_id": "97449340182256366014320155718265676486703217567849039806162053075113517266910", "price": "0.011", "size": "18.95", "side": "BUY", "hash": "877ea7093989037b3b56463c80186c21f5d3eeb9", "best_bid": "0.065", "best_ask": "0.069"}, {"asset_id": "59259495934562596318644973716893809974860301509869285036503555129962149752635", "price": "0.989", "size": "18.95", "side": "SELL", "hash": "8b2a8120218a29dd00120d344e77f583c50df742", "best_bid": "0.931", "best_ask": "0.935"}], "timestamp": "1769384173828", "event_type": "price_change"}}
{"_local_timestamp": "2026-01-25T23:36:15.970893+00:00", "data": {"market": "0x22ac5f75af18fdb453497fbf7ac0606a09a6fd55b78b2d08aace6b946ad62038", "price_changes": [{"asset_id": "59259495934562596318644973716893809974860301509869285036503555129962149752635", "price": "0.989", "size": "217.83", "side": "SELL", "hash": "dfce2699293d14e3bf17ededdac1b133d26821c7", "best_bid": "0.931", "best_ask": "0.935"}, {"asset_id": "97449340182256366014320155718265676486703217567849039806162053075113517266910", "price": "0.011", "size": "217.83", "side": "BUY", "hash": "41a70c9ccc97653f835488a8f402eb70e8f7bc40", "best_bid": "0.065", "best_ask": "0.069"}], "timestamp": "1769384175905", "event_type": "price_change"}}
{"_local_timestamp": "2026-01-25T23:36:16.872558+00:00", "data": {"market": "0x22ac5f75af18fdb453497fbf7ac0606a09a6fd55b78b2d08aace6b946ad62038", "price_changes": [{"asset_id": "97449340182256366014320155718265676486703217567849039806162053075113517266910", "price": "0.004", "size": "19.9", "side": "BUY", "hash": "5848dc84172a6dcd813c18f60fe976690ddd995a", "best_bid": "0.065", "best_ask": "0.069"}, {"asset_id": "59259495934562596318644973716893809974860301509869285036503555129962149752635", "price": "0.996", "size": "19.9", "side": "SELL", "hash": "7949fa09901fbfa13e54d9253421a4419ccf439a", "best_bid": "0.931", "best_ask": "0.935"}], "timestamp": "1769384176804", "event_type": "price_change"}}
{"_local_timestamp": "2026-01-25T23:36:16.873254+00:00", "data": {"market": "0x22ac5f75af18fdb453497fbf7ac0606a09a6fd55b78b2d08aace6b946ad62038", "price_changes": [{"asset_id": "97449340182256366014320155718265676486703217567849039806162053075113517266910", "price": "0.011", "size": "198.88", "side": "BUY", "hash": "5848dc84172a6dcd813c18f60fe976690ddd995a", "best_bid": "0.065", "best_ask": "0.069"}, {"asset_id": "59259495934562596318644973716893809974860301509869285036503555129962149752635", "price": "0.989", "size": "198.88", "side": "SELL", "hash": "7949fa09901fbfa13e54d9253421a4419ccf439a", "best_bid": "0.931", "best_ask": "0.935"}], "timestamp": "1769384176804", "event_type": "price_change"}}
{"_local_timestamp": "2026-01-25T23:36:17.252227+00:00", "data": {"market": "0x22ac5f75af18fdb453497fbf7ac0606a09a6fd55b78b2d08aace6b946ad62038", "price_changes": [{"asset_id": "97449340182256366014320155718265676486703217567849039806162053075113517266910", "price": "0.012", "size": "16.15", "side": "BUY", "hash": "e7050d025de488e68d40593a47423fbefc5ab703", "best_bid": "0.065", "best_ask": "0.069"}, {"asset_id": "59259495934562596318644973716893809974860301509869285036503555129962149752635", "price": "0.988", "size": "16.15", "side": "SELL", "hash": "d2255b33a6b7f01522ef343e3ad356063ef94a2c", "best_bid": "0.931", "best_ask": "0.935"}], "timestamp": "1769384177182", "event_type": "price_change"}}
{"_local_timestamp": "2026-01-25T23:36:17.256574+00:00", "data": {"market": "0x22ac5f75af18fdb453497fbf7ac0606a09a6fd55b78b2d08aace6b946ad62038", "price_changes": [{"asset_id": "97449340182256366014320155718265676486703217567849039806162053075113517266910", "price": "0.009", "size": "138.23", "side": "BUY", "hash": "0bfa4b8fb572ee77b403d22acfaf0d13d0d59312", "best_bid": "0.065", "best_ask": "0.069"}, {"asset_id": "59259495934562596318644973716893809974860301509869285036503555129962149752635", "price": "0.991", "size": "138.23", "side": "SELL", "hash": "31cdd4544d3011e87c65cb9bad23a2f36abfa353", "best_bid": "0.931", "best_ask": "0.935"}], "timestamp": "1769384177183", "event_type": "price_change"}}
{"_local_timestamp": "2026-01-25T23:36:18.110129+00:00", "data": {"market": "0x22ac5f75af18fdb453497fbf7ac0606a09a6fd55b78b2d08aace6b946ad62038", "price_changes": [{"asset_id": "59259495934562596318644973716893809974860301509869285036503555129962149752635", "price": "0.989", "size": "0", "side": "SELL", "hash": "9337d5ddffa9def67c2a5884019b7af799117df4", "best_bid": "0.931", "best_ask": "0.935"}, {"asset_id": "97449340182256366014320155718265676486703217567849039806162053075113517266910", "price": "0.011", "size": "0", "side": "BUY", "hash": "dc699cd1ed3ed9d2a5d8eb2362223a7c9cd0a0c2", "best_bid": "0.065", "best_ask": "0.069"}], "timestamp": "1769384178030", "event_type": "price_change"}}
{"_local_timestamp": "2026-01-25T23:36:19.411223+00:00", "data": {"market": "0x22ac5f75af18fdb453497fbf7ac0606a09a6fd55b78b2d08aace6b946ad62038", "price_changes": [{"asset_id": "97449340182256366014320155718265676486703217567849039806162053075113517266910", "price": "0.009", "size": "133.06", "side": "BUY", "hash": "0195fb6aec48e23a191a8e7779aa9fc5a93434b5", "best_bid": "0.065", "best_ask": "0.069"}, {"asset_id": "59259495934562596318644973716893809974860301509869285036503555129962149752635", "price": "0.991", "size": "133.06", "side": "SELL", "hash": "a4312973b0756220496f7b5b9556a62645e5e9dd", "best_bid": "0.931", "best_ask": "0.935"}], "timestamp": "1769384179345", "event_type": "price_change"}}
{"_local_timestamp": "2026-01-25T23:36:19.411937+00:00", "data": {"market": "0x22ac5f75af18fdb453497fbf7ac0606a09a6fd55b78b2d08aace6b946ad62038", "price_changes": [{"asset_id": "97449340182256366014320155718265676486703217567849039806162053075113517266910", "price": "0.012", "size": "0", "side": "BUY", "hash": "0195fb6aec48e23a191a8e7779aa9fc5a93434b5", "best_bid": "0.065", "best_ask": "0.069"}, {"asset_id": "59259495934562596318644973716893809974860301509869285036503555129962149752635", "price": "0.988", "size": "0", "side": "SELL", "hash": "a4312973b0756220496f7b5b9556a62645e5e9dd", "best_bid": "0.931", "best_ask": "0.935"}], "timestamp": "1769384179345", "event_type": "price_change"}}
{"_local_timestamp": "2026-01-25T23:36:19.742375+00:00", "data": {"market": "0x22ac5f75af18fdb453497fbf7ac0606a09a6fd55b78b2d08aace6b946ad62038", "price_changes": [{"asset_id": "97449340182256366014320155718265676486703217567849039806162053075113517266910", "price": "0.011", "size": "18.95", "side": "BUY", "hash": "200397e7c63cfaff0c84ddf06664314b5be35d38", "best_bid": "0.065", "best_ask": "0.069"}, {"asset_id": "59259495934562596318644973716893809974860301509869285036503555129962149752635", "price": "0.989", "size": "18.95", "side": "SELL", "hash": "aa5ffab70c5dee1c33ddbb39702f3dce9e6e57f6", "best_bid": "0.931", "best_ask": "0.935"}], "timestamp": "1769384179666", "event_type": "price_change"}}
{"_local_timestamp": "2026-01-25T23:36:19.743104+00:00", "data": {"market": "0x22ac5f75af18fdb453497fbf7ac0606a09a6fd55b78b2d08aace6b946ad62038", "price_changes": [{"asset_id": "97449340182256366014320155718265676486703217567849039806162053075113517266910", "price": "0.004", "size": "27.86", "side": "BUY", "hash": "26d7ec834806895cb86af40f896600c93bf2ad63", "best_bid": "0.065", "best_ask": "0.069"}, {"asset_id": "59259495934562596318644973716893809974860301509869285036503555129962149752635", "price": "0.996", "size": "27.86", "side": "SELL", "hash": "844327771f5ecec040b8967c4fb343209d59dea7", "best_bid": "0.931", "best_ask": "0.935"}], "timestamp": "1769384179667", "event_type": "price_change"}}
{"_local_timestamp": "2026-01-25T23:36:19.998426+00:00", "data": {"market": "0x22ac5f75af18fdb453497fbf7ac0606a09a6fd55b78b2d08aace6b946ad62038", "price_changes": [{"asset_id": "59259495934562596318644973716893809974860301509869285036503555129962149752635", "price": "0.988", "size": "198.88", "side": "SELL", "hash": "20dc3e9e23b08cd83069f74c3d906e5f28d651b2", "best_bid": "0.931", "best_ask": "0.935"}, {"asset_id": "97449340182256366014320155718265676486703217567849039806162053075113517266910", "price": "0.012", "size": "198.88", "side": "BUY", "hash": "ebc3e2df95784677c40978a01865d7b0477c66e7", "best_bid": "0.065", "best_ask": "0.069"}], "timestamp": "1769384179931", "event_type": "price_change"}}
{"_local_timestamp": "2026-01-25T23:36:20.295360+00:00", "data": {"market": "0x22ac5f75af18fdb453497fbf7ac0606a09a6fd55b78b2d08aace6b946ad62038", "price_changes": [{"asset_id": "59259495934562596318644973716893809974860301509869285036503555129962149752635", "price": "0.785", "size": "0", "side": "BUY", "hash": "26bbc6d5fa4c46cd886dce0e166f6067a2aaf737", "best_bid": "0.931", "best_ask": "0.935"}, {"asset_id": "97449340182256366014320155718265676486703217567849039806162053075113517266910", "price": "0.215", "size": "0", "side": "SELL", "hash": "b7f6ce0c43e6667b3ca318c99ec6d8d16eb6cec0", "best_bid": "0.065", "best_ask": "0.069"}], "timestamp": "1769384180199", "event_type": "price_change"}}
{"_local_timestamp": "2026-01-25T23:36:20.643515+00:00", "data": {"market": "0x22ac5f75af18fdb453497fbf7ac0606a09a6fd55b78b2d08aace6b946ad62038", "price_changes": [{"asset_id": "59259495934562596318644973716893809974860301509869285036503555129962149752635", "price": "0.785", "size": "5", "side": "BUY", "hash": "a7e2aedd0d2eb5e1aa480fda0b0676fb35aa7895", "best_bid": "0.931", "best_ask": "0.935"}, {"asset_id": "97449340182256366014320155718265676486703217567849039806162053075113517266910", "price": "0.215", "size": "5", "side": "SELL", "hash": "92ba8924c2c9daf75f5c9207e11fd9b5397d62f1", "best_bid": "0.065", "best_ask": "0.069"}], "timestamp": "1769384180572", "event_type": "price_change"}}
{"_local_timestamp": "2026-01-25T23:36:21.191710+00:00", "data": {"market": "0x22ac5f75af18fdb453497fbf7ac0606a09a6fd55b78b2d08aace6b946ad62038", "price_changes": [{"asset_id": "97449340182256366014320155718265676486703217567849039806162053075113517266910", "price": "0.004", "size": "19.9", "side": "BUY", "hash": "7a29d90017e0e77510e2eaa076daa695128e1364", "best_bid": "0.065", "best_ask": "0.069"}, {"asset_id": "59259495934562596318644973716893809974860301509869285036503555129962149752635", "price": "0.996", "size": "19.9", "side": "SELL", "hash": "200e30dc61f958d22863aa7efa52ac180c770d7d", "best_bid": "0.931", "best_ask": "0.935"}], "timestamp": "1769384181122", "event_type": "price_change"}}
{"_local_timestamp": "2026-01-25T23:36:21.192339+00:00", "data": {"market": "0x22ac5f75af18fdb453497fbf7ac0606a09a6fd55b78b2d08aace6b946ad62038", "price_changes": [{"asset_id": "97449340182256366014320155718265676486703217567849039806162053075113517266910", "price": "0.011", "size": "0", "side": "BUY", "hash": "7a29d90017e0e77510e2eaa076daa695128e1364", "best_bid": "0.065", "best_ask": "0.069"}, {"asset_id": "59259495934562596318644973716893809974860301509869285036503555129962149752635", "price": "0.989", "size": "0", "side": "SELL", "hash": "200e30dc61f958d22863aa7efa52ac180c770d7d", "best_bid": "0.931", "best_ask": "0.935"}], "timestamp": "1769384181122", "event_type": "price_change"}}
{"_local_timestamp": "2026-01-25T23:36:21.434031+00:00", "data": {"market": "0x22ac5f75af18fdb453497fbf7ac0606a09a6fd55b78b2d08aace6b946ad62038", "price_changes": [{"asset_id": "97449340182256366014320155718265676486703217567849039806162053075113517266910", "price": "0.013", "size": "13.72", "side": "BUY", "hash": "6cc1bba5a4545447e955c1b4ff54b83edbb6b4c9", "best_bid": "0.065", "best_ask": "0.069"}, {"asset_id": "59259495934562596318644973716893809974860301509869285036503555129962149752635", "price": "0.987", "size": "13.72", "side": "SELL", "hash": "658ce2cd541f8d0fa7fa540758c328420082a4df", "best_bid": "0.931", "best_ask": "0.935"}], "timestamp": "1769384181362", "event_type": "price_change"}}
{"_local_timestamp": "2026-01-25T23:36:21.438386+00:00", "data": {"market": "0x22ac5f75af18fdb453497fbf7ac0606a09a6fd55b78b2d08aace6b946ad62038", "price_changes": [{"asset_id": "97449340182256366014320155718265676486703217567849039806162053075113517266910", "price": "0.009", "size": "139.94", "side": "BUY", "hash": "ee65e9a15cfdcb637d366fb40bbc1216cb657e5e", "best_bid": "0.065", "best_ask": "0.069"}, {"asset_id": "59259495934562596318644973716893809974860301509869285036503555129962149752635", "price": "0.991", "size": "139.94", "side": "SELL", "hash": "2220f00273dc463d0e76cf07e48b3b9e8f54f592", "best_bid": "0.931", "best_ask": "0.935"}], "timestamp": "1769384181363", "event_type": "price_change"}}
{"_local_timestamp": "2026-01-25T23:36:22.629018+00:00", "data": {"market": "0x22ac5f75af18fdb453497fbf7ac0606a09a6fd55b78b2d08aace6b946ad62038", "price_changes": [{"asset_id": "59259495934562596318644973716893809974860301509869285036503555129962149752635", "price": "0.988", "size": "0", "side": "SELL", "hash": "e5a09ac2fa552cf871781e7c5ff04d490e97ea50", "best_bid": "0.931", "best_ask": "0.935"}, {"asset_id": "97449340182256366014320155718265676486703217567849039806162053075113517266910", "price": "0.012", "size": "0", "side": "BUY", "hash": "dbb5e4a5f1f45484a6b18f1c1f4adcf15cf8880d", "best_bid": "0.065", "best_ask": "0.069"}], "timestamp": "1769384182561", "event_type": "price_change"}}
{"_local_timestamp": "2026-01-25T23:36:23.756210+00:00", "data": {"market": "0x22ac5f75af18fdb453497fbf7ac0606a09a6fd55b78b2d08aace6b946ad62038", "price_changes": [{"asset_id": "97449340182256366014320155718265676486703217567849039806162053075113517266910", "price": "0.009", "size": "133.06", "side": "BUY", "hash": "4d812cdfa6ffd0bfb4274ddfdb1e3311c4cf03ba", "best_bid": "0.065", "best_ask": "0.069"}, {"asset_id": "59259495934562596318644973716893809974860301509869285036503555129962149752635", "price": "0.991", "size": "133.06", "side": "SELL", "hash": "df9b4c25f2ef66e1f2c91c8b641519d1499aa294", "best_bid": "0.931", "best_ask": "0.935"}], "timestamp": "1769384183688", "event_type": "price_change"}}
{"_local_timestamp": "2026-01-25T23:36:23.756971+00:00", "data": {"market": "0x22ac5f75af18fdb453497fbf7ac0606a09a6fd55b78b2d08aace6b946ad62038", "price_changes": [{"asset_id": "97449340182256366014320155718265676486703217567849039806162053075113517266910", "price": "0.013", "size": "0", "side": "BUY", "hash": "4d812cdfa6ffd0bfb4274ddfdb1e3311c4cf03ba", "best_bid": "0.065", "best_ask": "0.069"}, {"asset_id": "59259495934562596318644973716893809974860301509869285036503555129962149752635", "price": "0.987", "size": "0", "side": "SELL", "hash": "df9b4c25f2ef66e1f2c91c8b641519d1499aa294", "best_bid": "0.931", "best_ask": "0.935"}], "timestamp": "1769384183688", "event_type": "price_change"}}
{"_local_timestamp": "2026-01-25T23:36:24.145703+00:00", "data": {"market": "0x22ac5f75af18fdb453497fbf7ac0606a09a6fd55b78b2d08aace6b946ad62038", "price_changes": [{"asset_id": "97449340182256366014320155718265676486703217567849039806162053075113517266910", "price": "0.004", "size": "27.86", "side": "BUY", "hash": "24778f52c3c17ea3e8309b7bea569064aa2c260f", "best_bid": "0.065", "best_ask": "0.069"}, {"asset_id": "59259495934562596318644973716893809974860301509869285036503555129962149752635", "price": "0.996", "size": "27.86", "side": "SELL", "hash": "eb44f3d385b0eb75e76e9c3ef3efce1671fa2a97", "best_bid": "0.931", "best_ask": "0.935"}], "timestamp": "1769384184022", "event_type": "price_change"}}
{"_local_timestamp": "2026-01-25T23:36:24.173349+00:00", "data": {"market": "0x22ac5f75af18fdb453497fbf7ac0606a09a6fd55b78b2d08aace6b946ad62038", "price_changes": [{"asset_id": "97449340182256366014320155718265676486703217567849039806162053075113517266910", "price": "0.011", "size": "18.95", "side": "BUY", "hash": "cc0aa3c736afef0f61f63939362983fca85295f7", "best_bid": "0.065", "best_ask": "0.069"}, {"asset_id": "59259495934562596318644973716893809974860301509869285036503555129962149752635", "price": "0.989", "size": "18.95", "side": "SELL", "hash": "6675beed734d9e98b65a2652ae07ce436c3617e2", "best_bid": "0.931", "best_ask": "0.935"}], "timestamp": "1769384184025", "event_type": "price_change"}}
{"_local_timestamp": "2026-01-25T23:36:24.174100+00:00", "data": {"market": "0x22ac5f75af18fdb453497fbf7ac0606a09a6fd55b78b2d08aace6b946ad62038", "price_changes": [{"asset_id": "59259495934562596318644973716893809974860301509869285036503555129962149752635", "price": "0.989", "size": "217.83", "side": "SELL", "hash": "c05d38985b2b96b44f079ed1acfa3987e7a6357b", "best_bid": "0.931", "best_ask": "0.935"}, {"asset_id": "97449340182256366014320155718265676486703217567849039806162053075113517266910", "price": "0.011", "size": "217.83", "side": "BUY", "hash": "5ca214a6a8a2a3bb8d6d9a538aebc137d10f0c2c", "best_bid": "0.065", "best_ask": "0.069"}], "timestamp": "1769384184040", "event_type": "price_change"}}
{"_local_timestamp": "2026-01-25T23:36:25.052638+00:00", "data": {"market": "0x22ac5f75af18fdb453497fbf7ac0606a09a6fd55b78b2d08aace6b946ad62038", "price_changes": [{"asset_id": "97449340182256366014320155718265676486703217567849039806162053075113517266910", "price": "0.004", "size": "19.9", "side": "BUY", "hash": "9a5c4f0394f8ef38c82f8c42a4645b4480c34267", "best_bid": "0.065", "best_ask": "0.069"}, {"asset_id": "59259495934562596318644973716893809974860301509869285036503555129962149752635", "price": "0.996", "size": "19.9", "side": "SELL", "hash": "b7f0a7fe6c0bfd8957194299334f31cb7374a321", "best_bid": "0.931", "best_ask": "0.935"}], "timestamp": "1769384184980", "event_type": "price_change"}}
{"_local_timestamp": "2026-01-25T23:36:25.055559+00:00", "data": {"market": "0x22ac5f75af18fdb453497fbf7ac0606a09a6fd55b78b2d08aace6b946ad62038", "price_changes": [{"asset_id": "97449340182256366014320155718265676486703217567849039806162053075113517266910", "price": "0.011", "size": "198.88", "side": "BUY", "hash": "9a5c4f0394f8ef38c82f8c42a4645b4480c34267", "best_bid": "0.065", "best_ask": "0.069"}, {"asset_id": "59259495934562596318644973716893809974860301509869285036503555129962149752635", "price": "0.989", "size": "198.88", "side": "SELL", "hash": "b7f0a7fe6c0bfd8957194299334f31cb7374a321", "best_bid": "0.931", "best_ask": "0.935"}], "timestamp": "1769384184980", "event_type": "price_change"}}
{"_local_timestamp": "2026-01-25T23:36:25.320652+00:00", "data": {"market": "0x22ac5f75af18fdb453497fbf7ac0606a09a6fd55b78b2d08aace6b946ad62038", "price_changes": [{"asset_id": "97449340182256366014320155718265676486703217567849039806162053075113517266910", "price": "0.012", "size": "16.15", "side": "BUY", "hash": "12bf633e6d9a46ee7511b12bdb044b3468f85928", "best_bid": "0.065", "best_ask": "0.069"}, {"asset_id": "59259495934562596318644973716893809974860301509869285036503555129962149752635", "price": "0.988", "size": "16.15", "side": "SELL", "hash": "961d7aa1d9064f323214893c9b3b438a66440171", "best_bid": "0.931", "best_ask": "0.935"}], "timestamp": "1769384185229", "event_type": "price_change"}}
{"_local_timestamp": "2026-01-25T23:36:25.322284+00:00", "data": {"market": "0x22ac5f75af18fdb453497fbf7ac0606a09a6fd55b78b2d08aace6b946ad62038", "price_changes": [{"asset_id": "97449340182256366014320155718265676486703217567849039806162053075113517266910", "price": "0.009", "size": "138.23", "side": "BUY", "hash": "22462c68321aa22805467d0faa1c040417ef9841", "best_bid": "0.065", "best_ask": "0.069"}, {"asset_id": "59259495934562596318644973716893809974860301509869285036503555129962149752635", "price": "0.991", "size": "138.23", "side": "SELL", "hash": "34b5d52f4bb9d8b8b199139ada6add6816a696ef", "best_bid": "0.931", "best_ask": "0.935"}], "timestamp": "1769384185230", "event_type": "price_change"}}
{"_local_timestamp": "2026-01-25T23:36:25.897603+00:00", "data": {"market": "0x22ac5f75af18fdb453497fbf7ac0606a09a6fd55b78b2d08aace6b946ad62038", "price_changes": [{"asset_id": "59259495934562596318644973716893809974860301509869285036503555129962149752635", "price": "0.989", "size": "0", "side": "SELL", "hash": "3117d7b61ef677d5d4bdc833347b5addf0863a53", "best_bid": "0.931", "best_ask": "0.935"}, {"asset_id": "97449340182256366014320155718265676486703217567849039806162053075113517266910", "price": "0.011", "size": "0", "side": "BUY", "hash": "c55b1dd694785c6eda6acec4fa9695bda76df689", "best_bid": "0.065", "best_ask": "0.069"}], "timestamp": "1769384185828", "event_type": "price_change"}}
{"_local_timestamp": "2026-01-25T23:36:26.235121+00:00", "data": {"market": "0x22ac5f75af18fdb453497fbf7ac0606a09a6fd55b78b2d08aace6b946ad62038", "price_changes": [{"asset_id": "97449340182256366014320155718265676486703217567849039806162053075113517266910", "price": "0.009", "size": "133.06", "side": "BUY", "hash": "ad96a8cfcb9344da2703d3c0e881c303b4473813", "best_bid": "0.065", "best_ask": "0.069"}, {"asset_id": "59259495934562596318644973716893809974860301509869285036503555129962149752635", "price": "0.991", "size": "133.06", "side": "SELL", "hash": "91e2c2c06beb9c2c73ebea791523f5408382670e", "best_bid": "0.931", "best_ask": "0.935"}], "timestamp": "1769384186157", "event_type": "price_change"}}
{"_local_timestamp": "2026-01-25T23:36:26.235807+00:00", "data": {"market": "0x22ac5f75af18fdb453497fbf7ac0606a09a6fd55b78b2d08aace6b946ad62038", "price_changes": [{"asset_id": "97449340182256366014320155718265676486703217567849039806162053075113517266910", "price": "0.012", "size": "0", "side": "BUY", "hash": "ad96a8cfcb9344da2703d3c0e881c303b4473813", "best_bid": "0.065", "best_ask": "0.069"}, {"asset_id": "59259495934562596318644973716893809974860301509869285036503555129962149752635", "price": "0.988", "size": "0", "side": "SELL", "hash": "91e2c2c06beb9c2c73ebea791523f5408382670e", "best_bid": "0.931", "best_ask": "0.935"}], "timestamp": "1769384186157", "event_type": "price_change"}}
{"_local_timestamp": "2026-01-25T23:36:26.691670+00:00", "data": {"market": "0x22ac5f75af18fdb453497fbf7ac0606a09a6fd55b78b2d08aace6b946ad62038", "price_changes": [{"asset_id": "97449340182256366014320155718265676486703217567849039806162053075113517266910", "price": "0.013", "size": "13.72", "side": "BUY", "hash": "58e15efb25da7e733a915dd67e5097a53f29bd9a", "best_bid": "0.065", "best_ask": "0.069"}, {"asset_id": "59259495934562596318644973716893809974860301509869285036503555129962149752635", "price": "0.987", "size": "13.72", "side": "SELL", "hash": "5aefd2a7f186ac4be4c501e9cf8a761e001cb49e", "best_bid": "0.931", "best_ask": "0.935"}], "timestamp": "1769384186605", "event_type": "price_change"}}
{"_local_timestamp": "2026-01-25T23:36:26.692317+00:00", "data": {"market": "0x22ac5f75af18fdb453497fbf7ac0606a09a6fd55b78b2d08aace6b946ad62038", "price_changes": [{"asset_id": "97449340182256366014320155718265676486703217567849039806162053075113517266910", "price": "0.009", "size": "139.94", "side": "BUY", "hash": "31854f6c6b6c54fa98a12c6b5a9ceb986adf9d3c", "best_bid": "0.065", "best_ask": "0.069"}, {"asset_id": "59259495934562596318644973716893809974860301509869285036503555129962149752635", "price": "0.991", "size": "139.94", "side": "SELL", "hash": "0709981ad1d58a9176743cbf720393aca427a235", "best_bid": "0.931", "best_ask": "0.935"}], "timestamp": "1769384186606", "event_type": "price_change"}}
{"_local_timestamp": "2026-01-25T23:36:27.681685+00:00", "data": {"market": "0x22ac5f75af18fdb453497fbf7ac0606a09a6fd55b78b2d08aace6b946ad62038", "price_changes": [{"asset_id": "97449340182256366014320155718265676486703217567849039806162053075113517266910", "price": "0.009", "size": "133.06", "side": "BUY", "hash": "2480db6d94f82d53f0d4e246c101b3fcb53527e1", "best_bid": "0.065", "best_ask": "0.069"}, {"asset_id": "59259495934562596318644973716893809974860301509869285036503555129962149752635", "price": "0.991", "size": "133.06", "side": "SELL", "hash": "4f82c9533377438cef86e9297ad059767fbb51bf", "best_bid": "0.931", "best_ask": "0.935"}], "timestamp": "1769384187616", "event_type": "price_change"}}
{"_local_timestamp": "2026-01-25T23:36:27.692449+00:00", "data": {"market": "0x22ac5f75af18fdb453497fbf7ac0606a09a6fd55b78b2d08aace6b946ad62038", "price_changes": [{"asset_id": "97449340182256366014320155718265676486703217567849039806162053075113517266910", "price": "0.013", "size": "0", "side": "BUY", "hash": "2480db6d94f82d53f0d4e246c101b3fcb53527e1", "best_bid": "0.065", "best_ask": "0.069"}, {"asset_id": "59259495934562596318644973716893809974860301509869285036503555129962149752635", "price": "0.987", "size": "0", "side": "SELL", "hash": "4f82c9533377438cef86e9297ad059767fbb51bf", "best_bid": "0.931", "best_ask": "0.935"}], "timestamp": "1769384187616", "event_type": "price_change"}}
{"_local_timestamp": "2026-01-25T23:36:27.694357+00:00", "data": {"market": "0x22ac5f75af18fdb453497fbf7ac0606a09a6fd55b78b2d08aace6b946ad62038", "price_changes": [{"asset_id": "59259495934562596318644973716893809974860301509869285036503555129962149752635", "price": "0.785", "size": "0", "side": "BUY", "hash": "127c89eca729fd68fb8642fb8d41aa36868ea092", "best_bid": "0.931", "best_ask": "0.935"}, {"asset_id": "97449340182256366014320155718265676486703217567849039806162053075113517266910", "price": "0.215", "size": "0", "side": "SELL", "hash": "9cacff1cabc0d311238ea22a57a8f9de116ba4da", "best_bid": "0.065", "best_ask": "0.069"}], "timestamp": "1769384187616", "event_type": "price_change"}}
{"_local_timestamp": "2026-01-25T23:36:27.933326+00:00", "data": {"market": "0x22ac5f75af18fdb453497fbf7ac0606a09a6fd55b78b2d08aace6b946ad62038", "price_changes": [{"asset_id": "59259495934562596318644973716893809974860301509869285036503555129962149752635", "price": "0.988", "size": "198.88", "side": "SELL", "hash": "2bd802e62eea07204f189953fee2fc6695ca038c", "best_bid": "0.931", "best_ask": "0.935"}, {"asset_id": "97449340182256366014320155718265676486703217567849039806162053075113517266910", "price": "0.012", "size": "198.88", "side": "BUY", "hash": "4ca6cb2bd91e95597b98e915df8f37acf2965a1f", "best_bid": "0.065", "best_ask": "0.069"}], "timestamp": "1769384187861", "event_type": "price_change"}}
{"_local_timestamp": "2026-01-25T23:36:28.044299+00:00", "data": {"market": "0x22ac5f75af18fdb453497fbf7ac0606a09a6fd55b78b2d08aace6b946ad62038", "price_changes": [{"asset_id": "97449340182256366014320155718265676486703217567849039806162053075113517266910", "price": "0.004", "size": "27.86", "side": "BUY", "hash": "1c6f5ae60135455e428fc04ef50b4e34626d43d3", "best_bid": "0.065", "best_ask": "0.069"}, {"asset_id": "59259495934562596318644973716893809974860301509869285036503555129962149752635", "price": "0.996", "size": "27.86", "side": "SELL", "hash": "57825af7b0a211960ee4bcd00fcbcc0fc94f16fe", "best_bid": "0.931", "best_ask": "0.935"}], "timestamp": "1769384187978", "event_type": "price_change"}}
{"_local_timestamp": "2026-01-25T23:36:28.045060+00:00", "data": {"market": "0x22ac5f75af18fdb453497fbf7ac0606a09a6fd55b78b2d08aace6b946ad62038", "price_changes": [{"asset_id": "59259495934562596318644973716893809974860301509869285036503555129962149752635", "price": "0.785", "size": "5", "side": "BUY", "hash": "56f7e5af9865949bb454021826c72ebd5e763365", "best_bid": "0.931", "best_ask": "0.935"}, {"asset_id": "97449340182256366014320155718265676486703217567849039806162053075113517266910", "price": "0.215", "size": "5", "side": "SELL", "hash": "0499e0afc894dc4b426d312781d8a1b56db5729a", "best_bid": "0.065", "best_ask": "0.069"}], "timestamp": "1769384187979", "event_type": "price_change"}}
{"_local_timestamp": "2026-01-25T23:36:28.050715+00:00", "data": {"market": "0x22ac5f75af18fdb453497fbf7ac0606a09a6fd55b78b2d08aace6b946ad62038", "price_changes": [{"asset_id": "97449340182256366014320155718265676486703217567849039806162053075113517266910", "price": "0.011", "size": "18.95", "side": "BUY", "hash": "936555d9e5e7b130873d318e883239ae3ec2df9e", "best_bid": "0.065", "best_ask": "0.069"}, {"asset_id": "59259495934562596318644973716893809974860301509869285036503555129962149752635", "price": "0.989", "size": "18.95", "side": "SELL", "hash": "2d25bebc4f52316155c2d75321a1def6e57f6f02", "best_bid": "0.931", "best_ask": "0.935"}], "timestamp": "1769384187980", "event_type": "price_change"}}
{"_local_timestamp": "2026-01-25T23:36:29.186345+00:00", "data": {"market": "0x22ac5f75af18fdb453497fbf7ac0606a09a6fd55b78b2d08aace6b946ad62038", "price_changes": [{"asset_id": "97449340182256366014320155718265676486703217567849039806162053075113517266910", "price": "0.004", "size": "19.9", "side": "BUY", "hash": "55535c420b1c22ecda0ca8face4b8fa49cbc5adf", "best_bid": "0.065", "best_ask": "0.069"}, {"asset_id": "59259495934562596318644973716893809974860301509869285036503555129962149752635", "price": "0.996", "size": "19.9", "side": "SELL", "hash": "35750dfdc7b9f1dc00ca0f4e3a9c64ccfd9cd845", "best_bid": "0.931", "best_ask": "0.935"}], "timestamp": "1769384189107", "event_type": "price_change"}}
{"_local_timestamp": "2026-01-25T23:36:29.187059+00:00", "data": {"market": "0x22ac5f75af18fdb453497fbf7ac0606a09a6fd55b78b2d08aace6b946ad62038", "price_changes": [{"asset_id": "97449340182256366014320155718265676486703217567849039806162053075113517266910", "price": "0.011", "size": "0", "side": "BUY", "hash": "55535c420b1c22ecda0ca8face4b8fa49cbc5adf", "best_bid": "0.065", "best_ask": "0.069"}, {"asset_id": "59259495934562596318644973716893809974860301509869285036503555129962149752635", "price": "0.989", "size": "0", "side": "SELL", "hash": "35750dfdc7b9f1dc00ca0f4e3a9c64ccfd9cd845", "best_bid": "0.931", "best_ask": "0.935"}], "timestamp": "1769384189107", "event_type": "price_change"}}
{"_local_timestamp": "2026-01-25T23:36:29.473515+00:00", "data": {"market": "0x22ac5f75af18fdb453497fbf7ac0606a09a6fd55b78b2d08aace6b946ad62038", "price_changes": [{"asset_id": "97449340182256366014320155718265676486703217567849039806162053075113517266910", "price": "0.013", "size": "13.72", "side": "BUY", "hash": "980b6375aa140e3e18fa427afc092d7b623124d3", "best_bid": "0.065", "best_ask": "0.069"}, {"asset_id": "59259495934562596318644973716893809974860301509869285036503555129962149752635", "price": "0.987", "size": "13.72", "side": "SELL", "hash": "2cdc3f883bf5af299415bb9754f7869a3060607e", "best_bid": "0.931", "best_ask": "0.935"}], "timestamp": "1769384189404", "event_type": "price_change"}}
{"_local_timestamp": "2026-01-25T23:36:29.474239+00:00", "data": {"market": "0x22ac5f75af18fdb453497fbf7ac0606a09a6fd55b78b2d08aace6b946ad62038", "price_changes": [{"asset_id": "97449340182256366014320155718265676486703217567849039806162053075113517266910", "price": "0.009", "size": "139.94", "side": "BUY", "hash": "ec83daabbe167605cc8f7c751227db4873aab0f2", "best_bid": "0.065", "best_ask": "0.069"}, {"asset_id": "59259495934562596318644973716893809974860301509869285036503555129962149752635", "price": "0.991", "size": "139.94", "side": "SELL", "hash": "0d395a34de95b0a7f150d2578acf8543dee8361f", "best_bid": "0.931", "best_ask": "0.935"}], "timestamp": "1769384189405", "event_type": "price_change"}}
{"_local_timestamp": "2026-01-25T23:36:30.908230+00:00", "data": {"market": "0x22ac5f75af18fdb453497fbf7ac0606a09a6fd55b78b2d08aace6b946ad62038", "price_changes": [{"asset_id": "59259495934562596318644973716893809974860301509869285036503555129962149752635", "price": "0.988", "size": "0", "side": "SELL", "hash": "987372073f45a32e2acac3b90fcb677d7f136072", "best_bid": "0.931", "best_ask": "0.935"}, {"asset_id": "97449340182256366014320155718265676486703217567849039806162053075113517266910", "price": "0.012", "size": "0", "side": "BUY", "hash": "2ee141c7d98d3edbd99163d7d748aa70a768d807", "best_bid": "0.065", "best_ask": "0.069"}], "timestamp": "1769384190838", "event_type": "price_change"}}
{"_local_timestamp": "2026-01-25T23:36:32.847122+00:00", "data": {"market": "0x22ac5f75af18fdb453497fbf7ac0606a09a6fd55b78b2d08aace6b946ad62038", "price_changes": [{"asset_id": "97449340182256366014320155718265676486703217567849039806162053075113517266910", "price": "0.009", "size": "133.06", "side": "BUY", "hash": "6d6f4738df7baab186e278166b1c8ef196d2ac29", "best_bid": "0.065", "best_ask": "0.069"}, {"asset_id": "59259495934562596318644973716893809974860301509869285036503555129962149752635", "price": "0.991", "size": "133.06", "side": "SELL", "hash": "a25f5f740626c9ca78939bcf39b2ba1ab6fd6e16", "best_bid": "0.931", "best_ask": "0.935"}], "timestamp": "1769384192766", "event_type": "price_change"}}
{"_local_timestamp": "2026-01-25T23:36:32.847830+00:00", "data": {"market": "0x22ac5f75af18fdb453497fbf7ac0606a09a6fd55b78b2d08aace6b946ad62038", "price_changes": [{"asset_id": "97449340182256366014320155718265676486703217567849039806162053075113517266910", "price": "0.013", "size": "0", "side": "BUY", "hash": "6d6f4738df7baab186e278166b1c8ef196d2ac29", "best_bid": "0.065", "best_ask": "0.069"}, {"asset_id": "59259495934562596318644973716893809974860301509869285036503555129962149752635", "price": "0.987", "size": "0", "side": "SELL", "hash": "a25f5f740626c9ca78939bcf39b2ba1ab6fd6e16", "best_bid": "0.931", "best_ask": "0.935"}], "timestamp": "1769384192766", "event_type": "price_change"}}
{"_local_timestamp": "2026-01-25T23:36:33.170051+00:00", "data": {"market": "0x22ac5f75af18fdb453497fbf7ac0606a09a6fd55b78b2d08aace6b946ad62038", "price_changes": [{"asset_id": "97449340182256366014320155718265676486703217567849039806162053075113517266910", "price": "0.011", "size": "18.95", "side": "BUY", "hash": "9ce0bdc9c5584ef19f648345cfff30b1e08fa794", "best_bid": "0.065", "best_ask": "0.069"}, {"asset_id": "59259495934562596318644973716893809974860301509869285036503555129962149752635", "price": "0.989", "size": "18.95", "side": "SELL", "hash": "fe5dbef01ba212f2abf7b44b90ccb3494ce1d692", "best_bid": "0.931", "best_ask": "0.935"}], "timestamp": "1769384193102", "event_type": "price_change"}}
{"_local_timestamp": "2026-01-25T23:36:33.176003+00:00", "data": {"market": "0x22ac5f75af18fdb453497fbf7ac0606a09a6fd55b78b2d08aace6b946ad62038", "price_changes": [{"asset_id": "97449340182256366014320155718265676486703217567849039806162053075113517266910", "price": "0.004", "size": "27.86", "side": "BUY", "hash": "d784032fc4b999c9556717ddaaff0abd49f75632", "best_bid": "0.065", "best_ask": "0.069"}, {"asset_id": "59259495934562596318644973716893809974860301509869285036503555129962149752635", "price": "0.996", "size": "27.86", "side": "SELL", "hash": "c4aca43342db77f90442318a423974b78e5731da", "best_bid": "0.931", "best_ask": "0.935"}], "timestamp": "1769384193106", "event_type": "price_change"}}
{"_local_timestamp": "2026-01-25T23:36:33.637610+00:00", "data": {"market": "0x22ac5f75af18fdb453497fbf7ac0606a09a6fd55b78b2d08aace6b946ad62038", "price_changes": [{"asset_id": "59259495934562596318644973716893809974860301509869285036503555129962149752635", "price": "0.989", "size": "217.83", "side": "SELL", "hash": "eceae49bd31732254fb4e70fda6eb1a3800c82c9", "best_bid": "0.931", "best_ask": "0.935"}, {"asset_id": "97449340182256366014320155718265676486703217567849039806162053075113517266910", "price": "0.011", "size": "217.83", "side": "BUY", "hash": "d7c38a1835308b09220be869930badbc54e47959", "best_bid": "0.065", "best_ask": "0.069"}], "timestamp": "1769384193564", "event_type": "price_change"}}
{"_local_timestamp": "2026-01-25T23:36:34.603994+00:00", "data": {"market": "0x22ac5f75af18fdb453497fbf7ac0606a09a6fd55b78b2d08aace6b946ad62038", "price_changes": [{"asset_id": "97449340182256366014320155718265676486703217567849039806162053075113517266910", "price": "0.004", "size": "19.9", "side": "BUY", "hash": "b30c2fab09092b4d40037cb88d6354aa8142cd72", "best_bid": "0.065", "best_ask": "0.069"}, {"asset_id": "59259495934562596318644973716893809974860301509869285036503555129962149752635", "price": "0.996", "size": "19.9", "side": "SELL", "hash": "3bcdb59082522233889158ee21a3a5786d5acb4c", "best_bid": "0.931", "best_ask": "0.935"}], "timestamp": "1769384194532", "event_type": "price_change"}}
{"_local_timestamp": "2026-01-25T23:36:34.604736+00:00", "data": {"market": "0x22ac5f75af18fdb453497fbf7ac0606a09a6fd55b78b2d08aace6b946ad62038", "price_changes": [{"asset_id": "97449340182256366014320155718265676486703217567849039806162053075113517266910", "price": "0.011", "size": "198.88", "side": "BUY", "hash": "b30c2fab09092b4d40037cb88d6354aa8142cd72", "best_bid": "0.065", "best_ask": "0.069"}, {"asset_id": "59259495934562596318644973716893809974860301509869285036503555129962149752635", "price": "0.989", "size": "198.88", "side": "SELL", "hash": "3bcdb59082522233889158ee21a3a5786d5acb4c", "best_bid": "0.931", "best_ask": "0.935"}], "timestamp": "1769384194532", "event_type": "price_change"}}
{"_local_timestamp": "2026-01-25T23:36:34.910593+00:00", "data": {"market": "0x22ac5f75af18fdb453497fbf7ac0606a09a6fd55b78b2d08aace6b946ad62038", "price_changes": [{"asset_id": "97449340182256366014320155718265676486703217567849039806162053075113517266910", "price": "0.005", "size": "6.69", "side": "BUY", "hash": "32d68a435d6a8954ab2cddd30f2544b6fa3981ac", "best_bid": "0.065", "best_ask": "0.069"}, {"asset_id": "59259495934562596318644973716893809974860301509869285036503555129962149752635", "price": "0.995", "size": "6.69", "side": "SELL", "hash": "b7a8da80e1c6db98ad4cf2d21fbe07564ef0fa71", "best_bid": "0.931", "best_ask": "0.935"}], "timestamp": "1769384194838", "event_type": "price_change"}}
{"_local_timestamp": "2026-01-25T23:36:34.913426+00:00", "data": {"market": "0x22ac5f75af18fdb453497fbf7ac0606a09a6fd55b78b2d08aace6b946ad62038", "price_changes": [{"asset_id": "97449340182256366014320155718265676486703217567849039806162053075113517266910", "price": "0.012", "size": "17.24", "side": "BUY", "hash": "3b1480f316507e6ee770c2b4997199c36a2d27a9", "best_bid": "0.065", "best_ask": "0.069"}, {"asset_id": "59259495934562596318644973716893809974860301509869285036503555129962149752635", "price": "0.988", "size": "17.24", "side": "SELL", "hash": "1a7a902566dafed4998dba638522554ff2f0d494", "best_bid": "0.931", "best_ask": "0.935"}], "timestamp": "1769384194840", "event_type": "price_change"}}
{"_local_timestamp": "2026-01-25T23:36:35.347808+00:00", "data": {"market": "0x22ac5f75af18fdb453497fbf7ac0606a09a6fd55b78b2d08aace6b946ad62038", "price_changes": [{"asset_id": "59259495934562596318644973716893809974860301509869285036503555129962149752635", "price": "0.785", "size": "0", "side": "BUY", "hash": "f6cde82a9da9ae42a5b5356d2557785ce9e23f23", "best_bid": "0.931", "best_ask": "0.935"}, {"asset_id": "97449340182256366014320155718265676486703217567849039806162053075113517266910", "price": "0.215", "size": "0", "side": "SELL", "hash": "a807637ca6ec97a92f174bfe65ddcbfd3d195621", "best_bid": "0.065", "best_ask": "0.069"}], "timestamp": "1769384195278", "event_type": "price_change"}}
{"_local_timestamp": "2026-01-25T23:36:35.682412+00:00", "data": {"market": "0x22ac5f75af18fdb453497fbf7ac0606a09a6fd55b78b2d08aace6b946ad62038", "price_changes": [{"asset_id": "59259495934562596318644973716893809974860301509869285036503555129962149752635", "price": "0.785", "size": "5", "side": "BUY", "hash": "d74a966bcba5d89c962cc21d138b68e25d5fabcc", "best_bid": "0.931", "best_ask": "0.935"}, {"asset_id": "97449340182256366014320155718265676486703217567849039806162053075113517266910", "price": "0.215", "size": "5", "side": "SELL", "hash": "9e1c00de1f38cedd3ea46aee798a4634527ccd71", "best_bid": "0.065", "best_ask": "0.069"}], "timestamp": "1769384195616", "event_type": "price_change"}}
{"_local_timestamp": "2026-01-25T23:36:36.112640+00:00", "data": {"market": "0x22ac5f75af18fdb453497fbf7ac0606a09a6fd55b78b2d08aace6b946ad62038", "price_changes": [{"asset_id": "97449340182256366014320155718265676486703217567849039806162053075113517266910", "price": "0.005", "size": "0", "side": "BUY", "hash": "b6595cc22575e1b1f430738a3eb1c01cf01c973f", "best_bid": "0.065", "best_ask": "0.069"}, {"asset_id": "59259495934562596318644973716893809974860301509869285036503555129962149752635", "price": "0.995", "size": "0", "side": "SELL", "hash": "4d00d37f41ccbce6ceac2ae434e99136d98805a5", "best_bid": "0.931", "best_ask": "0.935"}], "timestamp": "1769384196013", "event_type": "price_change"}}
{"_local_timestamp": "2026-01-25T23:36:36.272772+00:00", "data": {"market": "0x22ac5f75af18fdb453497fbf7ac0606a09a6fd55b78b2d08aace6b946ad62038", "price_changes": [{"asset_id": "59259495934562596318644973716893809974860301509869285036503555129962149752635", "price": "0.989", "size": "0", "side": "SELL", "hash": "ee48d4739558b352c86eecefb47f11af1f7ca376", "best_bid": "0.931", "best_ask": "0.935"}, {"asset_id": "97449340182256366014320155718265676486703217567849039806162053075113517266910", "price": "0.011", "size": "0", "side": "BUY", "hash": "6e54fb8d7fd8bd7a27f5f0467d6dfab5bae44092", "best_bid": "0.065", "best_ask": "0.069"}], "timestamp": "1769384196209", "event_type": "price_change"}}
{"_local_timestamp": "2026-01-25T23:36:36.502499+00:00", "data": {"market": "0x22ac5f75af18fdb453497fbf7ac0606a09a6fd55b78b2d08aace6b946ad62038", "price_changes": [{"asset_id": "97449340182256366014320155718265676486703217567849039806162053075113517266910", "price": "0.004", "size": "28.27", "side": "BUY", "hash": "b3a90d62b4dab5fa7de912e18b08f6dca7daded1", "best_bid": "0.065", "best_ask": "0.069"}, {"asset_id": "59259495934562596318644973716893809974860301509869285036503555129962149752635", "price": "0.996", "size": "28.27", "side": "SELL", "hash": "5dd5011d67342343a9b7653e4d5bcdcb46f9cbd4", "best_bid": "0.931", "best_ask": "0.935"}], "timestamp": "1769384196435", "event_type": "price_change"}}
{"_local_timestamp": "2026-01-25T23:36:38.241530+00:00", "data": {"market": "0x22ac5f75af18fdb453497fbf7ac0606a09a6fd55b78b2d08aace6b946ad62038", "price_changes": [{"asset_id": "97449340182256366014320155718265676486703217567849039806162053075113517266910", "price": "0.012", "size": "0", "side": "BUY", "hash": "62882bdb04eaf5cfb450bc90afe7d340a2a6b00d", "best_bid": "0.065", "best_ask": "0.069"}, {"asset_id": "59259495934562596318644973716893809974860301509869285036503555129962149752635", "price": "0.988", "size": "0", "side": "SELL", "hash": "816fc12a1a40a67542d2f93c6bf10a6eedca07f9", "best_bid": "0.931", "best_ask": "0.935"}], "timestamp": "1769384198169", "event_type": "price_change"}}
{"_local_timestamp": "2026-01-25T23:36:38.506270+00:00", "data": {"market": "0x22ac5f75af18fdb453497fbf7ac0606a09a6fd55b78b2d08aace6b946ad62038", "price_changes": [{"asset_id": "97449340182256366014320155718265676486703217567849039806162053075113517266910", "price": "0.011", "size": "18.8", "side": "BUY", "hash": "519c4a757bdf6aa6d64c68facd4d1432722b39fc", "best_bid": "0.065", "best_ask": "0.069"}, {"asset_id": "59259495934562596318644973716893809974860301509869285036503555129962149752635", "price": "0.989", "size": "18.8", "side": "SELL", "hash": "4497ed67e639cebc1bc76ae81d3ec6b8d362f864", "best_bid": "0.931", "best_ask": "0.935"}], "timestamp": "1769384198441", "event_type": "price_change"}}
{"_local_timestamp": "2026-01-25T23:36:39.019872+00:00", "data": {"market": "0x22ac5f75af18fdb453497fbf7ac0606a09a6fd55b78b2d08aace6b946ad62038", "price_changes": [{"asset_id": "59259495934562596318644973716893809974860301509869285036503555129962149752635", "price": "0.988", "size": "198.88", "side": "SELL", "hash": "3ecc54a248b32b9021c53e250c298676e84d9130", "best_bid": "0.931", "best_ask": "0.935"}, {"asset_id": "97449340182256366014320155718265676486703217567849039806162053075113517266910", "price": "0.012", "size": "198.88", "side": "BUY", "hash": "2ab4050fbdb03c0618e8e786bb58e1cf1a073d60", "best_bid": "0.065", "best_ask": "0.069"}], "timestamp": "1769384198952", "event_type": "price_change"}}
{"_local_timestamp": "2026-01-25T23:36:40.415742+00:00", "data": {"market": "0x22ac5f75af18fdb453497fbf7ac0606a09a6fd55b78b2d08aace6b946ad62038", "price_changes": [{"asset_id": "97449340182256366014320155718265676486703217567849039806162053075113517266910", "price": "0.004", "size": "19.9", "side": "BUY", "hash": "dccc7340155997e90feb31ff493eed8feef3337f", "best_bid": "0.065", "best_ask": "0.069"}, {"asset_id": "59259495934562596318644973716893809974860301509869285036503555129962149752635", "price": "0.996", "size": "19.9", "side": "SELL", "hash": "03031c102903c07f9ea791f828ff25d42c502d9c", "best_bid": "0.931", "best_ask": "0.935"}], "timestamp": "1769384200334", "event_type": "price_change"}}
{"_local_timestamp": "2026-01-25T23:36:40.416432+00:00", "data": {"market": "0x22ac5f75af18fdb453497fbf7ac0606a09a6fd55b78b2d08aace6b946ad62038", "price_changes": [{"asset_id": "97449340182256366014320155718265676486703217567849039806162053075113517266910", "price": "0.011", "size": "0", "side": "BUY", "hash": "dccc7340155997e90feb31ff493eed8feef3337f", "best_bid": "0.065", "best_ask": "0.069"}, {"asset_id": "59259495934562596318644973716893809974860301509869285036503555129962149752635", "price": "0.989", "size": "0", "side": "SELL", "hash": "03031c102903c07f9ea791f828ff25d42c502d9c", "best_bid": "0.931", "best_ask": "0.935"}], "timestamp": "1769384200334", "event_type": "price_change"}}
{"_local_timestamp": "2026-01-25T23:36:40.759682+00:00", "data": {"market": "0x22ac5f75af18fdb453497fbf7ac0606a09a6fd55b78b2d08aace6b946ad62038", "price_changes": [{"asset_id": "97449340182256366014320155718265676486703217567849039806162053075113517266910", "price": "0.005", "size": "5.79", "side": "BUY", "hash": "53d65bd8a0fd28bdee46f818f85534368568406e", "best_bid": "0.065", "best_ask": "0.069"}, {"asset_id": "59259495934562596318644973716893809974860301509869285036503555129962149752635", "price": "0.995", "size": "5.79", "side": "SELL", "hash": "850f9a52a42cc5d04f0ec5a3ebfc9d8d052d3d8d", "best_bid": "0.931", "best_ask": "0.935"}], "timestamp": "1769384200678", "event_type": "price_change"}}
{"_local_timestamp": "2026-01-25T23:36:40.760419+00:00", "data": {"market": "0x22ac5f75af18fdb453497fbf7ac0606a09a6fd55b78b2d08aace6b946ad62038", "price_changes": [{"asset_id": "97449340182256366014320155718265676486703217567849039806162053075113517266910", "price": "0.013", "size": "12.07", "side": "BUY", "hash": "9c30a9878524beccf795723764a86545367e9acf", "best_bid": "0.065", "best_ask": "0.069"}, {"asset_id": "59259495934562596318644973716893809974860301509869285036503555129962149752635", "price": "0.987", "size": "12.07", "side": "SELL", "hash": "5b218f25bf334db5f4f4205ee265d24377a1856d", "best_bid": "0.931", "best_ask": "0.935"}], "timestamp": "1769384200679", "event_type": "price_change"}}
{"_local_timestamp": "2026-01-25T23:36:40.761096+00:00", "data": {"market": "0x22ac5f75af18fdb453497fbf7ac0606a09a6fd55b78b2d08aace6b946ad62038", "price_changes": [{"asset_id": "97449340182256366014320155718265676486703217567849039806162053075113517266910", "price": "0.009", "size": "139.11", "side": "BUY", "hash": "848983f5afc59dc5a02872605e8c2c9a6b0121bf", "best_bid": "0.065", "best_ask": "0.069"}, {"asset_id": "59259495934562596318644973716893809974860301509869285036503555129962149752635", "price": "0.991", "size": "139.11", "side": "SELL", "hash": "2e58a6f87573bb53c40e37d0976adbf148b4108e", "best_bid": "0.931", "best_ask": "0.935"}], "timestamp": "1769384200680", "event_type": "price_change"}}
{"_local_timestamp": "2026-01-25T23:36:41.873450+00:00", "data": {"market": "0x22ac5f75af18fdb453497fbf7ac0606a09a6fd55b78b2d08aace6b946ad62038", "price_changes": [{"asset_id": "97449340182256366014320155718265676486703217567849039806162053075113517266910", "price": "0.005", "size": "0", "side": "BUY", "hash": "11633f61a31dd34bcfa0a87dbba27fbe8e640770", "best_bid": "0.065", "best_ask": "0.069"}, {"asset_id": "59259495934562596318644973716893809974860301509869285036503555129962149752635", "price": "0.995", "size": "0", "side": "SELL", "hash": "fec273d79e1194259d73a22c8fdbfc97ebb974dc", "best_bid": "0.931", "best_ask": "0.935"}], "timestamp": "1769384201805", "event_type": "price_change"}}
{"_local_timestamp": "2026-01-25T23:36:42.282633+00:00", "data": {"market": "0x22ac5f75af18fdb453497fbf7ac0606a09a6fd55b78b2d08aace6b946ad62038", "price_changes": [{"asset_id": "97449340182256366014320155718265676486703217567849039806162053075113517266910", "price": "0.004", "size": "27.15", "side": "BUY", "hash": "118732f0023f1eb8d59508af8a619809c9503cb5", "best_bid": "0.065", "best_ask": "0.069"}, {"asset_id": "59259495934562596318644973716893809974860301509869285036503555129962149752635", "price": "0.996", "size": "27.15", "side": "SELL", "hash": "c75f3fa997270318f574c65838897f60373b451e", "best_bid": "0.931", "best_ask": "0.935"}], "timestamp": "1769384202208", "event_type": "price_change"}}
{"_local_timestamp": "2026-01-25T23:36:42.645580+00:00", "data": {"market": "0x22ac5f75af18fdb453497fbf7ac0606a09a6fd55b78b2d08aace6b946ad62038", "price_changes": [{"asset_id": "59259495934562596318644973716893809974860301509869285036503555129962149752635", "price": "0.988", "size": "0", "side": "SELL", "hash": "a95653cb00111b8992d0f0e74f3e747fd7401cfb", "best_bid": "0.931", "best_ask": "0.935"}, {"asset_id": "97449340182256366014320155718265676486703217567849039806162053075113517266910", "price": "0.012", "size": "0", "side": "BUY", "hash": "5ab1ce212923a1f0a43297dc09d8fe76d1a73919", "best_bid": "0.065", "best_ask": "0.069"}], "timestamp": "1769384202582", "event_type": "price_change"}}
{"_local_timestamp": "2026-01-25T23:36:42.741612+00:00", "data": {"market": "0x22ac5f75af18fdb453497fbf7ac0606a09a6fd55b78b2d08aace6b946ad62038", "price_changes": [{"asset_id": "59259495934562596318644973716893809974860301509869285036503555129962149752635", "price": "0.785", "size": "0", "side": "BUY", "hash": "2707e143bb944db67f6824b89bcf4637bf1b4165", "best_bid": "0.931", "best_ask": "0.935"}, {"asset_id": "97449340182256366014320155718265676486703217567849039806162053075113517266910", "price": "0.215", "size": "0", "side": "SELL", "hash": "18aca01cec242f7e9d73361a9c4e1d6c9fafb11d", "best_bid": "0.065", "best_ask": "0.069"}], "timestamp": "1769384202674", "event_type": "price_change"}}
{"_local_timestamp": "2026-01-25T23:36:43.125945+00:00", "data": {"market": "0x22ac5f75af18fdb453497fbf7ac0606a09a6fd55b78b2d08aace6b946ad62038", "price_changes": [{"asset_id": "59259495934562596318644973716893809974860301509869285036503555129962149752635", "price": "0.785", "size": "5", "side": "BUY", "hash": "43516189536cd5d06adfe62ce129a9cfd3c70d46", "best_bid": "0.931", "best_ask": "0.935"}, {"asset_id": "97449340182256366014320155718265676486703217567849039806162053075113517266910", "price": "0.215", "size": "5", "side": "SELL", "hash": "4e7c515edbedd2c2af58b40fce157bf11643878b", "best_bid": "0.065", "best_ask": "0.069"}], "timestamp": "1769384203054", "event_type": "price_change"}}
{"_local_timestamp": "2026-01-25T23:36:43.470176+00:00", "data": {"market": "0x22ac5f75af18fdb453497fbf7ac0606a09a6fd55b78b2d08aace6b946ad62038", "price_changes": [{"asset_id": "97449340182256366014320155718265676486703217567849039806162053075113517266910", "price": "0.009", "size": "133.06", "side": "BUY", "hash": "48179689895acc8afa164d70706bdfcc8e54f34e", "best_bid": "0.065", "best_ask": "0.069"}, {"asset_id": "59259495934562596318644973716893809974860301509869285036503555129962149752635", "price": "0.991", "size": "133.06", "side": "SELL", "hash": "fe50c40d69918476a9e75c744003b9721bddaba8", "best_bid": "0.931", "best_ask": "0.935"}], "timestamp": "1769384203405", "event_type": "price_change"}}
{"_local_timestamp": "2026-01-25T23:36:43.470905+00:00", "data": {"market": "0x22ac5f75af18fdb453497fbf7ac0606a09a6fd55b78b2d08aace6b946ad62038", "price_changes": [{"asset_id": "97449340182256366014320155718265676486703217567849039806162053075113517266910", "price": "0.013", "size": "0", "side": "BUY", "hash": "48179689895acc8afa164d70706bdfcc8e54f34e", "best_bid": "0.065", "best_ask": "0.069"}, {"asset_id": "59259495934562596318644973716893809974860301509869285036503555129962149752635", "price": "0.987", "size": "0", "side": "SELL", "hash": "fe50c40d69918476a9e75c744003b9721bddaba8", "best_bid": "0.931", "best_ask": "0.935"}], "timestamp": "1769384203405", "event_type": "price_change"}}
{"_local_timestamp": "2026-01-25T23:36:43.915548+00:00", "data": {"market": "0x22ac5f75af18fdb453497fbf7ac0606a09a6fd55b78b2d08aace6b946ad62038", "price_changes": [{"asset_id": "97449340182256366014320155718265676486703217567849039806162053075113517266910", "price": "0.011", "size": "19.21", "side": "BUY", "hash": "68443fa7a3209a8e9ab3aa299c49fd2b191c3fbf", "best_bid": "0.065", "best_ask": "0.069"}, {"asset_id": "59259495934562596318644973716893809974860301509869285036503555129962149752635", "price": "0.989", "size": "19.21", "side": "SELL", "hash": "fee52c0e8e32f681198937f7834092b922e242c7", "best_bid": "0.931", "best_ask": "0.935"}], "timestamp": "1769384203849", "event_type": "price_change"}}
{"_local_timestamp": "2026-01-25T23:36:45.712745+00:00", "data": {"market": "0x22ac5f75af18fdb453497fbf7ac0606a09a6fd55b78b2d08aace6b946ad62038", "price_changes": [{"asset_id": "59259495934562596318644973716893809974860301509869285036503555129962149752635", "price": "0.989", "size": "218.09", "side": "SELL", "hash": "93c27fe7344750520b2af120071cac102352ec66", "best_bid": "0.931", "best_ask": "0.935"}, {"asset_id": "97449340182256366014320155718265676486703217567849039806162053075113517266910", "price": "0.011", "size": "218.09", "side": "BUY", "hash": "7a5727c76dbeed39599f642cf24ea0d7e71ceca5", "best_bid": "0.065", "best_ask": "0.069"}], "timestamp": "1769384205645", "event_type": "price_change"}}
{"_local_timestamp": "2026-01-25T23:36:47.162474+00:00", "data": {"market": "0x22ac5f75af18fdb453497fbf7ac0606a09a6fd55b78b2d08aace6b946ad62038", "price_changes": [{"asset_id": "97449340182256366014320155718265676486703217567849039806162053075113517266910", "price": "0.004", "size": "19.31", "side": "BUY", "hash": "e0bb39e7ed3893737622b94f0b175573b9690b36", "best_bid": "0.065", "best_ask": "0.069"}, {"asset_id": "59259495934562596318644973716893809974860301509869285036503555129962149752635", "price": "0.996", "size": "19.31", "side": "SELL", "hash": "49df3fba1b0ac6b624a4e8e3d4def851d38f06e5", "best_bid": "0.931", "best_ask": "0.935"}], "timestamp": "1769384207090", "event_type": "price_change"}}
{"_local_timestamp": "2026-01-25T23:36:47.163501+00:00", "data": {"market": "0x22ac5f75af18fdb453497fbf7ac0606a09a6fd55b78b2d08aace6b946ad62038", "price_changes": [{"asset_id": "97449340182256366014320155718265676486703217567849039806162053075113517266910", "price": "0.011", "size": "198.88", "side": "BUY", "hash": "e0bb39e7ed3893737622b94f0b175573b9690b36", "best_bid": "0.065", "best_ask": "0.069"}, {"asset_id": "59259495934562596318644973716893809974860301509869285036503555129962149752635", "price": "0.989", "size": "198.88", "side": "SELL", "hash": "49df3fba1b0ac6b624a4e8e3d4def851d38f06e5", "best_bid": "0.931", "best_ask": "0.935"}], "timestamp": "1769384207090", "event_type": "price_change"}}
{"_local_timestamp": "2026-01-25T23:36:47.446379+00:00", "data": {"market": "0x22ac5f75af18fdb453497fbf7ac0606a09a6fd55b78b2d08aace6b946ad62038", "price_changes": [{"asset_id": "97449340182256366014320155718265676486703217567849039806162053075113517266910", "price": "0.009", "size": "138.28", "side": "BUY", "hash": "e34f0ece66413f87ad9aae4017713711c3100e56", "best_bid": "0.065", "best_ask": "0.069"}, {"asset_id": "59259495934562596318644973716893809974860301509869285036503555129962149752635", "price": "0.991", "size": "138.28", "side": "SELL", "hash": "d461bc9f98a5fe464fad555302d2fe6a071ceb12", "best_bid": "0.931", "best_ask": "0.935"}], "timestamp": "1769384207379", "event_type": "price_change"}}
{"_local_timestamp": "2026-01-25T23:36:47.454653+00:00", "data": {"market": "0x22ac5f75af18fdb453497fbf7ac0606a09a6fd55b78b2d08aace6b946ad62038", "price_changes": [{"asset_id": "97449340182256366014320155718265676486703217567849039806162053075113517266910", "price": "0.012", "size": "16.31", "side": "BUY", "hash": "c3fee617ed5977d78db66dafab60260cdf269396", "best_bid": "0.065", "best_ask": "0.069"}, {"asset_id": "59259495934562596318644973716893809974860301509869285036503555129962149752635", "price": "0.988", "size": "16.31", "side": "SELL", "hash": "bfde33953eae078410b3a4da28961f2d9025d8dc", "best_bid": "0.931", "best_ask": "0.935"}], "timestamp": "1769384207385", "event_type": "price_change"}}
{"_local_timestamp": "2026-01-25T23:36:47.738135+00:00", "data": {"market": "0x22ac5f75af18fdb453497fbf7ac0606a09a6fd55b78b2d08aace6b946ad62038", "price_changes": [{"asset_id": "59259495934562596318644973716893809974860301509869285036503555129962149752635", "price": "0.989", "size": "0", "side": "SELL", "hash": "920965b44fbdfe7906c2d8dbdb7d544599ca7739", "best_bid": "0.931", "best_ask": "0.935"}, {"asset_id": "97449340182256366014320155718265676486703217567849039806162053075113517266910", "price": "0.011", "size": "0", "side": "BUY", "hash": "6db339b618400fdb58986c3496116d9510f85b8a", "best_bid": "0.065", "best_ask": "0.069"}], "timestamp": "1769384207665", "event_type": "price_change"}}
{"_local_timestamp": "2026-01-25T23:36:48.618118+00:00", "data": {"market": "0x22ac5f75af18fdb453497fbf7ac0606a09a6fd55b78b2d08aace6b946ad62038", "price_changes": [{"asset_id": "97449340182256366014320155718265676486703217567849039806162053075113517266910", "price": "0.009", "size": "133.06", "side": "BUY", "hash": "d3e171fe8f235cd19ec6e2fc703a358c46e46bce", "best_bid": "0.065", "best_ask": "0.069"}, {"asset_id": "59259495934562596318644973716893809974860301509869285036503555129962149752635", "price": "0.991", "size": "133.06", "side": "SELL", "hash": "69329d1a716e9af920911fc7ff19d5002b166604", "best_bid": "0.931", "best_ask": "0.935"}], "timestamp": "1769384208552", "event_type": "price_change"}}
{"_local_timestamp": "2026-01-25T23:36:48.618974+00:00", "data": {"market": "0x22ac5f75af18fdb453497fbf7ac0606a09a6fd55b78b2d08aace6b946ad62038", "price_changes": [{"asset_id": "97449340182256366014320155718265676486703217567849039806162053075113517266910", "price": "0.012", "size": "0", "side": "BUY", "hash": "d3e171fe8f235cd19ec6e2fc703a358c46e46bce", "best_bid": "0.065", "best_ask": "0.069"}, {"asset_id": "59259495934562596318644973716893809974860301509869285036503555129962149752635", "price": "0.988", "size": "0", "side": "SELL", "hash": "69329d1a716e9af920911fc7ff19d5002b166604", "best_bid": "0.931", "best_ask": "0.935"}], "timestamp": "1769384208552", "event_type": "price_change"}}
{"_local_timestamp": "2026-01-25T23:36:49.038139+00:00", "data": {"market": "0x22ac5f75af18fdb453497fbf7ac0606a09a6fd55b78b2d08aace6b946ad62038", "price_changes": [{"asset_id": "97449340182256366014320155718265676486703217567849039806162053075113517266910", "price": "0.011", "size": "18.96", "side": "BUY", "hash": "248d0ba2690e331b0d3f260aab58fa28439a17fd", "best_bid": "0.065", "best_ask": "0.069"}, {"asset_id": "59259495934562596318644973716893809974860301509869285036503555129962149752635", "price": "0.989", "size": "18.96", "side": "SELL", "hash": "b10f9681087c812a54d1ccb6224fa991f7c9e9e0", "best_bid": "0.931", "best_ask": "0.935"}], "timestamp": "1769384208967", "event_type": "price_change"}}
{"_local_timestamp": "2026-01-25T23:36:49.039056+00:00", "data": {"market": "0x22ac5f75af18fdb453497fbf7ac0606a09a6fd55b78b2d08aace6b946ad62038", "price_changes": [{"asset_id": "97449340182256366014320155718265676486703217567849039806162053075113517266910", "price": "0.004", "size": "27.85", "side": "BUY", "hash": "c84a6d669480b3e08360e73e84175e02d3edff6b", "best_bid": "0.065", "best_ask": "0.069"}, {"asset_id": "59259495934562596318644973716893809974860301509869285036503555129962149752635", "price": "0.996", "size": "27.85", "side": "SELL", "hash": "cf43245d6df2b43658c548dcf77a53c086720501", "best_bid": "0.931", "best_ask": "0.935"}], "timestamp": "1769384208969", "event_type": "price_change"}}
{"_local_timestamp": "2026-01-25T23:36:49.253629+00:00", "data": {"market": "0x22ac5f75af18fdb453497fbf7ac0606a09a6fd55b78b2d08aace6b946ad62038", "price_changes": [{"asset_id": "59259495934562596318644973716893809974860301509869285036503555129962149752635", "price": "0.988", "size": "198.88", "side": "SELL", "hash": "b332aea3026ce13042a77f51f026174cd8e01329", "best_bid": "0.931", "best_ask": "0.935"}, {"asset_id": "97449340182256366014320155718265676486703217567849039806162053075113517266910", "price": "0.012", "size": "198.88", "side": "BUY", "hash": "7f35c649963c2dbac08cb4545e20daabd2a5191a", "best_bid": "0.065", "best_ask": "0.069"}], "timestamp": "1769384209185", "event_type": "price_change"}}
{"_local_timestamp": "2026-01-25T23:36:49.346144+00:00", "data": {"market": "0x22ac5f75af18fdb453497fbf7ac0606a09a6fd55b78b2d08aace6b946ad62038", "price_changes": [{"asset_id": "59259495934562596318644973716893809974860301509869285036503555129962149752635", "price": "0.785", "size": "0", "side": "BUY", "hash": "a0fda374709860a3091c6a79e7719a9039bd32fb", "best_bid": "0.931", "best_ask": "0.935"}, {"asset_id": "97449340182256366014320155718265676486703217567849039806162053075113517266910", "price": "0.215", "size": "0", "side": "SELL", "hash": "5c16e2604cc3dfc54724f62fd3a6fe8a9c30837e", "best_bid": "0.065", "best_ask": "0.069"}], "timestamp": "1769384209278", "event_type": "price_change"}}
{"_local_timestamp": "2026-01-25T23:36:49.749156+00:00", "data": {"market": "0x22ac5f75af18fdb453497fbf7ac0606a09a6fd55b78b2d08aace6b946ad62038", "price_changes": [{"asset_id": "59259495934562596318644973716893809974860301509869285036503555129962149752635", "price": "0.785", "size": "5", "side": "BUY", "hash": "5408c68a1b5a3aaca04216bcc1c8dcbeec1dd3e4", "best_bid": "0.931", "best_ask": "0.935"}, {"asset_id": "97449340182256366014320155718265676486703217567849039806162053075113517266910", "price": "0.215", "size": "5", "side": "SELL", "hash": "a318410c9155974e3039ceaaba9022b915695598", "best_bid": "0.065", "best_ask": "0.069"}], "timestamp": "1769384209679", "event_type": "price_change"}}
{"_local_timestamp": "2026-01-25T23:36:50.118812+00:00", "data": {"market": "0x22ac5f75af18fdb453497fbf7ac0606a09a6fd55b78b2d08aace6b946ad62038", "price_changes": [{"asset_id": "97449340182256366014320155718265676486703217567849039806162053075113517266910", "price": "0.004", "size": "19.31", "side": "BUY", "hash": "9a9976a9b2b9e31085da59a41b19ac33ea5b8aea", "best_bid": "0.065", "best_ask": "0.069"}, {"asset_id": "59259495934562596318644973716893809974860301509869285036503555129962149752635", "price": "0.996", "size": "19.31", "side": "SELL", "hash": "3440a6e9a836410fdb561bc47b6125da97e1bbbb", "best_bid": "0.931", "best_ask": "0.935"}], "timestamp": "1769384210006", "event_type": "price_change"}}
{"_local_timestamp": "2026-01-25T23:36:50.120102+00:00", "data": {"market": "0x22ac5f75af18fdb453497fbf7ac0606a09a6fd55b78b2d08aace6b946ad62038", "price_changes": [{"asset_id": "97449340182256366014320155718265676486703217567849039806162053075113517266910", "price": "0.011", "size": "0", "side": "BUY", "hash": "9a9976a9b2b9e31085da59a41b19ac33ea5b8aea", "best_bid": "0.065", "best_ask": "0.069"}, {"asset_id": "59259495934562596318644973716893809974860301509869285036503555129962149752635", "price": "0.989", "size": "0", "side": "SELL", "hash": "3440a6e9a836410fdb561bc47b6125da97e1bbbb", "best_bid": "0.931", "best_ask": "0.935"}], "timestamp": "1769384210006", "event_type": "price_change"}}
{"_local_timestamp": "2026-01-25T23:36:50.515839+00:00", "data": {"market": "0x22ac5f75af18fdb453497fbf7ac0606a09a6fd55b78b2d08aace6b946ad62038", "price_changes": [{"asset_id": "97449340182256366014320155718265676486703217567849039806162053075113517266910", "price": "0.005", "size": "5.95", "side": "BUY", "hash": "31a8bdc3053646ea75ee148812d3387e7d0f5a12", "best_bid": "0.065", "best_ask": "0.069"}, {"asset_id": "59259495934562596318644973716893809974860301509869285036503555129962149752635", "price": "0.995", "size": "5.95", "side": "SELL", "hash": "f19b47bc860cbca2f96fcd1d4be69d82110fcc1b", "best_bid": "0.931", "best_ask": "0.935"}], "timestamp": "1769384210446", "event_type": "price_change"}}
{"_local_timestamp": "2026-01-25T23:36:50.516679+00:00", "data": {"market": "0x22ac5f75af18fdb453497fbf7ac0606a09a6fd55b78b2d08aace6b946ad62038", "price_changes": [{"asset_id": "97449340182256366014320155718265676486703217567849039806162053075113517266910", "price": "0.009", "size": "139.15", "side": "BUY", "hash": "af169ff7d2ff54bcf962a5a1f274bc60f7cb15b3", "best_bid": "0.065", "best_ask": "0.069"}, {"asset_id": "59259495934562596318644973716893809974860301509869285036503555129962149752635", "price": "0.991", "size": "139.15", "side": "SELL", "hash": "969f3ccc3b437b34e9878591450c9ba4b87fd2ce", "best_bid": "0.931", "best_ask": "0.935"}], "timestamp": "1769384210447", "event_type": "price_change"}}
{"_local_timestamp": "2026-01-25T23:36:50.517342+00:00", "data": {"market": "0x22ac5f75af18fdb453497fbf7ac0606a09a6fd55b78b2d08aace6b946ad62038", "price_changes": [{"asset_id": "97449340182256366014320155718265676486703217567849039806162053075113517266910", "price": "0.013", "size": "12.16", "side": "BUY", "hash": "4bbdf93ef4589dae9c0518e0aa65afdb78998de7", "best_bid": "0.065", "best_ask": "0.069"}, {"asset_id": "59259495934562596318644973716893809974860301509869285036503555129962149752635", "price": "0.987", "size": "12.16", "side": "SELL", "hash": "5d364b1fe65516b35fcb9de4675167e9fe5e4929", "best_bid": "0.931", "best_ask": "0.935"}], "timestamp": "1769384210448", "event_type": "price_change"}}
{"_local_timestamp": "2026-01-25T23:36:51.682077+00:00", "data": {"market": "0x22ac5f75af18fdb453497fbf7ac0606a09a6fd55b78b2d08aace6b946ad62038", "price_changes": [{"asset_id": "97449340182256366014320155718265676486703217567849039806162053075113517266910", "price": "0.005", "size": "0", "side": "BUY", "hash": "54d93234e666f54af1e12c093d2efd6ac4371c95", "best_bid": "0.065", "best_ask": "0.069"}, {"asset_id": "59259495934562596318644973716893809974860301509869285036503555129962149752635", "price": "0.995", "size": "0", "side": "SELL", "hash": "599a32e05cee6d4e8da0917d973dba8291dc6734", "best_bid": "0.931", "best_ask": "0.935"}], "timestamp": "1769384211615", "event_type": "price_change"}}
{"_local_timestamp": "2026-01-25T23:36:51.852941+00:00", "data": {"market": "0x22ac5f75af18fdb453497fbf7ac0606a09a6fd55b78b2d08aace6b946ad62038", "price_changes": [{"asset_id": "59259495934562596318644973716893809974860301509869285036503555129962149752635", "price": "0.988", "size": "0", "side": "SELL", "hash": "8a428ca88fe810b03849dde4dcb0db9b50a37066", "best_bid": "0.931", "best_ask": "0.935"}, {"asset_id": "97449340182256366014320155718265676486703217567849039806162053075113517266910", "price": "0.012", "size": "0", "side": "BUY", "hash": "257148c6577a310956b06e121f367b18fcb3a4a9", "best_bid": "0.065", "best_ask": "0.069"}], "timestamp": "1769384211789", "event_type": "price_change"}}
{"_local_timestamp": "2026-01-25T23:36:52.033179+00:00", "data": {"market": "0x22ac5f75af18fdb453497fbf7ac0606a09a6fd55b78b2d08aace6b946ad62038", "price_changes": [{"asset_id": "97449340182256366014320155718265676486703217567849039806162053075113517266910", "price": "0.004", "size": "26.77", "side": "BUY", "hash": "5a2b5de9353f248f0ee4c98d8b03a024b13add3a", "best_bid": "0.065", "best_ask": "0.069"}, {"asset_id": "59259495934562596318644973716893809974860301509869285036503555129962149752635", "price": "0.996", "size": "26.77", "side": "SELL", "hash": "40962ee3fe7dfee922accaaea9d92bb3f54810f4", "best_bid": "0.931", "best_ask": "0.935"}], "timestamp": "1769384211969", "event_type": "price_change"}}
{"_local_timestamp": "2026-01-25T23:36:52.910698+00:00", "data": {"market": "0x22ac5f75af18fdb453497fbf7ac0606a09a6fd55b78b2d08aace6b946ad62038", "price_changes": [{"asset_id": "59259495934562596318644973716893809974860301509869285036503555129962149752635", "price": "0.989", "size": "198.88", "side": "SELL", "hash": "014cd8d34f431162367966f64bff2ad067b7dc9a", "best_bid": "0.931", "best_ask": "0.935"}, {"asset_id": "97449340182256366014320155718265676486703217567849039806162053075113517266910", "price": "0.011", "size": "198.88", "side": "BUY", "hash": "558da22b4ffece0e57780d36397b80c8a0e59c2f", "best_bid": "0.065", "best_ask": "0.069"}], "timestamp": "1769384212840", "event_type": "price_change"}}
{"_local_timestamp": "2026-01-25T23:36:53.161415+00:00", "data": {"market": "0x22ac5f75af18fdb453497fbf7ac0606a09a6fd55b78b2d08aace6b946ad62038", "price_changes": [{"asset_id": "97449340182256366014320155718265676486703217567849039806162053075113517266910", "price": "0.009", "size": "133.06", "side": "BUY", "hash": "64b80e85eb7ec21cc25f2eccb7087243a71c1c2c", "best_bid": "0.065", "best_ask": "0.069"}, {"asset_id": "59259495934562596318644973716893809974860301509869285036503555129962149752635", "price": "0.991", "size": "133.06", "side": "SELL", "hash": "d3aaaa9bddfa8ce91457c614c5c75f906efeb285", "best_bid": "0.931", "best_ask": "0.935"}], "timestamp": "1769384213090", "event_type": "price_change"}}
{"_local_timestamp": "2026-01-25T23:36:53.162260+00:00", "data": {"market": "0x22ac5f75af18fdb453497fbf7ac0606a09a6fd55b78b2d08aace6b946ad62038", "price_changes": [{"asset_id": "97449340182256366014320155718265676486703217567849039806162053075113517266910", "price": "0.013", "size": "0", "side": "BUY", "hash": "64b80e85eb7ec21cc25f2eccb7087243a71c1c2c", "best_bid": "0.065", "best_ask": "0.069"}, {"asset_id": "59259495934562596318644973716893809974860301509869285036503555129962149752635", "price": "0.987", "size": "0", "side": "SELL", "hash": "d3aaaa9bddfa8ce91457c614c5c75f906efeb285", "best_bid": "0.931", "best_ask": "0.935"}], "timestamp": "1769384213090", "event_type": "price_change"}}
{"_local_timestamp": "2026-01-25T23:36:53.488864+00:00", "data": {"market": "0x22ac5f75af18fdb453497fbf7ac0606a09a6fd55b78b2d08aace6b946ad62038", "price_changes": [{"asset_id": "97449340182256366014320155718265676486703217567849039806162053075113517266910", "price": "0.012", "size": "17.74", "side": "BUY", "hash": "c57dcbfd7640ec44e4c473a5b47312ed860a1fc8", "best_bid": "0.065", "best_ask": "0.069"}, {"asset_id": "59259495934562596318644973716893809974860301509869285036503555129962149752635", "price": "0.988", "size": "17.74", "side": "SELL", "hash": "cf113109581a1558b2968dff1a4cd654b56fafe0", "best_bid": "0.931", "best_ask": "0.935"}], "timestamp": "1769384213423", "event_type": "price_change"}}
{"_local_timestamp": "2026-01-25T23:36:53.903018+00:00", "data": {"market": "0x22ac5f75af18fdb453497fbf7ac0606a09a6fd55b78b2d08aace6b946ad62038", "price_changes": [{"asset_id": "97449340182256366014320155718265676486703217567849039806162053075113517266910", "price": "0.004", "size": "19.31", "side": "BUY", "hash": "0b6585e19a75b6943c028302ee64c8167c2e037c", "best_bid": "0.065", "best_ask": "0.069"}, {"asset_id": "59259495934562596318644973716893809974860301509869285036503555129962149752635", "price": "0.996", "size": "19.31", "side": "SELL", "hash": "e1ce9bcfc1d29fc86d3c6d6e8eb150b516dc264c", "best_bid": "0.931", "best_ask": "0.935"}], "timestamp": "1769384213828", "event_type": "price_change"}}
{"_local_timestamp": "2026-01-25T23:36:54.209277+00:00", "data": {"market": "0x22ac5f75af18fdb453497fbf7ac0606a09a6fd55b78b2d08aace6b946ad62038", "price_changes": [{"asset_id": "97449340182256366014320155718265676486703217567849039806162053075113517266910", "price": "0.004", "size": "26.77", "side": "BUY", "hash": "ebb80bfc92d01eb543b7876a701f6dfc0271b35f", "best_bid": "0.065", "best_ask": "0.069"}, {"asset_id": "59259495934562596318644973716893809974860301509869285036503555129962149752635", "price": "0.996", "size": "26.77", "side": "SELL", "hash": "0f7e92a9e25ccde9d2eb52c2f9bb9845d12e6f88", "best_bid": "0.931", "best_ask": "0.935"}], "timestamp": "1769384214134", "event_type": "price_change"}}
{"_local_timestamp": "2026-01-25T23:36:54.803699+00:00", "data": {"market": "0x22ac5f75af18fdb453497fbf7ac0606a09a6fd55b78b2d08aace6b946ad62038", "price_changes": [{"asset_id": "59259495934562596318644973716893809974860301509869285036503555129962149752635", "price": "0.989", "size": "0", "side": "SELL", "hash": "b2d8055ec1239fab866d8cdc1a6316750eff2faf", "best_bid": "0.931", "best_ask": "0.935"}, {"asset_id": "97449340182256366014320155718265676486703217567849039806162053075113517266910", "price": "0.011", "size": "0", "side": "BUY", "hash": "fafe7053137de4871ea86805b69b3719030a03bc", "best_bid": "0.065", "best_ask": "0.069"}], "timestamp": "1769384214722", "event_type": "price_change"}}
{"_local_timestamp": "2026-01-25T23:36:55.358244+00:00", "data": {"market": "0x22ac5f75af18fdb453497fbf7ac0606a09a6fd55b78b2d08aace6b946ad62038", "price_changes": [{"asset_id": "59259495934562596318644973716893809974860301509869285036503555129962149752635", "price": "0.785", "size": "0", "side": "BUY", "hash": "5ec85e801d663a19f5c72290cc28c60c2804ab06", "best_bid": "0.931", "best_ask": "0.935"}, {"asset_id": "97449340182256366014320155718265676486703217567849039806162053075113517266910", "price": "0.215", "size": "0", "side": "SELL", "hash": "a709c477eacac8737096d27b909ae6d929d8c5ca", "best_bid": "0.065", "best_ask": "0.069"}], "timestamp": "1769384215293", "event_type": "price_change"}}
{"_local_timestamp": "2026-01-25T23:36:56.038441+00:00", "data": {"market": "0x22ac5f75af18fdb453497fbf7ac0606a09a6fd55b78b2d08aace6b946ad62038", "price_changes": [{"asset_id": "59259495934562596318644973716893809974860301509869285036503555129962149752635", "price": "0.785", "size": "5", "side": "BUY", "hash": "db324d8b0276f285ad64043f48488816c41f772d", "best_bid": "0.931", "best_ask": "0.935"}, {"asset_id": "97449340182256366014320155718265676486703217567849039806162053075113517266910", "price": "0.215", "size": "5", "side": "SELL", "hash": "39ba67c2aa3abc97df7ceb19c7bb512bed12e448", "best_bid": "0.065", "best_ask": "0.069"}], "timestamp": "1769384215750", "event_type": "price_change"}}
{"_local_timestamp": "2026-01-25T23:36:56.246221+00:00", "data": {"market": "0x22ac5f75af18fdb453497fbf7ac0606a09a6fd55b78b2d08aace6b946ad62038", "price_changes": [{"asset_id": "59259495934562596318644973716893809974860301509869285036503555129962149752635", "price": "0.987", "size": "198.88", "side": "SELL", "hash": "baa88e7b891f80377a9ca4b5313627b93d65e638", "best_bid": "0.931", "best_ask": "0.935"}, {"asset_id": "97449340182256366014320155718265676486703217567849039806162053075113517266910", "price": "0.013", "size": "198.88", "side": "BUY", "hash": "0f47fa9081a9b77d6da89f2c0b156766cfad9565", "best_bid": "0.065", "best_ask": "0.069"}], "timestamp": "1769384215815", "event_type": "price_change"}}
{"_local_timestamp": "2026-01-25T23:36:56.392927+00:00", "data": {"market": "0x22ac5f75af18fdb453497fbf7ac0606a09a6fd55b78b2d08aace6b946ad62038", "price_changes": [{"asset_id": "97449340182256366014320155718265676486703217567849039806162053075113517266910", "price": "0.012", "size": "0", "side": "BUY", "hash": "0bdc43966f166c1ca073db767ca53d5ce2bfdb06", "best_bid": "0.065", "best_ask": "0.069"}, {"asset_id": "59259495934562596318644973716893809974860301509869285036503555129962149752635", "price": "0.988", "size": "0", "side": "SELL", "hash": "09eef3d57e60b0e03ea13ee0a34a3103848c3718", "best_bid": "0.931", "best_ask": "0.935"}], "timestamp": "1769384216028", "event_type": "price_change"}}
{"_local_timestamp": "2026-01-25T23:36:56.474962+00:00", "data": {"market": "0x22ac5f75af18fdb453497fbf7ac0606a09a6fd55b78b2d08aace6b946ad62038", "price_changes": [{"asset_id": "97449340182256366014320155718265676486703217567849039806162053075113517266910", "price": "0.013", "size": "204.95", "side": "BUY", "hash": "020f6b96a42bdf04d33cd4c7e9b90be1b21a5e54", "best_bid": "0.065", "best_ask": "0.069"}, {"asset_id": "59259495934562596318644973716893809974860301509869285036503555129962149752635", "price": "0.987", "size": "204.95", "side": "SELL", "hash": "2a246588950bbdc603a53e08fd453c21bdf47418", "best_bid": "0.931", "best_ask": "0.935"}], "timestamp": "1769384216408", "event_type": "price_change"}}
{"_local_timestamp": "2026-01-25T23:36:56.475771+00:00", "data": {"market": "0x22ac5f75af18fdb453497fbf7ac0606a09a6fd55b78b2d08aace6b946ad62038", "price_changes": [{"asset_id": "97449340182256366014320155718265676486703217567849039806162053075113517266910", "price": "0.013", "size": "211.02", "side": "BUY", "hash": "a7487c2db0c46718084c95a8de1987fc3ae19052", "best_bid": "0.065", "best_ask": "0.069"}, {"asset_id": "59259495934562596318644973716893809974860301509869285036503555129962149752635", "price": "0.987", "size": "211.02", "side": "SELL", "hash": "4deed06343c2aba5f6808968e0b1ccaddadd027c", "best_bid": "0.931", "best_ask": "0.935"}], "timestamp": "1769384216410", "event_type": "price_change"}}
{"_local_timestamp": "2026-01-25T23:36:56.481999+00:00", "data": {"market": "0x22ac5f75af18fdb453497fbf7ac0606a09a6fd55b78b2d08aace6b946ad62038", "price_changes": [{"asset_id": "97449340182256366014320155718265676486703217567849039806162053075113517266910", "price": "0.009", "size": "139.15", "side": "BUY", "hash": "012858b31a30d388b6ba16fb3b6543dc51a3131e", "best_bid": "0.065", "best_ask": "0.069"}, {"asset_id": "59259495934562596318644973716893809974860301509869285036503555129962149752635", "price": "0.991", "size": "139.15", "side": "SELL", "hash": "46e0e965369aaba56d006e3f47c41ef13f45a71c", "best_bid": "0.931", "best_ask": "0.935"}], "timestamp": "1769384216411", "event_type": "price_change"}}
{"_local_timestamp": "2026-01-25T23:36:57.122394+00:00", "data": {"market": "0x22ac5f75af18fdb453497fbf7ac0606a09a6fd55b78b2d08aace6b946ad62038", "price_changes": [{"asset_id": "97449340182256366014320155718265676486703217567849039806162053075113517266910", "price": "0.004", "size": "19.31", "side": "BUY", "hash": "22240e66fd1ea29894ec714304ec83022fa2087d", "best_bid": "0.065", "best_ask": "0.069"}, {"asset_id": "59259495934562596318644973716893809974860301509869285036503555129962149752635", "price": "0.996", "size": "19.31", "side": "SELL", "hash": "f0bce4e375fb3033de8acc0769575e9b08c77d22", "best_bid": "0.931", "best_ask": "0.935"}], "timestamp": "1769384217052", "event_type": "price_change"}}
{"_local_timestamp": "2026-01-25T23:36:57.123647+00:00", "data": {"market": "0x22ac5f75af18fdb453497fbf7ac0606a09a6fd55b78b2d08aace6b946ad62038", "price_changes": [{"asset_id": "97449340182256366014320155718265676486703217567849039806162053075113517266910", "price": "0.009", "size": "133.06", "side": "BUY", "hash": "22240e66fd1ea29894ec714304ec83022fa2087d", "best_bid": "0.065", "best_ask": "0.069"}, {"asset_id": "59259495934562596318644973716893809974860301509869285036503555129962149752635", "price": "0.991", "size": "133.06", "side": "SELL", "hash": "f0bce4e375fb3033de8acc0769575e9b08c77d22", "best_bid": "0.931", "best_ask": "0.935"}], "timestamp": "1769384217052", "event_type": "price_change"}}
{"_local_timestamp": "2026-01-25T23:36:57.130693+00:00", "data": {"market": "0x22ac5f75af18fdb453497fbf7ac0606a09a6fd55b78b2d08aace6b946ad62038", "price_changes": [{"asset_id": "97449340182256366014320155718265676486703217567849039806162053075113517266910", "price": "0.013", "size": "204.95", "side": "BUY", "hash": "22240e66fd1ea29894ec714304ec83022fa2087d", "best_bid": "0.065", "best_ask": "0.069"}, {"asset_id": "59259495934562596318644973716893809974860301509869285036503555129962149752635", "price": "0.987", "size": "204.95", "side": "SELL", "hash": "f0bce4e375fb3033de8acc0769575e9b08c77d22", "best_bid": "0.931", "best_ask": "0.935"}], "timestamp": "1769384217052", "event_type": "price_change"}}
{"_local_timestamp": "2026-01-25T23:36:57.823035+00:00", "data": {"market": "0x22ac5f75af18fdb453497fbf7ac0606a09a6fd55b78b2d08aace6b946ad62038", "price_changes": [{"asset_id": "97449340182256366014320155718265676486703217567849039806162053075113517266910", "price": "0.014", "size": "5.85", "side": "BUY", "hash": "57bd729a821664deea5f95891df6d57b7d37a79c", "best_bid": "0.065", "best_ask": "0.069"}, {"asset_id": "59259495934562596318644973716893809974860301509869285036503555129962149752635", "price": "0.986", "size": "5.85", "side": "SELL", "hash": "20076649e98aed0c096a04d98f871fc9ae61b2db", "best_bid": "0.931", "best_ask": "0.935"}], "timestamp": "1769384217367", "event_type": "price_change"}}
{"_local_timestamp": "2026-01-25T23:36:57.823975+00:00", "data": {"market": "0x22ac5f75af18fdb453497fbf7ac0606a09a6fd55b78b2d08aace6b946ad62038", "price_changes": [{"asset_id": "97449340182256366014320155718265676486703217567849039806162053075113517266910", "price": "0.014", "size": "11.7", "side": "BUY", "hash": "e6701878eae5f9824452f8ff9dc40ba01ac43dd9", "best_bid": "0.065", "best_ask": "0.069"}, {"asset_id": "59259495934562596318644973716893809974860301509869285036503555129962149752635", "price": "0.986", "size": "11.7", "side": "SELL", "hash": "7317ef49c8bcac6a92e64ab71bae5c75ef39c83a", "best_bid": "0.931", "best_ask": "0.935"}], "timestamp": "1769384217371", "event_type": "price_change"}}
{"_local_timestamp": "2026-01-25T23:36:58.050163+00:00", "data": {"market": "0x22ac5f75af18fdb453497fbf7ac0606a09a6fd55b78b2d08aace6b946ad62038", "price_changes": [{"asset_id": "97449340182256366014320155718265676486703217567849039806162053075113517266910", "price": "0.013", "size": "198.88", "side": "BUY", "hash": "6680c584a1f20c0695874cf62fff42d5a4e14302", "best_bid": "0.065", "best_ask": "0.069"}, {"asset_id": "59259495934562596318644973716893809974860301509869285036503555129962149752635", "price": "0.987", "size": "198.88", "side": "SELL", "hash": "041362193fdf89a43dd2e3bc392d18cd7a75d038", "best_bid": "0.931", "best_ask": "0.935"}], "timestamp": "1769384217987", "event_type": "price_change"}}
{"_local_timestamp": "2026-01-25T23:36:58.455944+00:00", "data": {"market": "0x22ac5f75af18fdb453497fbf7ac0606a09a6fd55b78b2d08aace6b946ad62038", "price_changes": [{"asset_id": "59259495934562596318644973716893809974860301509869285036503555129962149752635", "price": "0.987", "size": "0", "side": "SELL", "hash": "d1eb9027689e789f99b29a3930a732e72fe4dfd7", "best_bid": "0.931", "best_ask": "0.935"}, {"asset_id": "97449340182256366014320155718265676486703217567849039806162053075113517266910", "price": "0.013", "size": "0", "side": "BUY", "hash": "d1acce68a8c1618d8c35d682aef0261ff2ad5ab3", "best_bid": "0.065", "best_ask": "0.069"}], "timestamp": "1769384218361", "event_type": "price_change"}}
{"_local_timestamp": "2026-01-25T23:36:58.482084+00:00", "data": {"market": "0x22ac5f75af18fdb453497fbf7ac0606a09a6fd55b78b2d08aace6b946ad62038", "price_changes": [{"asset_id": "97449340182256366014320155718265676486703217567849039806162053075113517266910", "price": "0.01", "size": "292.34", "side": "BUY", "hash": "b18b2cc67dfdf8f582dcf41377eba1025d2be679", "best_bid": "0.065", "best_ask": "0.069"}, {"asset_id": "59259495934562596318644973716893809974860301509869285036503555129962149752635", "price": "0.99", "size": "292.34", "side": "SELL", "hash": "7ef3c20458ff665030dd880e9db34dcc3fb5f9ce", "best_bid": "0.931", "best_ask": "0.935"}], "timestamp": "1769384218408", "event_type": "price_change"}}
{"_local_timestamp": "2026-01-25T23:37:00.231897+00:00", "data": {"market": "0x22ac5f75af18fdb453497fbf7ac0606a09a6fd55b78b2d08aace6b946ad62038", "price_changes": [{"asset_id": "97449340182256366014320155718265676486703217567849039806162053075113517266910", "price": "0.01", "size": "284.45", "side": "BUY", "hash": "a17e9bcd39aa988d8f9c826757939c106845b174", "best_bid": "0.065", "best_ask": "0.069"}, {"asset_id": "59259495934562596318644973716893809974860301509869285036503555129962149752635", "price": "0.99", "size": "284.45", "side": "SELL", "hash": "2cb6f131fd0e7ba4746bbb7d6e9c1437840c3be9", "best_bid": "0.931", "best_ask": "0.935"}], "timestamp": "1769384220159", "event_type": "price_change"}}
{"_local_timestamp": "2026-01-25T23:37:00.233155+00:00", "data": {"market": "0x22ac5f75af18fdb453497fbf7ac0606a09a6fd55b78b2d08aace6b946ad62038", "price_changes": [{"asset_id": "97449340182256366014320155718265676486703217567849039806162053075113517266910", "price": "0.014", "size": "5.85", "side": "BUY", "hash": "a17e9bcd39aa988d8f9c826757939c106845b174", "best_bid": "0.065", "best_ask": "0.069"}, {"asset_id": "59259495934562596318644973716893809974860301509869285036503555129962149752635", "price": "0.986", "size": "5.85", "side": "SELL", "hash": "2cb6f131fd0e7ba4746bbb7d6e9c1437840c3be9", "best_bid": "0.931", "best_ask": "0.935"}], "timestamp": "1769384220159", "event_type": "price_change"}}
{"_local_timestamp": "2026-01-25T23:37:00.576733+00:00", "data": {"market": "0x22ac5f75af18fdb453497fbf7ac0606a09a6fd55b78b2d08aace6b946ad62038", "price_changes": [{"asset_id": "97449340182256366014320155718265676486703217567849039806162053075113517266910", "price": "0.004", "size": "24.97", "side": "BUY", "hash": "b84491d5000637bec775ff6fe209045703837cff", "best_bid": "0.065", "best_ask": "0.069"}, {"asset_id": "59259495934562596318644973716893809974860301509869285036503555129962149752635", "price": "0.996", "size": "24.97", "side": "SELL", "hash": "90299dd770d6e4e433664ee257c59d683819e093", "best_bid": "0.931", "best_ask": "0.935"}], "timestamp": "1769384220509", "event_type": "price_change"}}
{"_local_timestamp": "2026-01-25T23:37:00.577551+00:00", "data": {"market": "0x22ac5f75af18fdb453497fbf7ac0606a09a6fd55b78b2d08aace6b946ad62038", "price_changes": [{"asset_id": "97449340182256366014320155718265676486703217567849039806162053075113517266910", "price": "0.011", "size": "6.28", "side": "BUY", "hash": "e17ad3f7f4b6607e6073e5c81e2ff8e69c480bae", "best_bid": "0.065", "best_ask": "0.069"}, {"asset_id": "59259495934562596318644973716893809974860301509869285036503555129962149752635", "price": "0.989", "size": "6.28", "side": "SELL", "hash": "a280105597b6f04dc10a21b743b16987ece994f9", "best_bid": "0.931", "best_ask": "0.935"}], "timestamp": "1769384220511", "event_type": "price_change"}}
{"_local_timestamp": "2026-01-25T23:37:00.578313+00:00", "data": {"market": "0x22ac5f75af18fdb453497fbf7ac0606a09a6fd55b78b2d08aace6b946ad62038", "price_changes": [{"asset_id": "97449340182256366014320155718265676486703217567849039806162053075113517266910", "price": "0.011", "size": "12.56", "side": "BUY", "hash": "b9fc8d9be9ef92124b61e36db9c1175c5ea8e3f1", "best_bid": "0.065", "best_ask": "0.069"}, {"asset_id": "59259495934562596318644973716893809974860301509869285036503555129962149752635", "price": "0.989", "size": "12.56", "side": "SELL", "hash": "6701e6f660aea6e1d528fa24c7b1139eb6148352", "best_bid": "0.931", "best_ask": "0.935"}], "timestamp": "1769384220512", "event_type": "price_change"}}
{"_local_timestamp": "2026-01-25T23:37:01.132303+00:00", "data": {"market": "0x22ac5f75af18fdb453497fbf7ac0606a09a6fd55b78b2d08aace6b946ad62038", "price_changes": [{"asset_id": "59259495934562596318644973716893809974860301509869285036503555129962149752635", "price": "0.989", "size": "211.44", "side": "SELL", "hash": "e2c363a98221438d418bf31ebad00bcd48b1b3d5", "best_bid": "0.931", "best_ask": "0.935"}, {"asset_id": "97449340182256366014320155718265676486703217567849039806162053075113517266910", "price": "0.011", "size": "211.44", "side": "BUY", "hash": "b39aa4f43162713be05c24bdbabf4008a0959729", "best_bid": "0.065", "best_ask": "0.069"}], "timestamp": "1769384221063", "event_type": "price_change"}}
{"_local_timestamp": "2026-01-25T23:37:02.610288+00:00", "data": {"market": "0x22ac5f75af18fdb453497fbf7ac0606a09a6fd55b78b2d08aace6b946ad62038", "price_changes": [{"asset_id": "97449340182256366014320155718265676486703217567849039806162053075113517266910", "price": "0.004", "size": "17.72", "side": "BUY", "hash": "833319d5a7e497175c6153b3da32b7085980b395", "best_bid": "0.065", "best_ask": "0.069"}, {"asset_id": "59259495934562596318644973716893809974860301509869285036503555129962149752635", "price": "0.996", "size": "17.72", "side": "SELL", "hash": "5ff499d1e500eae88cd174a856862551e973d812", "best_bid": "0.931", "best_ask": "0.935"}], "timestamp": "1769384222531", "event_type": "price_change"}}
{"_local_timestamp": "2026-01-25T23:37:02.611235+00:00", "data": {"market": "0x22ac5f75af18fdb453497fbf7ac0606a09a6fd55b78b2d08aace6b946ad62038", "price_changes": [{"asset_id": "97449340182256366014320155718265676486703217567849039806162053075113517266910", "price": "0.011", "size": "205.16", "side": "BUY", "hash": "833319d5a7e497175c6153b3da32b7085980b395", "best_bid": "0.065", "best_ask": "0.069"}, {"asset_id": "59259495934562596318644973716893809974860301509869285036503555129962149752635", "price": "0.989", "size": "205.16", "side": "SELL", "hash": "5ff499d1e500eae88cd174a856862551e973d812", "best_bid": "0.931", "best_ask": "0.935"}], "timestamp": "1769384222531", "event_type": "price_change"}}
{"_local_timestamp": "2026-01-25T23:37:02.612006+00:00", "data": {"market": "0x22ac5f75af18fdb453497fbf7ac0606a09a6fd55b78b2d08aace6b946ad62038", "price_changes": [{"asset_id": "97449340182256366014320155718265676486703217567849039806162053075113517266910", "price": "0.014", "size": "0", "side": "BUY", "hash": "833319d5a7e497175c6153b3da32b7085980b395", "best_bid": "0.065", "best_ask": "0.069"}, {"asset_id": "59259495934562596318644973716893809974860301509869285036503555129962149752635", "price": "0.986", "size": "0", "side": "SELL", "hash": "5ff499d1e500eae88cd174a856862551e973d812", "best_bid": "0.931", "best_ask": "0.935"}], "timestamp": "1769384222531", "event_type": "price_change"}}
{"_local_timestamp": "2026-01-25T23:37:02.964500+00:00", "data": {"market": "0x22ac5f75af18fdb453497fbf7ac0606a09a6fd55b78b2d08aace6b946ad62038", "price_changes": [{"asset_id": "97449340182256366014320155718265676486703217567849039806162053075113517266910", "price": "0.012", "size": "7.5", "side": "BUY", "hash": "1f1235debcd7de677e706f0a3d90f8dae7fd107e", "best_bid": "0.065", "best_ask": "0.069"}, {"asset_id": "59259495934562596318644973716893809974860301509869285036503555129962149752635", "price": "0.988", "size": "7.5", "side": "SELL", "hash": "ef9ec0a2e4564d2c15b8f514a17ba607a427be66", "best_bid": "0.931", "best_ask": "0.935"}], "timestamp": "1769384222888", "event_type": "price_change"}}
{"_local_timestamp": "2026-01-25T23:37:02.965425+00:00", "data": {"market": "0x22ac5f75af18fdb453497fbf7ac0606a09a6fd55b78b2d08aace6b946ad62038", "price_changes": [{"asset_id": "97449340182256366014320155718265676486703217567849039806162053075113517266910", "price": "0.012", "size": "15", "side": "BUY", "hash": "fd9cd74e3aba1bed52e0d5f988578b5e1a2ae0b7", "best_bid": "0.065", "best_ask": "0.069"}, {"asset_id": "59259495934562596318644973716893809974860301509869285036503555129962149752635", "price": "0.988", "size": "15", "side": "SELL", "hash": "127aa4811041a8cb7abf74ef773fdeb39a239f4d", "best_bid": "0.931", "best_ask": "0.935"}], "timestamp": "1769384222889", "event_type": "price_change"}}
{"_local_timestamp": "2026-01-25T23:37:03.465377+00:00", "data": {"market": "0x22ac5f75af18fdb453497fbf7ac0606a09a6fd55b78b2d08aace6b946ad62038", "price_changes": [{"asset_id": "59259495934562596318644973716893809974860301509869285036503555129962149752635", "price": "0.785", "size": "0", "side": "BUY", "hash": "73fee111f35892933d4e5cb8059d44f2572c855f", "best_bid": "0.931", "best_ask": "0.935"}, {"asset_id": "97449340182256366014320155718265676486703217567849039806162053075113517266910", "price": "0.215", "size": "0", "side": "SELL", "hash": "878b2ea6428f12d10b6f7edee6d69650e8620948", "best_bid": "0.065", "best_ask": "0.069"}], "timestamp": "1769384223400", "event_type": "price_change"}}
{"_local_timestamp": "2026-01-25T23:37:03.507732+00:00", "data": {"market": "0x22ac5f75af18fdb453497fbf7ac0606a09a6fd55b78b2d08aace6b946ad62038", "price_changes": [{"asset_id": "59259495934562596318644973716893809974860301509869285036503555129962149752635", "price": "0.989", "size": "6.28", "side": "SELL", "hash": "798c5c61d3229fab1f312a4e490d57de636a0e59", "best_bid": "0.931", "best_ask": "0.935"}, {"asset_id": "97449340182256366014320155718265676486703217567849039806162053075113517266910", "price": "0.011", "size": "6.28", "side": "BUY", "hash": "4135d9d5b107e2bbb5a9e029d059af450f872389", "best_bid": "0.065", "best_ask": "0.069"}], "timestamp": "1769384223432", "event_type": "price_change"}}
{"_local_timestamp": "2026-01-25T23:37:03.870103+00:00", "data": {"market": "0x22ac5f75af18fdb453497fbf7ac0606a09a6fd55b78b2d08aace6b946ad62038", "price_changes": [{"asset_id": "59259495934562596318644973716893809974860301509869285036503555129962149752635", "price": "0.785", "size": "5", "side": "BUY", "hash": "6b9c44ba3cdef7f60ab9c317af413cfa3383da28", "best_bid": "0.931", "best_ask": "0.935"}, {"asset_id": "97449340182256366014320155718265676486703217567849039806162053075113517266910", "price": "0.215", "size": "5", "side": "SELL", "hash": "3668749dc0f3b21865ba93a655c361fc2ca479b4", "best_bid": "0.065", "best_ask": "0.069"}], "timestamp": "1769384223805", "event_type": "price_change"}}
{"_local_timestamp": "2026-01-25T23:37:03.901212+00:00", "data": {"market": "0x22ac5f75af18fdb453497fbf7ac0606a09a6fd55b78b2d08aace6b946ad62038", "price_changes": [{"asset_id": "97449340182256366014320155718265676486703217567849039806162053075113517266910", "price": "0.011", "size": "0", "side": "BUY", "hash": "5c94f60fdf9498449333191007ea239481e5789e", "best_bid": "0.065", "best_ask": "0.069"}, {"asset_id": "59259495934562596318644973716893809974860301509869285036503555129962149752635", "price": "0.989", "size": "0", "side": "SELL", "hash": "c7ab8096e18671bf53399706f2206ebf89634a77", "best_bid": "0.931", "best_ask": "0.935"}], "timestamp": "1769384223835", "event_type": "price_change"}}
{"_local_timestamp": "2026-01-25T23:37:04.172802+00:00", "data": {"market": "0x22ac5f75af18fdb453497fbf7ac0606a09a6fd55b78b2d08aace6b946ad62038", "price_changes": [{"asset_id": "97449340182256366014320155718265676486703217567849039806162053075113517266910", "price": "0.004", "size": "26.35", "side": "BUY", "hash": "734b31c9772d9a7cf8da5f4356e48d3883047e1f", "best_bid": "0.065", "best_ask": "0.069"}, {"asset_id": "59259495934562596318644973716893809974860301509869285036503555129962149752635", "price": "0.996", "size": "26.35", "side": "SELL", "hash": "2ea37955bf24c34637790759813425dd4e35f82b", "best_bid": "0.931", "best_ask": "0.935"}], "timestamp": "1769384224103", "event_type": "price_change"}}
{"_local_timestamp": "2026-01-25T23:37:04.173675+00:00", "data": {"market": "0x22ac5f75af18fdb453497fbf7ac0606a09a6fd55b78b2d08aace6b946ad62038", "price_changes": [{"asset_id": "97449340182256366014320155718265676486703217567849039806162053075113517266910", "price": "0.004", "size": "34.98", "side": "BUY", "hash": "3c7f5fd17408fc46cd2a6f8fd0edc9c4c17d28fb", "best_bid": "0.065", "best_ask": "0.069"}, {"asset_id": "59259495934562596318644973716893809974860301509869285036503555129962149752635", "price": "0.996", "size": "34.98", "side": "SELL", "hash": "8cddd1cf369ede8d853ca8e827112ba0cc3879d5", "best_bid": "0.931", "best_ask": "0.935"}], "timestamp": "1769384224104", "event_type": "price_change"}}
{"_local_timestamp": "2026-01-25T23:37:05.117005+00:00", "data": {"market": "0x22ac5f75af18fdb453497fbf7ac0606a09a6fd55b78b2d08aace6b946ad62038", "price_changes": [{"asset_id": "97449340182256366014320155718265676486703217567849039806162053075113517266910", "price": "0.004", "size": "26.35", "side": "BUY", "hash": "afe9e605e44ab7083c2bcfd47599fd7840b6d84d", "best_bid": "0.065", "best_ask": "0.069"}, {"asset_id": "59259495934562596318644973716893809974860301509869285036503555129962149752635", "price": "0.996", "size": "26.35", "side": "SELL", "hash": "fc33668b8d2925b950bbf02a73386cafd7bee180", "best_bid": "0.931", "best_ask": "0.935"}], "timestamp": "1769384225011", "event_type": "price_change"}}
{"_local_timestamp": "2026-01-25T23:37:05.117877+00:00", "data": {"market": "0x22ac5f75af18fdb453497fbf7ac0606a09a6fd55b78b2d08aace6b946ad62038", "price_changes": [{"asset_id": "97449340182256366014320155718265676486703217567849039806162053075113517266910", "price": "0.012", "size": "7.5", "side": "BUY", "hash": "afe9e605e44ab7083c2bcfd47599fd7840b6d84d", "best_bid": "0.065", "best_ask": "0.069"}, {"asset_id": "59259495934562596318644973716893809974860301509869285036503555129962149752635", "price": "0.988", "size": "7.5", "side": "SELL", "hash": "fc33668b8d2925b950bbf02a73386cafd7bee180", "best_bid": "0.931", "best_ask": "0.935"}], "timestamp": "1769384225011", "event_type": "price_change"}}
{"_local_timestamp": "2026-01-25T23:37:05.412627+00:00", "data": {"market": "0x22ac5f75af18fdb453497fbf7ac0606a09a6fd55b78b2d08aace6b946ad62038", "price_changes": [{"asset_id": "97449340182256366014320155718265676486703217567849039806162053075113517266910", "price": "0.011", "size": "5.66", "side": "BUY", "hash": "c571170c841ae4bb5576ccdab4b5ded6945f0943", "best_bid": "0.065", "best_ask": "0.069"}, {"asset_id": "59259495934562596318644973716893809974860301509869285036503555129962149752635", "price": "0.989", "size": "5.66", "side": "SELL", "hash": "e3681bcbc00d72f5122cec24427b172573d2fdad", "best_bid": "0.931", "best_ask": "0.935"}], "timestamp": "1769384225348", "event_type": "price_change"}}
{"_local_timestamp": "2026-01-25T23:37:05.413591+00:00", "data": {"market": "0x22ac5f75af18fdb453497fbf7ac0606a09a6fd55b78b2d08aace6b946ad62038", "price_changes": [{"asset_id": "97449340182256366014320155718265676486703217567849039806162053075113517266910", "price": "0.011", "size": "11.32", "side": "BUY", "hash": "b622c49e43a77bd054a376e357f120bb76092f81", "best_bid": "0.065", "best_ask": "0.069"}, {"asset_id": "59259495934562596318644973716893809974860301509869285036503555129962149752635", "price": "0.989", "size": "11.32", "side": "SELL", "hash": "f09f923eb992178739d043846dc17dcd4eda384c", "best_bid": "0.931", "best_ask": "0.935"}], "timestamp": "1769384225349", "event_type": "price_change"}}
{"_local_timestamp": "2026-01-25T23:37:05.920680+00:00", "data": {"market": "0x22ac5f75af18fdb453497fbf7ac0606a09a6fd55b78b2d08aace6b946ad62038", "price_changes": [{"asset_id": "59259495934562596318644973716893809974860301509869285036503555129962149752635", "price": "0.988", "size": "206.38", "side": "SELL", "hash": "7a1c287f4dcf490e4a20f99abff8a6b04fec9c52", "best_bid": "0.931", "best_ask": "0.935"}, {"asset_id": "97449340182256366014320155718265676486703217567849039806162053075113517266910", "price": "0.012", "size": "206.38", "side": "BUY", "hash": "75996ba48925c56faead0d7f015d7a1208e6990b", "best_bid": "0.065", "best_ask": "0.069"}], "timestamp": "1769384225853", "event_type": "price_change"}}
{"_local_timestamp": "2026-01-25T23:37:06.409133+00:00", "data": {"market": "0x22ac5f75af18fdb453497fbf7ac0606a09a6fd55b78b2d08aace6b946ad62038", "price_changes": [{"asset_id": "97449340182256366014320155718265676486703217567849039806162053075113517266910", "price": "0.004", "size": "17.72", "side": "BUY", "hash": "5980b8915d935d375156df0a9d7f40c58e8344d9", "best_bid": "0.065", "best_ask": "0.069"}, {"asset_id": "59259495934562596318644973716893809974860301509869285036503555129962149752635", "price": "0.996", "size": "17.72", "side": "SELL", "hash": "947b7ef28bb10e7a9aaa0ae589f8378b6cef40a3", "best_bid": "0.931", "best_ask": "0.935"}], "timestamp": "1769384226336", "event_type": "price_change"}}
{"_local_timestamp": "2026-01-25T23:37:06.410147+00:00", "data": {"market": "0x22ac5f75af18fdb453497fbf7ac0606a09a6fd55b78b2d08aace6b946ad62038", "price_changes": [{"asset_id": "97449340182256366014320155718265676486703217567849039806162053075113517266910", "price": "0.011", "size": "5.66", "side": "BUY", "hash": "5980b8915d935d375156df0a9d7f40c58e8344d9", "best_bid": "0.065", "best_ask": "0.069"}, {"asset_id": "59259495934562596318644973716893809974860301509869285036503555129962149752635", "price": "0.989", "size": "5.66", "side": "SELL", "hash": "947b7ef28bb10e7a9aaa0ae589f8378b6cef40a3", "best_bid": "0.931", "best_ask": "0.935"}], "timestamp": "1769384226336", "event_type": "price_change"}}
{"_local_timestamp": "2026-01-25T23:37:06.410986+00:00", "data": {"market": "0x22ac5f75af18fdb453497fbf7ac0606a09a6fd55b78b2d08aace6b946ad62038", "price_changes": [{"asset_id": "97449340182256366014320155718265676486703217567849039806162053075113517266910", "price": "0.012", "size": "198.88", "side": "BUY", "hash": "5980b8915d935d375156df0a9d7f40c58e8344d9", "best_bid": "0.065", "best_ask": "0.069"}, {"asset_id": "59259495934562596318644973716893809974860301509869285036503555129962149752635", "price": "0.988", "size": "198.88", "side": "SELL", "hash": "947b7ef28bb10e7a9aaa0ae589f8378b6cef40a3", "best_bid": "0.931", "best_ask": "0.935"}], "timestamp": "1769384226336", "event_type": "price_change"}}
{"_local_timestamp": "2026-01-25T23:37:06.706847+00:00", "data": {"market": "0x22ac5f75af18fdb453497fbf7ac0606a09a6fd55b78b2d08aace6b946ad62038", "price_changes": [{"asset_id": "97449340182256366014320155718265676486703217567849039806162053075113517266910", "price": "0.013", "size": "6.03", "side": "BUY", "hash": "1a49324513aa334274ea9b6d2cf920f229f2e0e1", "best_bid": "0.065", "best_ask": "0.069"}, {"asset_id": "59259495934562596318644973716893809974860301509869285036503555129962149752635", "price": "0.987", "size": "6.03", "side": "SELL", "hash": "716c795a43a1a6a5e40c687f3f3cd4bdf4227671", "best_bid": "0.931", "best_ask": "0.935"}], "timestamp": "1769384226640", "event_type": "price_change"}}
{"_local_timestamp": "2026-01-25T23:37:06.707845+00:00", "data": {"market": "0x22ac5f75af18fdb453497fbf7ac0606a09a6fd55b78b2d08aace6b946ad62038", "price_changes": [{"asset_id": "97449340182256366014320155718265676486703217567849039806162053075113517266910", "price": "0.005", "size": "5.97", "side": "BUY", "hash": "1e90293c4eb64187de6770e4a0fea705daafb4ca", "best_bid": "0.065", "best_ask": "0.069"}, {"asset_id": "59259495934562596318644973716893809974860301509869285036503555129962149752635", "price": "0.995", "size": "5.97", "side": "SELL", "hash": "b15f0d777075cca05b9bcacea07f88af0609a93f", "best_bid": "0.931", "best_ask": "0.935"}], "timestamp": "1769384226641", "event_type": "price_change"}}
{"_local_timestamp": "2026-01-25T23:37:06.708810+00:00", "data": {"market": "0x22ac5f75af18fdb453497fbf7ac0606a09a6fd55b78b2d08aace6b946ad62038", "price_changes": [{"asset_id": "97449340182256366014320155718265676486703217567849039806162053075113517266910", "price": "0.013", "size": "12.06", "side": "BUY", "hash": "32a2ea32af947acca756bb5626fc4403b5ee83c0", "best_bid": "0.065", "best_ask": "0.069"}, {"asset_id": "59259495934562596318644973716893809974860301509869285036503555129962149752635", "price": "0.987", "size": "12.06", "side": "SELL", "hash": "d5e3edb293822073b3233dbecf4b245df9618613", "best_bid": "0.931", "best_ask": "0.935"}], "timestamp": "1769384226642", "event_type": "price_change"}}
{"_local_timestamp": "2026-01-25T23:37:08.064366+00:00", "data": {"market": "0x22ac5f75af18fdb453497fbf7ac0606a09a6fd55b78b2d08aace6b946ad62038", "price_changes": [{"asset_id": "97449340182256366014320155718265676486703217567849039806162053075113517266910", "price": "0.005", "size": "0", "side": "BUY", "hash": "9d7a5137a9bdd9e01e2daed16b515d978d43bf9f", "best_bid": "0.065", "best_ask": "0.069"}, {"asset_id": "59259495934562596318644973716893809974860301509869285036503555129962149752635", "price": "0.995", "size": "0", "side": "SELL", "hash": "db78e3be9d036dd800722883113632868c4e7c2e", "best_bid": "0.931", "best_ask": "0.935"}], "timestamp": "1769384227994", "event_type": "price_change"}}
{"_local_timestamp": "2026-01-25T23:37:08.065467+00:00", "data": {"market": "0x22ac5f75af18fdb453497fbf7ac0606a09a6fd55b78b2d08aace6b946ad62038", "price_changes": [{"asset_id": "97449340182256366014320155718265676486703217567849039806162053075113517266910", "price": "0.011", "size": "0", "side": "BUY", "hash": "9d7a5137a9bdd9e01e2daed16b515d978d43bf9f", "best_bid": "0.065", "best_ask": "0.069"}, {"asset_id": "59259495934562596318644973716893809974860301509869285036503555129962149752635", "price": "0.989", "size": "0", "side": "SELL", "hash": "db78e3be9d036dd800722883113632868c4e7c2e", "best_bid": "0.931", "best_ask": "0.935"}], "timestamp": "1769384227994", "event_type": "price_change"}}
{"_local_timestamp": "2026-01-25T23:37:08.344498+00:00", "data": {"market": "0x22ac5f75af18fdb453497fbf7ac0606a09a6fd55b78b2d08aace6b946ad62038", "price_changes": [{"asset_id": "59259495934562596318644973716893809974860301509869285036503555129962149752635", "price": "0.988", "size": "0", "side": "SELL", "hash": "ebb4a051dac54beed1e258f024d6215e1a922189", "best_bid": "0.931", "best_ask": "0.935"}, {"asset_id": "97449340182256366014320155718265676486703217567849039806162053075113517266910", "price": "0.012", "size": "0", "side": "BUY", "hash": "4fe0c61b21765ba3fff1473e96b47878b3a877d4", "best_bid": "0.065", "best_ask": "0.069"}], "timestamp": "1769384228274", "event_type": "price_change"}}
{"_local_timestamp": "2026-01-25T23:37:08.417457+00:00", "data": {"market": "0x22ac5f75af18fdb453497fbf7ac0606a09a6fd55b78b2d08aace6b946ad62038", "price_changes": [{"asset_id": "97449340182256366014320155718265676486703217567849039806162053075113517266910", "price": "0.009", "size": "138.18", "side": "BUY", "hash": "4d6b8ce5842ad43b3ca89282ea68d274dea9b183", "best_bid": "0.065", "best_ask": "0.069"}, {"asset_id": "59259495934562596318644973716893809974860301509869285036503555129962149752635", "price": "0.991", "size": "138.18", "side": "SELL", "hash": "8a855ec8da295d4560274e5b8e42122ebecbb440", "best_bid": "0.931", "best_ask": "0.935"}], "timestamp": "1769384228348", "event_type": "price_change"}}
{"_local_timestamp": "2026-01-25T23:37:08.418403+00:00", "data": {"market": "0x22ac5f75af18fdb453497fbf7ac0606a09a6fd55b78b2d08aace6b946ad62038", "price_changes": [{"asset_id": "97449340182256366014320155718265676486703217567849039806162053075113517266910", "price": "0.009", "size": "143.3", "side": "BUY", "hash": "c8ca224ddbe4a0d47c7eb26d44b7904a723b09d4", "best_bid": "0.065", "best_ask": "0.069"}, {"asset_id": "59259495934562596318644973716893809974860301509869285036503555129962149752635", "price": "0.991", "size": "143.3", "side": "SELL", "hash": "eae1385c82c89373ac912c44bc2ddf46e4a3c9bd", "best_bid": "0.931", "best_ask": "0.935"}], "timestamp": "1769384228349", "event_type": "price_change"}}
{"_local_timestamp": "2026-01-25T23:37:09.359341+00:00", "data": {"market": "0x22ac5f75af18fdb453497fbf7ac0606a09a6fd55b78b2d08aace6b946ad62038", "price_changes": [{"asset_id": "97449340182256366014320155718265676486703217567849039806162053075113517266910", "price": "0.009", "size": "138.18", "side": "BUY", "hash": "38dd41a49e1fa13889b1d33b5cb5773eedf80563", "best_bid": "0.065", "best_ask": "0.069"}, {"asset_id": "59259495934562596318644973716893809974860301509869285036503555129962149752635", "price": "0.991", "size": "138.18", "side": "SELL", "hash": "2d53ab194281f0dd6598eec50db5f5d8c12e349f", "best_bid": "0.931", "best_ask": "0.935"}], "timestamp": "1769384229286", "event_type": "price_change"}}
{"_local_timestamp": "2026-01-25T23:37:09.361487+00:00", "data": {"market": "0x22ac5f75af18fdb453497fbf7ac0606a09a6fd55b78b2d08aace6b946ad62038", "price_changes": [{"asset_id": "97449340182256366014320155718265676486703217567849039806162053075113517266910", "price": "0.013", "size": "6.03", "side": "BUY", "hash": "38dd41a49e1fa13889b1d33b5cb5773eedf80563", "best_bid": "0.065", "best_ask": "0.069"}, {"asset_id": "59259495934562596318644973716893809974860301509869285036503555129962149752635", "price": "0.987", "size": "6.03", "side": "SELL", "hash": "2d53ab194281f0dd6598eec50db5f5d8c12e349f", "best_bid": "0.931", "best_ask": "0.935"}], "timestamp": "1769384229286", "event_type": "price_change"}}
{"_local_timestamp": "2026-01-25T23:37:09.654174+00:00", "data": {"market": "0x22ac5f75af18fdb453497fbf7ac0606a09a6fd55b78b2d08aace6b946ad62038", "price_changes": [{"asset_id": "97449340182256366014320155718265676486703217567849039806162053075113517266910", "price": "0.004", "size": "25.03", "side": "BUY", "hash": "a9a40a67d33078f78adf6e942286523944b58b8c", "best_bid": "0.065", "best_ask": "0.069"}, {"asset_id": "59259495934562596318644973716893809974860301509869285036503555129962149752635", "price": "0.996", "size": "25.03", "side": "SELL", "hash": "facd2730b6d2338137b7d4f679953640583228fe", "best_bid": "0.931", "best_ask": "0.935"}], "timestamp": "1769384229579", "event_type": "price_change"}}
{"_local_timestamp": "2026-01-25T23:37:09.661457+00:00", "data": {"market": "0x22ac5f75af18fdb453497fbf7ac0606a09a6fd55b78b2d08aace6b946ad62038", "price_changes": [{"asset_id": "97449340182256366014320155718265676486703217567849039806162053075113517266910", "price": "0.011", "size": "8.67", "side": "BUY", "hash": "dc0c1d54c67c7b1f7f26168f100d915d3c59603f", "best_bid": "0.065", "best_ask": "0.069"}, {"asset_id": "59259495934562596318644973716893809974860301509869285036503555129962149752635", "price": "0.989", "size": "8.67", "side": "SELL", "hash": "56ad0e2887df642307831cb816c664b1205e17b9", "best_bid": "0.931", "best_ask": "0.935"}], "timestamp": "1769384229581", "event_type": "price_change"}}
{"_local_timestamp": "2026-01-25T23:37:10.720403+00:00", "data": {"market": "0x22ac5f75af18fdb453497fbf7ac0606a09a6fd55b78b2d08aace6b946ad62038", "price_changes": [{"asset_id": "97449340182256366014320155718265676486703217567849039806162053075113517266910", "price": "0.009", "size": "133.06", "side": "BUY", "hash": "b9b0088e712f2139fd2a132d0f7e45827379cdfe", "best_bid": "0.065", "best_ask": "0.069"}, {"asset_id": "59259495934562596318644973716893809974860301509869285036503555129962149752635", "price": "0.991", "size": "133.06", "side": "SELL", "hash": "be825fadbf5819afcf51782107bd2eab413bd119", "best_bid": "0.931", "best_ask": "0.935"}], "timestamp": "1769384230610", "event_type": "price_change"}}
{"_local_timestamp": "2026-01-25T23:37:10.723093+00:00", "data": {"market": "0x22ac5f75af18fdb453497fbf7ac0606a09a6fd55b78b2d08aace6b946ad62038", "price_changes": [{"asset_id": "97449340182256366014320155718265676486703217567849039806162053075113517266910", "price": "0.013", "size": "0", "side": "BUY", "hash": "b9b0088e712f2139fd2a132d0f7e45827379cdfe", "best_bid": "0.065", "best_ask": "0.069"}, {"asset_id": "59259495934562596318644973716893809974860301509869285036503555129962149752635", "price": "0.987", "size": "0", "side": "SELL", "hash": "be825fadbf5819afcf51782107bd2eab413bd119", "best_bid": "0.931", "best_ask": "0.935"}], "timestamp": "1769384230610", "event_type": "price_change"}}
{"_local_timestamp": "2026-01-25T23:37:10.999687+00:00", "data": {"market": "0x22ac5f75af18fdb453497fbf7ac0606a09a6fd55b78b2d08aace6b946ad62038", "price_changes": [{"asset_id": "97449340182256366014320155718265676486703217567849039806162053075113517266910", "price": "0.014", "size": "8.89", "side": "BUY", "hash": "64d1f7e9c3782d9ba3c5844abe7a428dde337d51", "best_bid": "0.065", "best_ask": "0.069"}, {"asset_id": "59259495934562596318644973716893809974860301509869285036503555129962149752635", "price": "0.986", "size": "8.89", "side": "SELL", "hash": "c40981995f045bf7303c18b3ae5758be0badcee8", "best_bid": "0.931", "best_ask": "0.935"}], "timestamp": "1769384230930", "event_type": "price_change"}}
{"_local_timestamp": "2026-01-25T23:37:11.233839+00:00", "data": {"market": "0x22ac5f75af18fdb453497fbf7ac0606a09a6fd55b78b2d08aace6b946ad62038", "price_changes": [{"asset_id": "59259495934562596318644973716893809974860301509869285036503555129962149752635", "price": "0.987", "size": "198.88", "side": "SELL", "hash": "a352ed145992f3e9623e6ba1b8d18f741d14b88a", "best_bid": "0.931", "best_ask": "0.935"}, {"asset_id": "97449340182256366014320155718265676486703217567849039806162053075113517266910", "price": "0.013", "size": "198.88", "side": "BUY", "hash": "f7720189ec34ff8c347f19f25c6925da777710b8", "best_bid": "0.065", "best_ask": "0.069"}], "timestamp": "1769384231155", "event_type": "price_change"}}
{"_local_timestamp": "2026-01-25T23:37:11.548739+00:00", "data": {"market": "0x22ac5f75af18fdb453497fbf7ac0606a09a6fd55b78b2d08aace6b946ad62038", "price_changes": [{"asset_id": "59259495934562596318644973716893809974860301509869285036503555129962149752635", "price": "0.785", "size": "0", "side": "BUY", "hash": "b2b5fcfb2e970cc95fa1a5db5d387d21554aebe4", "best_bid": "0.931", "best_ask": "0.935"}, {"asset_id": "97449340182256366014320155718265676486703217567849039806162053075113517266910", "price": "0.215", "size": "0", "side": "SELL", "hash": "a30ae8338ea3683b4dc0a996b3d5fae0d53309e1", "best_bid": "0.065", "best_ask": "0.069"}], "timestamp": "1769384231485", "event_type": "price_change"}}
{"_local_timestamp": "2026-01-25T23:37:11.780486+00:00", "data": {"market": "0x22ac5f75af18fdb453497fbf7ac0606a09a6fd55b78b2d08aace6b946ad62038", "price_changes": [{"asset_id": "59259495934562596318644973716893809974860301509869285036503555129962149752635", "price": "0.785", "size": "5", "side": "BUY", "hash": "2b5c2db49addd2b6c8ba6d1f3caee6614d87b320", "best_bid": "0.931", "best_ask": "0.935"}, {"asset_id": "97449340182256366014320155718265676486703217567849039806162053075113517266910", "price": "0.215", "size": "5", "side": "SELL", "hash": "920d70adfcca024d93e017f80bd6dee12a772f6c", "best_bid": "0.065", "best_ask": "0.069"}], "timestamp": "1769384231712", "event_type": "price_change"}}
{"_local_timestamp": "2026-01-25T23:37:12.030107+00:00", "data": {"market": "0x22ac5f75af18fdb453497fbf7ac0606a09a6fd55b78b2d08aace6b946ad62038", "price_changes": [{"asset_id": "97449340182256366014320155718265676486703217567849039806162053075113517266910", "price": "0.011", "size": "0", "side": "BUY", "hash": "92f2ee3ce22a88b627d160ab9176bf0e2a26d53f", "best_bid": "0.065", "best_ask": "0.069"}, {"asset_id": "59259495934562596318644973716893809974860301509869285036503555129962149752635", "price": "0.989", "size": "0", "side": "SELL", "hash": "719707e25ef94c26736d21c5c2f07ed67000c354", "best_bid": "0.931", "best_ask": "0.935"}], "timestamp": "1769384231941", "event_type": "price_change"}}
{"_local_timestamp": "2026-01-25T23:37:12.400688+00:00", "data": {"market": "0x22ac5f75af18fdb453497fbf7ac0606a09a6fd55b78b2d08aace6b946ad62038", "price_changes": [{"asset_id": "97449340182256366014320155718265676486703217567849039806162053075113517266910", "price": "0.01", "size": "293.99", "side": "BUY", "hash": "df14130bb22dc3af77f14ec1ac2ffc6700d72d4e", "best_bid": "0.065", "best_ask": "0.069"}, {"asset_id": "59259495934562596318644973716893809974860301509869285036503555129962149752635", "price": "0.99", "size": "293.99", "side": "SELL", "hash": "22144e371d24feb8a09fd21cd4aa7335fa29ed4d", "best_bid": "0.931", "best_ask": "0.935"}], "timestamp": "1769384232327", "event_type": "price_change"}}
{"_local_timestamp": "2026-01-25T23:37:13.337854+00:00", "data": {"market": "0x22ac5f75af18fdb453497fbf7ac0606a09a6fd55b78b2d08aace6b946ad62038", "price_changes": [{"asset_id": "97449340182256366014320155718265676486703217567849039806162053075113517266910", "price": "0.01", "size": "284.45", "side": "BUY", "hash": "913cb1fbe11272fcf0d6bbb9301b13c9563eab36", "best_bid": "0.065", "best_ask": "0.069"}, {"asset_id": "59259495934562596318644973716893809974860301509869285036503555129962149752635", "price": "0.99", "size": "284.45", "side": "SELL", "hash": "c3e0227b20a34b5b4bc3363ee37af26f3fccbdd2", "best_bid": "0.931", "best_ask": "0.935"}], "timestamp": "1769384233269", "event_type": "price_change"}}
{"_local_timestamp": "2026-01-25T23:37:13.601987+00:00", "data": {"market": "0x22ac5f75af18fdb453497fbf7ac0606a09a6fd55b78b2d08aace6b946ad62038", "price_changes": [{"asset_id": "97449340182256366014320155718265676486703217567849039806162053075113517266910", "price": "0.01", "size": "293.99", "side": "BUY", "hash": "bdced3ec558b2b69d189eb11fed7ac4f09c5e7ae", "best_bid": "0.065", "best_ask": "0.069"}, {"asset_id": "59259495934562596318644973716893809974860301509869285036503555129962149752635", "price": "0.99", "size": "293.99", "side": "SELL", "hash": "be842129f0dd47c8592da60cdd58a1f066a192cf", "best_bid": "0.931", "best_ask": "0.935"}], "timestamp": "1769384233493", "event_type": "price_change"}}
{"_local_timestamp": "2026-01-25T23:37:13.979173+00:00", "data": {"market": "0x22ac5f75af18fdb453497fbf7ac0606a09a6fd55b78b2d08aace6b946ad62038", "price_changes": [{"asset_id": "59259495934562596318644973716893809974860301509869285036503555129962149752635", "price": "0.987", "size": "0", "side": "SELL", "hash": "da6e35796d3c23017e0af059b10c13571074e6de", "best_bid": "0.931", "best_ask": "0.935"}, {"asset_id": "97449340182256366014320155718265676486703217567849039806162053075113517266910", "price": "0.013", "size": "0", "side": "BUY", "hash": "d269bc19c4555b08e7073e2b3d50f742e47bcecb", "best_bid": "0.065", "best_ask": "0.069"}], "timestamp": "1769384233909", "event_type": "price_change"}}
{"_local_timestamp": "2026-01-25T23:37:14.536748+00:00", "data": {"market": "0x22ac5f75af18fdb453497fbf7ac0606a09a6fd55b78b2d08aace6b946ad62038", "price_changes": [{"asset_id": "97449340182256366014320155718265676486703217567849039806162053075113517266910", "price": "0.01", "size": "284.45", "side": "BUY", "hash": "e62bb06219222b69b753a3240782adfd006e5048", "best_bid": "0.065", "best_ask": "0.069"}, {"asset_id": "59259495934562596318644973716893809974860301509869285036503555129962149752635", "price": "0.99", "size": "284.45", "side": "SELL", "hash": "66e9ff5bd6c48ed3113e7367e7f679eef76837bb", "best_bid": "0.931", "best_ask": "0.935"}], "timestamp": "1769384234459", "event_type": "price_change"}}
{"_local_timestamp": "2026-01-25T23:37:14.537796+00:00", "data": {"market": "0x22ac5f75af18fdb453497fbf7ac0606a09a6fd55b78b2d08aace6b946ad62038", "price_changes": [{"asset_id": "97449340182256366014320155718265676486703217567849039806162053075113517266910", "price": "0.014", "size": "0", "side": "BUY", "hash": "e62bb06219222b69b753a3240782adfd006e5048", "best_bid": "0.065", "best_ask": "0.069"}, {"asset_id": "59259495934562596318644973716893809974860301509869285036503555129962149752635", "price": "0.986", "size": "0", "side": "SELL", "hash": "66e9ff5bd6c48ed3113e7367e7f679eef76837bb", "best_bid": "0.931", "best_ask": "0.935"}], "timestamp": "1769384234459", "event_type": "price_change"}}
{"_local_timestamp": "2026-01-25T23:37:15.185700+00:00", "data": {"market": "0x22ac5f75af18fdb453497fbf7ac0606a09a6fd55b78b2d08aace6b946ad62038", "price_changes": [{"asset_id": "97449340182256366014320155718265676486703217567849039806162053075113517266910", "price": "0.011", "size": "9.99", "side": "BUY", "hash": "3e748e9b6ec1ed8971172af892fd5533adba1cc5", "best_bid": "0.065", "best_ask": "0.069"}, {"asset_id": "59259495934562596318644973716893809974860301509869285036503555129962149752635", "price": "0.989", "size": "9.99", "side": "SELL", "hash": "ee730e5e47c7272c17816f80dbd3b33be7c9b03a", "best_bid": "0.931", "best_ask": "0.935"}], "timestamp": "1769384235120", "event_type": "price_change"}}
{"_local_timestamp": "2026-01-25T23:37:15.202028+00:00", "data": {"market": "0x22ac5f75af18fdb453497fbf7ac0606a09a6fd55b78b2d08aace6b946ad62038", "price_changes": [{"asset_id": "97449340182256366014320155718265676486703217567849039806162053075113517266910", "price": "0.011", "size": "19.98", "side": "BUY", "hash": "4d25ff2f7f93ccd40a236c9bef1c636d8aa7ca03", "best_bid": "0.065", "best_ask": "0.069"}, {"asset_id": "59259495934562596318644973716893809974860301509869285036503555129962149752635", "price": "0.989", "size": "19.98", "side": "SELL", "hash": "b6a42df14ece4fec6e398f08377ea61684679856", "best_bid": "0.931", "best_ask": "0.935"}], "timestamp": "1769384235125", "event_type": "price_change"}}
{"_local_timestamp": "2026-01-25T23:37:16.718000+00:00", "data": {"market": "0x22ac5f75af18fdb453497fbf7ac0606a09a6fd55b78b2d08aace6b946ad62038", "price_changes": [{"asset_id": "59259495934562596318644973716893809974860301509869285036503555129962149752635", "price": "0.988", "size": "198.88", "side": "SELL", "hash": "3e22b02322382cc621e25e591e5ee43b6582ee8c", "best_bid": "0.931", "best_ask": "0.935"}, {"asset_id": "97449340182256366014320155718265676486703217567849039806162053075113517266910", "price": "0.012", "size": "198.88", "side": "BUY", "hash": "4067424923c683ad16fecac1de7b5fb0e665600f", "best_bid": "0.065", "best_ask": "0.069"}], "timestamp": "1769384236647", "event_type": "price_change"}}
{"_local_timestamp": "2026-01-25T23:37:17.536042+00:00", "data": {"market": "0x22ac5f75af18fdb453497fbf7ac0606a09a6fd55b78b2d08aace6b946ad62038", "price_changes": [{"asset_id": "97449340182256366014320155718265676486703217567849039806162053075113517266910", "price": "0.004", "size": "17.72", "side": "BUY", "hash": "342f4bb77de486ea26def413f08e08571e29f87f", "best_bid": "0.065", "best_ask": "0.069"}, {"asset_id": "59259495934562596318644973716893809974860301509869285036503555129962149752635", "price": "0.996", "size": "17.72", "side": "SELL", "hash": "c54dfbfc6a3ab65eec3d18d0c22944fcc4ce2826", "best_bid": "0.931", "best_ask": "0.935"}], "timestamp": "1769384237467", "event_type": "price_change"}}
{"_local_timestamp": "2026-01-25T23:37:17.537005+00:00", "data": {"market": "0x22ac5f75af18fdb453497fbf7ac0606a09a6fd55b78b2d08aace6b946ad62038", "price_changes": [{"asset_id": "97449340182256366014320155718265676486703217567849039806162053075113517266910", "price": "0.011", "size": "9.99", "side": "BUY", "hash": "342f4bb77de486ea26def413f08e08571e29f87f", "best_bid": "0.065", "best_ask": "0.069"}, {"asset_id": "59259495934562596318644973716893809974860301509869285036503555129962149752635", "price": "0.989", "size": "9.99", "side": "SELL", "hash": "c54dfbfc6a3ab65eec3d18d0c22944fcc4ce2826", "best_bid": "0.931", "best_ask": "0.935"}], "timestamp": "1769384237467", "event_type": "price_change"}}
{"_local_timestamp": "2026-01-25T23:37:17.975782+00:00", "data": {"market": "0x22ac5f75af18fdb453497fbf7ac0606a09a6fd55b78b2d08aace6b946ad62038", "price_changes": [{"asset_id": "97449340182256366014320155718265676486703217567849039806162053075113517266910", "price": "0.013", "size": "5.35", "side": "BUY", "hash": "991260be5cfe2af85fc1be207d8a6aa774b1477d", "best_bid": "0.065", "best_ask": "0.069"}, {"asset_id": "59259495934562596318644973716893809974860301509869285036503555129962149752635", "price": "0.987", "size": "5.35", "side": "SELL", "hash": "41c397c7b9bf625f236adeaaeda528af4274c175", "best_bid": "0.931", "best_ask": "0.935"}], "timestamp": "1769384237909", "event_type": "price_change"}}
{"_local_timestamp": "2026-01-25T23:37:17.976822+00:00", "data": {"market": "0x22ac5f75af18fdb453497fbf7ac0606a09a6fd55b78b2d08aace6b946ad62038", "price_changes": [{"asset_id": "97449340182256366014320155718265676486703217567849039806162053075113517266910", "price": "0.013", "size": "10.7", "side": "BUY", "hash": "022e174b2ac7dc6a05413b1317acf07db9d5af60", "best_bid": "0.065", "best_ask": "0.069"}, {"asset_id": "59259495934562596318644973716893809974860301509869285036503555129962149752635", "price": "0.987", "size": "10.7", "side": "SELL", "hash": "02be9525d6bae3044a90051cf470dbe137935c1f", "best_bid": "0.931", "best_ask": "0.935"}], "timestamp": "1769384237910", "event_type": "price_change"}}
{"_local_timestamp": "2026-01-25T23:37:19.143737+00:00", "data": {"market": "0x22ac5f75af18fdb453497fbf7ac0606a09a6fd55b78b2d08aace6b946ad62038", "price_changes": [{"asset_id": "97449340182256366014320155718265676486703217567849039806162053075113517266910", "price": "0.011", "size": "0", "side": "BUY", "hash": "13391f463d6882ef45ce5cb11b81c4edf2915eaa", "best_bid": "0.065", "best_ask": "0.069"}, {"asset_id": "59259495934562596318644973716893809974860301509869285036503555129962149752635", "price": "0.989", "size": "0", "side": "SELL", "hash": "00174b14ad04caebde5f6e33099e95c62c1a1824", "best_bid": "0.931", "best_ask": "0.935"}], "timestamp": "1769384239077", "event_type": "price_change"}}
{"_local_timestamp": "2026-01-25T23:37:19.616495+00:00", "data": {"market": "0x22ac5f75af18fdb453497fbf7ac0606a09a6fd55b78b2d08aace6b946ad62038", "price_changes": [{"asset_id": "97449340182256366014320155718265676486703217567849039806162053075113517266910", "price": "0.009", "size": "139.17", "side": "BUY", "hash": "2995676caf9c889f7a0c8acd84f1a11a74311b82", "best_bid": "0.065", "best_ask": "0.069"}, {"asset_id": "59259495934562596318644973716893809974860301509869285036503555129962149752635", "price": "0.991", "size": "139.17", "side": "SELL", "hash": "e3126a6335a1a9c51e418e58feffca086ef4f768", "best_bid": "0.931", "best_ask": "0.935"}], "timestamp": "1769384239543", "event_type": "price_change"}}
{"_local_timestamp": "2026-01-25T23:37:19.618305+00:00", "data": {"market": "0x22ac5f75af18fdb453497fbf7ac0606a09a6fd55b78b2d08aace6b946ad62038", "price_changes": [{"asset_id": "97449340182256366014320155718265676486703217567849039806162053075113517266910", "price": "0.009", "size": "145.28", "side": "BUY", "hash": "3704b8f06106b2c4f9dd0ea84e34a847c264fa14", "best_bid": "0.065", "best_ask": "0.069"}, {"asset_id": "59259495934562596318644973716893809974860301509869285036503555129962149752635", "price": "0.991", "size": "145.28", "side": "SELL", "hash": "e5e34e03c80f1f52604319400612081b13fa3011", "best_bid": "0.931", "best_ask": "0.935"}], "timestamp": "1769384239544", "event_type": "price_change"}}
{"_local_timestamp": "2026-01-25T23:37:19.886711+00:00", "data": {"market": "0x22ac5f75af18fdb453497fbf7ac0606a09a6fd55b78b2d08aace6b946ad62038", "price_changes": [{"asset_id": "59259495934562596318644973716893809974860301509869285036503555129962149752635", "price": "0.785", "size": "0", "side": "BUY", "hash": "5797654f15d7a65c917bee45dbb3d8de872a739d", "best_bid": "0.931", "best_ask": "0.935"}, {"asset_id": "97449340182256366014320155718265676486703217567849039806162053075113517266910", "price": "0.215", "size": "0", "side": "SELL", "hash": "68eb2f596f37e30e88bd8e7f3a36002130824405", "best_bid": "0.065", "best_ask": "0.069"}], "timestamp": "1769384239821", "event_type": "price_change"}}
{"_local_timestamp": "2026-01-25T23:37:20.336223+00:00", "data": {"market": "0x22ac5f75af18fdb453497fbf7ac0606a09a6fd55b78b2d08aace6b946ad62038", "price_changes": [{"asset_id": "59259495934562596318644973716893809974860301509869285036503555129962149752635", "price": "0.785", "size": "5", "side": "BUY", "hash": "ef23c856bd1a39067b790e918606148371a16d63", "best_bid": "0.931", "best_ask": "0.935"}, {"asset_id": "97449340182256366014320155718265676486703217567849039806162053075113517266910", "price": "0.215", "size": "5", "side": "SELL", "hash": "a6cd5288139a6ecc264ee88ca2cc4250afce1c24", "best_bid": "0.065", "best_ask": "0.069"}], "timestamp": "1769384240265", "event_type": "price_change"}}
{"_local_timestamp": "2026-01-25T23:37:21.154979+00:00", "data": {"market": "0x22ac5f75af18fdb453497fbf7ac0606a09a6fd55b78b2d08aace6b946ad62038", "price_changes": [{"asset_id": "59259495934562596318644973716893809974860301509869285036503555129962149752635", "price": "0.988", "size": "0", "side": "SELL", "hash": "c1ba6f9c330bb345935338bac00c3df003843f9d", "best_bid": "0.931", "best_ask": "0.935"}, {"asset_id": "97449340182256366014320155718265676486703217567849039806162053075113517266910", "price": "0.012", "size": "0", "side": "BUY", "hash": "d8e04ad7473be7c0f934aaa73bd935c4ab61464b", "best_bid": "0.065", "best_ask": "0.069"}], "timestamp": "1769384241087", "event_type": "price_change"}}
{"_local_timestamp": "2026-01-25T23:37:21.534298+00:00", "data": {"market": "0x22ac5f75af18fdb453497fbf7ac0606a09a6fd55b78b2d08aace6b946ad62038", "price_changes": [{"asset_id": "97449340182256366014320155718265676486703217567849039806162053075113517266910", "price": "0.009", "size": "139.17", "side": "BUY", "hash": "759f927a8e843fd832bfb31b6afb270cf2d2ec91", "best_bid": "0.065", "best_ask": "0.069"}, {"asset_id": "59259495934562596318644973716893809974860301509869285036503555129962149752635", "price": "0.991", "size": "139.17", "side": "SELL", "hash": "226eef15445dc5e0fd65c44e8b32f2a6a72d4151", "best_bid": "0.931", "best_ask": "0.935"}], "timestamp": "1769384241460", "event_type": "price_change"}}
{"_local_timestamp": "2026-01-25T23:37:21.958980+00:00", "data": {"market": "0x22ac5f75af18fdb453497fbf7ac0606a09a6fd55b78b2d08aace6b946ad62038", "price_changes": [{"asset_id": "97449340182256366014320155718265676486703217567849039806162053075113517266910", "price": "0.004", "size": "24.59", "side": "BUY", "hash": "e828f518c25b95ec79719df16bb6d0a5ef377da9", "best_bid": "0.065", "best_ask": "0.069"}, {"asset_id": "59259495934562596318644973716893809974860301509869285036503555129962149752635", "price": "0.996", "size": "24.59", "side": "SELL", "hash": "49a5d693f0a782788091bade4761a54eb1562fb4", "best_bid": "0.931", "best_ask": "0.935"}], "timestamp": "1769384241893", "event_type": "price_change"}}
{"_local_timestamp": "2026-01-25T23:37:21.969446+00:00", "data": {"market": "0x22ac5f75af18fdb453497fbf7ac0606a09a6fd55b78b2d08aace6b946ad62038", "price_changes": [{"asset_id": "97449340182256366014320155718265676486703217567849039806162053075113517266910", "price": "0.004", "size": "31.46", "side": "BUY", "hash": "8e11dce45c239fa06aa1cecad38209857d7d2689", "best_bid": "0.065", "best_ask": "0.069"}, {"asset_id": "59259495934562596318644973716893809974860301509869285036503555129962149752635", "price": "0.996", "size": "31.46", "side": "SELL", "hash": "89e7bb2674d0573e2f3bd6865656f002c49e4843", "best_bid": "0.931", "best_ask": "0.935"}], "timestamp": "1769384241900", "event_type": "price_change"}}
{"_local_timestamp": "2026-01-25T23:37:23.381706+00:00", "data": {"market": "0x22ac5f75af18fdb453497fbf7ac0606a09a6fd55b78b2d08aace6b946ad62038", "price_changes": [{"asset_id": "97449340182256366014320155718265676486703217567849039806162053075113517266910", "price": "0.004", "size": "24.46", "side": "BUY", "hash": "97481322a686e6ab77c8efded0c3b0735b078f08", "best_bid": "0.065", "best_ask": "0.069"}, {"asset_id": "59259495934562596318644973716893809974860301509869285036503555129962149752635", "price": "0.996", "size": "24.46", "side": "SELL", "hash": "3ed801b0efe0c45cbf14c160fb464814e960cb86", "best_bid": "0.931", "best_ask": "0.935"}], "timestamp": "1769384243312", "event_type": "price_change"}}
{"_local_timestamp": "2026-01-25T23:37:23.389859+00:00", "data": {"market": "0x22ac5f75af18fdb453497fbf7ac0606a09a6fd55b78b2d08aace6b946ad62038", "price_changes": [{"asset_id": "97449340182256366014320155718265676486703217567849039806162053075113517266910", "price": "0.009", "size": "133.06", "side": "BUY", "hash": "97481322a686e6ab77c8efded0c3b0735b078f08", "best_bid": "0.065", "best_ask": "0.069"}, {"asset_id": "59259495934562596318644973716893809974860301509869285036503555129962149752635", "price": "0.991", "size": "133.06", "side": "SELL", "hash": "3ed801b0efe0c45cbf14c160fb464814e960cb86", "best_bid": "0.931", "best_ask": "0.935"}], "timestamp": "1769384243312", "event_type": "price_change"}}
{"_local_timestamp": "2026-01-25T23:37:23.390857+00:00", "data": {"market": "0x22ac5f75af18fdb453497fbf7ac0606a09a6fd55b78b2d08aace6b946ad62038", "price_changes": [{"asset_id": "97449340182256366014320155718265676486703217567849039806162053075113517266910", "price": "0.013", "size": "5.35", "side": "BUY", "hash": "97481322a686e6ab77c8efded0c3b0735b078f08", "best_bid": "0.065", "best_ask": "0.069"}, {"asset_id": "59259495934562596318644973716893809974860301509869285036503555129962149752635", "price": "0.987", "size": "5.35", "side": "SELL", "hash": "3ed801b0efe0c45cbf14c160fb464814e960cb86", "best_bid": "0.931", "best_ask": "0.935"}], "timestamp": "1769384243312", "event_type": "price_change"}}
{"_local_timestamp": "2026-01-25T23:37:23.484743+00:00", "data": {"market": "0x22ac5f75af18fdb453497fbf7ac0606a09a6fd55b78b2d08aace6b946ad62038", "price_changes": [{"asset_id": "59259495934562596318644973716893809974860301509869285036503555129962149752635", "price": "0.989", "size": "198.88", "side": "SELL", "hash": "7a26b1a54cd983f729c8183b9179bbfb921f5eaa", "best_bid": "0.931", "best_ask": "0.935"}, {"asset_id": "97449340182256366014320155718265676486703217567849039806162053075113517266910", "price": "0.011", "size": "198.88", "side": "BUY", "hash": "b489e1e4f4dcbad1055e0288efc8c25fdd5280d8", "best_bid": "0.065", "best_ask": "0.069"}], "timestamp": "1769384243411", "event_type": "price_change"}}
{"_local_timestamp": "2026-01-25T23:37:23.785603+00:00", "data": {"market": "0x22ac5f75af18fdb453497fbf7ac0606a09a6fd55b78b2d08aace6b946ad62038", "price_changes": [{"asset_id": "97449340182256366014320155718265676486703217567849039806162053075113517266910", "price": "0.011", "size": "205.81", "side": "BUY", "hash": "3277a3b930c692b7af632b211fe55f0e6ad5fa55", "best_bid": "0.065", "best_ask": "0.069"}, {"asset_id": "59259495934562596318644973716893809974860301509869285036503555129962149752635", "price": "0.989", "size": "205.81", "side": "SELL", "hash": "387a0573cedf3f87ec7c7b2805fcb3bf895ff478", "best_bid": "0.931", "best_ask": "0.935"}], "timestamp": "1769384243719", "event_type": "price_change"}}
{"_local_timestamp": "2026-01-25T23:37:24.049682+00:00", "data": {"market": "0x22ac5f75af18fdb453497fbf7ac0606a09a6fd55b78b2d08aace6b946ad62038", "price_changes": [{"asset_id": "97449340182256366014320155718265676486703217567849039806162053075113517266910", "price": "0.011", "size": "212.74", "side": "BUY", "hash": "c7e1ff877dabddba0ce74a471e1d525b18aba60d", "best_bid": "0.065", "best_ask": "0.069"}, {"asset_id": "59259495934562596318644973716893809974860301509869285036503555129962149752635", "price": "0.989", "size": "212.74", "side": "SELL", "hash": "3e0620f0fba6f6d1d8b3516b344abe21bfa9d7b3", "best_bid": "0.931", "best_ask": "0.935"}], "timestamp": "1769384243720", "event_type": "price_change"}}
