{"_local_timestamp": "2026-01-25T23:33:21.791207+00:00", "data": [{"market": "0x387abd33ec2706bf5e2d5089556962f899c76f2e53e72de416ee097f5e0cde5f", "asset_id": "92117937101612979995545967061706012469465044784784255337936477146012148388257", "timestamp": "1769383959304", "hash": "fa2359a03ce15c4ade2cc6645b47dec69f5baae4", "bids": [{"price": "0.01", "size": "5509.69"}, {"price": "0.02", "size": "2200"}, {"price": "0.03", "size": "10.12"}, {"price": "0.05", "size": "30"}, {"price": "0.06", "size": "33"}, {"price": "0.08", "size": "800"}, {"price": "0.09", "size": "400"}, {"price": "0.1", "size": "1250"}, {"price": "0.11", "size": "305.44"}, {"price": "0.14", "size": "242.85"}, {"price": "0.15", "size": "550"}, {"price": "0.19", "size": "168.42"}, {"price": "0.2", "size": "700"}, {"price": "0.23", "size": "815.73"}, {"price": "0.24", "size": "1748"}, {"price": "0.25", "size": "300"}, {"price": "0.28", "size": "92.85"}, {"price": "0.3", "size": "350"}, {"price": "0.33", "size": "72.72"}, {"price": "0.37", "size": "4455"}, {"price": "0.38", "size": "52.63"}, {"price": "0.39", "size": "1543"}, {"price": "0.48", "size": "160"}, {"price": "0.65", "size": "190.9"}, {"price": "0.75", "size": "1000"}, {"price": "0.87", "size": "984.6"}, {"price": "0.91", "size": "710.79"}, {"price": "0.92", "size": "981.23"}, {"price": "0.93", "size": "628.21"}], "asks": [{"price": "0.99", "size": "1020.27"}, {"price": "0.98", "size": "5267.5"}, {"price": "0.97", "size": "1739.1"}, {"price": "0.96", "size": "1232.87"}, {"price": "0.95", "size": "2183.12"}, {"price": "0.94", "size": "650.53"}], "event_type": "book", "last_trade_price": "0.070"}, {"market": "0x387abd33ec2706bf5e2d5089556962f899c76f2e53e72de416ee097f5e0cde5f", "asset_id": "87834167452414513395250782274912164961953327877923232604083507081218756225485", "timestamp": "1769383959304", "hash": "08889f36909e30273905f6acf8dcd7f154d56beb", "bids": [{"price": "0.01", "size": "1020.27"}, {"price": "0.02", "size": "5267.5"}, {"price": "0.03", "size": "1739.1"}, {"price": "0.04", "size": "1232.87"}, {"price": "0.05", "size": "2183.12"}, {"price": "0.06", "size": "650.53"}], "asks": [{"price": "0.99", "size": "5509.69"}, {"price": "0.98", "size": "2200"}, {"price": "0.97", "size": "10.12"}, {"price": "0.95", "size": "30"}, {"price": "0.94", "size": "33"}, {"price": "0.92", "size": "800"}, {"price": "0.91", "size": "400"}, {"price": "0.9", "size": "1250"}, {"price": "0.89", "size": "305.44"}, {"price": "0.86", "size": "242.85"}, {"price": "0.85", "size": "550"}, {"price": "0.81", "size": "168.42"}, {"price": "0.8", "size": "700"}, {"price": "0.77", "size": "815.73"}, {"price": "0.76", "size": "1748"}, {"price": "0.75", "size": "300"}, {"price": "0.72", "size": "92.85"}, {"price": "0.7", "size": "350"}, {"price": "0.67", "size": "72.72"}, {"price": "0.63", "size": "4455"}, {"price": "0.62", "size": "52.63"}, {"price": "0.61", "size": "1543"}, {"price": "0.52", "size": "160"}, {"price": "0.35", "size": "190.9"}, {"price": "0.25", "size": "1000"}, {"price": "0.13", "size": "984.6"}, {"price": "0.09", "size": "710.79"}, {"price": "0.08", "size": "981.23"}, {"price": "0.07", "size": "628.21"}], "event_type": "book", "last_trade_price": "0.070"}]}
{"_local_timestamp": "2026-01-25T23:33:23.896840+00:00", "data": {"market": "0x387abd33ec2706bf5e2d5089556962f899c76f2e53e72de416ee097f5e0cde5f", "price_changes": [{"asset_id": "92117937101612979995545967061706012469465044784784255337936477146012148388257", "price": "0.25", "size": "200", "side": "BUY", "hash": "7875df07383b601ba4684733b952c44aaab6d03e", "best_bid": "0.93", "best_ask": "0.94"}, {"asset_id": "87834167452414513395250782274912164961953327877923232604083507081218756225485", "price": "0.75", "size": "200", "side": "SELL", "hash": "f0703d65d0405aeb0504a1e048f3dc0eb137abb4", "best_bid": "0.06", "best_ask": "0.07"}], "timestamp": "1769384003781", "event_type": "price_change"}}
{"_local_timestamp": "2026-01-25T23:33:24.366936+00:00", "data": {"market": "0x387abd33ec2706bf5e2d5089556962f899c76f2e53e72de416ee097f5e0cde5f", "price_changes": [{"asset_id": "92117937101612979995545967061706012469465044784784255337936477146012148388257", "price": "0.24", "size": "1848", "side": "BUY", "hash": "536e0979ca131fd0cbfa1c56620ad02a1f7f09a1", "best_bid": "0.93", "best_ask": "0.94"}, {"asset_id": "87834167452414513395250782274912164961953327877923232604083507081218756225485", "price": "0.76", "size": "1848", "side": "SELL", "hash": "4b4d8075e64dbe596dc4269b143442f6844cbce4", "best_bid": "0.06", "best_ask": "0.07"}], "timestamp": "1769384004264", "event_type": "price_change"}}
{"_local_timestamp": "2026-01-25T23:33:40.960773+00:00", "data": {"market": "0x387abd33ec2706bf5e2d5089556962f899c76f2e53e72de416ee097f5e0cde5f", "price_changes": [{"asset_id": "87834167452414513395250782274912164961953327877923232604083507081218756225485", "price": "0.02", "size": "5250", "side": "BUY", "hash": "782763bba56d896ffbe1ee5ea0866454cc62be74", "best_bid": "0.06", "best_ask": "0.07"}, {"asset_id": "92117937101612979995545967061706012469465044784784255337936477146012148388257", "price": "0.98", "size": "5250", "side": "SELL", "hash": "c827a146c072bfd6ea8c76e40571e9e206826df4", "best_bid": "0.93", "best_ask": "0.94"}], "timestamp": "1769384020860", "event_type": "price_change"}}
{"_local_timestamp": "2026-01-25T23:33:40.964389+00:00", "data": {"market": "0x387abd33ec2706bf5e2d5089556962f899c76f2e53e72de416ee097f5e0cde5f", "price_changes": [{"asset_id": "87834167452414513395250782274912164961953327877923232604083507081218756225485", "price": "0.03", "size": "1728", "side": "BUY", "hash": "782763bba56d896ffbe1ee5ea0866454cc62be74", "best_bid": "0.06", "best_ask": "0.07"}, {"asset_id": "92117937101612979995545967061706012469465044784784255337936477146012148388257", "price": "0.97", "size": "1728", "side": "SELL", "hash": "c827a146c072bfd6ea8c76e40571e9e206826df4", "best_bid": "0.93", "best_ask": "0.94"}], "timestamp": "1769384020860", "event_type": "price_change"}}
{"_local_timestamp": "2026-01-25T23:33:40.965563+00:00", "data": {"market": "0x387abd33ec2706bf5e2d5089556962f899c76f2e53e72de416ee097f5e0cde5f", "price_changes": [{"asset_id": "87834167452414513395250782274912164961953327877923232604083507081218756225485", "price": "0.04", "size": "1224.95", "side": "BUY", "hash": "782763bba56d896ffbe1ee5ea0866454cc62be74", "best_bid": "0.06", "best_ask": "0.07"}, {"asset_id": "92117937101612979995545967061706012469465044784784255337936477146012148388257", "price": "0.96", "size": "1224.95", "side": "SELL", "hash": "c827a146c072bfd6ea8c76e40571e9e206826df4", "best_bid": "0.93", "best_ask": "0.94"}], "timestamp": "1769384020860", "event_type": "price_change"}}
{"_local_timestamp": "2026-01-25T23:33:41.222023+00:00", "data": {"market": "0x387abd33ec2706bf5e2d5089556962f899c76f2e53e72de416ee097f5e0cde5f", "price_changes": [{"asset_id": "87834167452414513395250782274912164961953327877923232604083507081218756225485", "price": "0.02", "size": "5267.5", "side": "BUY", "hash": "75939c4c8118756c5b95970a5a13186653c30c43", "best_bid": "0.06", "best_ask": "0.07"}, {"asset_id": "92117937101612979995545967061706012469465044784784255337936477146012148388257", "price": "0.98", "size": "5267.5", "side": "SELL", "hash": "cdc8f63335dcad3410d59e6da01f66a74c3f1f7f", "best_bid": "0.93", "best_ask": "0.94"}], "timestamp": "1769384021144", "event_type": "price_change"}}
{"_local_timestamp": "2026-01-25T23:33:41.222647+00:00", "data": {"market": "0x387abd33ec2706bf5e2d5089556962f899c76f2e53e72de416ee097f5e0cde5f", "price_changes": [{"asset_id": "87834167452414513395250782274912164961953327877923232604083507081218756225485", "price": "0.03", "size": "1739.1", "side": "BUY", "hash": "851071cbb7053824f0f74b50f8bb0cb02c23aded", "best_bid": "0.06", "best_ask": "0.07"}, {"asset_id": "92117937101612979995545967061706012469465044784784255337936477146012148388257", "price": "0.97", "size": "1739.1", "side": "SELL", "hash": "64f35b07a8b573a06700f9f97f42f43ef02f7e52", "best_bid": "0.93", "best_ask": "0.94"}], "timestamp": "1769384021144", "event_type": "price_change"}}
{"_local_timestamp": "2026-01-25T23:33:41.223010+00:00", "data": {"market": "0x387abd33ec2706bf5e2d5089556962f899c76f2e53e72de416ee097f5e0cde5f", "price_changes": [{"asset_id": "87834167452414513395250782274912164961953327877923232604083507081218756225485", "price": "0.04", "size": "1232.87", "side": "BUY", "hash": "33e379ced89b3d0142d15728bc0aefc674fe65c5", "best_bid": "0.06", "best_ask": "0.07"}, {"asset_id": "92117937101612979995545967061706012469465044784784255337936477146012148388257", "price": "0.96", "size": "1232.87", "side": "SELL", "hash": "1bbfc4a9eba9d037f6f351a9eec2bbe18aa0d3be", "best_bid": "0.93", "best_ask": "0.94"}], "timestamp": "1769384021145", "event_type": "price_change"}}
{"_local_timestamp": "2026-01-25T23:34:19.936335+00:00", "data": {"market": "0x387abd33ec2706bf5e2d5089556962f899c76f2e53e72de416ee097f5e0cde5f", "price_changes": [{"asset_id": "92117937101612979995545967061706012469465044784784255337936477146012148388257", "price": "0.24", "size": "100", "side": "BUY", "hash": "6376d20a0817537488ded4056ef7d1469aa24d62", "best_bid": "0.93", "best_ask": "0.94"}, {"asset_id": "87834167452414513395250782274912164961953327877923232604083507081218756225485", "price": "0.76", "size": "100", "side": "SELL", "hash": "128292b68846bda0a7642c87d78adf29205426f3", "best_bid": "0.06", "best_ask": "0.07"}], "timestamp": "1769384059755", "event_type": "price_change"}}
{"_local_timestamp": "2026-01-25T23:34:44.303414+00:00", "data": {"market": "0x387abd33ec2706bf5e2d5089556962f899c76f2e53e72de416ee097f5e0cde5f", "price_changes": [{"asset_id": "87834167452414513395250782274912164961953327877923232604083507081218756225485", "price": "0.02", "size": "5250", "side": "BUY", "hash": "349357533423f92d5a83cc4ac6190d0f381a18b4", "best_bid": "0.06", "best_ask": "0.07"}, {"asset_id": "92117937101612979995545967061706012469465044784784255337936477146012148388257", "price": "0.98", "size": "5250", "side": "SELL", "hash": "6f50cd64da42c4aeb1b2e11fa3b3bc919b7bcf04", "best_bid": "0.93", "best_ask": "0.94"}], "timestamp": "1769384084227", "event_type": "price_change"}}
{"_local_timestamp": "2026-01-25T23:34:44.304183+00:00", "data": {"market": "0x387abd33ec2706bf5e2d5089556962f899c76f2e53e72de416ee097f5e0cde5f", "price_changes": [{"asset_id": "87834167452414513395250782274912164961953327877923232604083507081218756225485", "price": "0.03", "size": "1728", "side": "BUY", "hash": "349357533423f92d5a83cc4ac6190d0f381a18b4", "best_bid": "0.06", "best_ask": "0.07"}, {"asset_id": "92117937101612979995545967061706012469465044784784255337936477146012148388257", "price": "0.97", "size": "1728", "side": "SELL", "hash": "6f50cd64da42c4aeb1b2e11fa3b3bc919b7bcf04", "best_bid": "0.93", "best_ask": "0.94"}], "timestamp": "1769384084227", "event_type": "price_change"}}
{"_local_timestamp": "2026-01-25T23:34:44.304491+00:00", "data": {"market": "0x387abd33ec2706bf5e2d5089556962f899c76f2e53e72de416ee097f5e0cde5f", "price_changes": [{"asset_id": "87834167452414513395250782274912164961953327877923232604083507081218756225485", "price": "0.04", "size": "1224.95", "side": "BUY", "hash": "349357533423f92d5a83cc4ac6190d0f381a18b4", "best_bid": "0.06", "best_ask": "0.07"}, {"asset_id": "92117937101612979995545967061706012469465044784784255337936477146012148388257", "price": "0.96", "size": "1224.95", "side": "SELL", "hash": "6f50cd64da42c4aeb1b2e11fa3b3bc919b7bcf04", "best_bid": "0.93", "best_ask": "0.94"}], "timestamp": "1769384084227", "event_type": "price_change"}}
{"_local_timestamp": "2026-01-25T23:34:46.438812+00:00", "data": {"market": "0x387abd33ec2706bf5e2d5089556962f899c76f2e53e72de416ee097f5e0cde5f", "price_changes": [{"asset_id": "87834167452414513395250782274912164961953327877923232604083507081218756225485", "price": "0.03", "size": "1739.1", "side": "BUY", "hash": "398ad35d7de9163382a1a4dc917d66f216fb3e2c", "best_bid": "0.06", "best_ask": "0.07"}, {"asset_id": "92117937101612979995545967061706012469465044784784255337936477146012148388257", "price": "0.97", "size": "1739.1", "side": "SELL", "hash": "c2237200dd13ead1cda47f790e787cd3751ae29d", "best_bid": "0.93", "best_ask": "0.94"}], "timestamp": "1769384086370", "event_type": "price_change"}}
{"_local_timestamp": "2026-01-25T23:34:46.439207+00:00", "data": {"market": "0x387abd33ec2706bf5e2d5089556962f899c76f2e53e72de416ee097f5e0cde5f", "price_changes": [{"asset_id": "87834167452414513395250782274912164961953327877923232604083507081218756225485", "price": "0.02", "size": "5267.5", "side": "BUY", "hash": "6f411f9a4fda9406bbc18e719a8fbeb06647da78", "best_bid": "0.06", "best_ask": "0.07"}, {"asset_id": "92117937101612979995545967061706012469465044784784255337936477146012148388257", "price": "0.98", "size": "5267.5", "side": "SELL", "hash": "92a16dd115e5b473136e830c51b4fb5c74de9ba4", "best_bid": "0.93", "best_ask": "0.94"}], "timestamp": "1769384086371", "event_type": "price_change"}}
{"_local_timestamp": "2026-01-25T23:34:46.439485+00:00", "data": {"market": "0x387abd33ec2706bf5e2d5089556962f899c76f2e53e72de416ee097f5e0cde5f", "price_changes": [{"asset_id": "87834167452414513395250782274912164961953327877923232604083507081218756225485", "price": "0.04", "size": "1232.87", "side": "BUY", "hash": "8a26a5b6d865b5be52c7145e195bde231db081e8", "best_bid": "0.06", "best_ask": "0.07"}, {"asset_id": "92117937101612979995545967061706012469465044784784255337936477146012148388257", "price": "0.96", "size": "1232.87", "side": "SELL", "hash": "5ad17853ba4c0b5b3c521eddad5c4c76c20db36c", "best_bid": "0.93", "best_ask": "0.94"}], "timestamp": "1769384086372", "event_type": "price_change"}}
{"_local_timestamp": "2026-01-25T23:34:55.379118+00:00", "data": {"market": "0x387abd33ec2706bf5e2d5089556962f899c76f2e53e72de416ee097f5e0cde5f", "price_changes": [{"asset_id": "92117937101612979995545967061706012469465044784784255337936477146012148388257", "price": "0.26", "size": "1614", "side": "BUY", "hash": "4547d32aeba884fe0bc353e744b9765c3ae564e5", "best_bid": "0.93", "best_ask": "0.94"}, {"asset_id": "87834167452414513395250782274912164961953327877923232604083507081218756225485", "price": "0.74", "size": "1614", "side": "SELL", "hash": "ee657e4e88dde8b4d9774cf317cb1e37aa83b8a9", "best_bid": "0.06", "best_ask": "0.07"}], "timestamp": "1769384095269", "event_type": "price_change"}}
{"_local_timestamp": "2026-01-25T23:35:23.938029+00:00", "data": {"market": "0x387abd33ec2706bf5e2d5089556962f899c76f2e53e72de416ee097f5e0cde5f", "price_changes": [{"asset_id": "92117937101612979995545967061706012469465044784784255337936477146012148388257", "price": "0.24", "size": "0", "side": "BUY", "hash": "c3a92dc15b5101a90e03e2932a7a2fc2fe7e270d", "best_bid": "0.93", "best_ask": "0.94"}, {"asset_id": "87834167452414513395250782274912164961953327877923232604083507081218756225485", "price": "0.76", "size": "0", "side": "SELL", "hash": "114c1cad85cac745a6593e2d90a5037d20e79abf", "best_bid": "0.06", "best_ask": "0.07"}], "timestamp": "1769384123680", "event_type": "price_change"}}
{"_local_timestamp": "2026-01-25T23:35:24.465438+00:00", "data": {"market": "0x387abd33ec2706bf5e2d5089556962f899c76f2e53e72de416ee097f5e0cde5f", "price_changes": [{"asset_id": "92117937101612979995545967061706012469465044784784255337936477146012148388257", "price": "0.23", "size": "915.73", "side": "BUY", "hash": "a7d9fc0da5e17f304810a320ab86a2e4e10310db", "best_bid": "0.93", "best_ask": "0.94"}, {"asset_id": "87834167452414513395250782274912164961953327877923232604083507081218756225485", "price": "0.77", "size": "915.73", "side": "SELL", "hash": "067022f5bd13b5e263c9894c2eb9d9bc59006610", "best_bid": "0.06", "best_ask": "0.07"}], "timestamp": "1769384124070", "event_type": "price_change"}}
{"_local_timestamp": "2026-01-25T23:35:26.744606+00:00", "data": {"market": "0x387abd33ec2706bf5e2d5089556962f899c76f2e53e72de416ee097f5e0cde5f", "price_changes": [{"asset_id": "92117937101612979995545967061706012469465044784784255337936477146012148388257", "price": "0.25", "size": "150", "side": "BUY", "hash": "f34180bdccd56ce4c4d1e3a8543f47e03c0d0f2f", "best_bid": "0.93", "best_ask": "0.94"}, {"asset_id": "87834167452414513395250782274912164961953327877923232604083507081218756225485", "price": "0.75", "size": "150", "side": "SELL", "hash": "275cd62696ce4c4efd1353230e85fe9897eaa8c3", "best_bid": "0.06", "best_ask": "0.07"}], "timestamp": "1769384126520", "event_type": "price_change"}}
{"_local_timestamp": "2026-01-25T23:35:27.665274+00:00", "data": {"market": "0x387abd33ec2706bf5e2d5089556962f899c76f2e53e72de416ee097f5e0cde5f", "price_changes": [{"asset_id": "92117937101612979995545967061706012469465044784784255337936477146012148388257", "price": "0.24", "size": "50", "side": "BUY", "hash": "c17977502babc69fcbd6d494af459a771aa99b85", "best_bid": "0.93", "best_ask": "0.94"}, {"asset_id": "87834167452414513395250782274912164961953327877923232604083507081218756225485", "price": "0.76", "size": "50", "side": "SELL", "hash": "33409296d923b8722bbd1b960859ee214e19cea8", "best_bid": "0.06", "best_ask": "0.07"}], "timestamp": "1769384126876", "event_type": "price_change"}}
{"_local_timestamp": "2026-01-25T23:35:49.115905+00:00", "data": {"market": "0x387abd33ec2706bf5e2d5089556962f899c76f2e53e72de416ee097f5e0cde5f", "price_changes": [{"asset_id": "87834167452414513395250782274912164961953327877923232604083507081218756225485", "price": "0.03", "size": "1405.1", "side": "BUY", "hash": "3461a9ae8a8bc09c1c5396e4adbcedf902712daa", "best_bid": "0.06", "best_ask": "0.07"}, {"asset_id": "92117937101612979995545967061706012469465044784784255337936477146012148388257", "price": "0.97", "size": "1405.1", "side": "SELL", "hash": "a55e5014806f79afc5cded037297480ea0ddfb53", "best_bid": "0.93", "best_ask": "0.94"}], "timestamp": "1769384149000", "event_type": "price_change"}}
{"_local_timestamp": "2026-01-25T23:35:49.116715+00:00", "data": {"market": "0x387abd33ec2706bf5e2d5089556962f899c76f2e53e72de416ee097f5e0cde5f", "price_changes": [{"asset_id": "87834167452414513395250782274912164961953327877923232604083507081218756225485", "price": "0.02", "size": "4267.5", "side": "BUY", "hash": "be4b76c1a7c03e1261830dadb1b422aeae573b70", "best_bid": "0.06", "best_ask": "0.07"}, {"asset_id": "92117937101612979995545967061706012469465044784784255337936477146012148388257", "price": "0.98", "size": "4267.5", "side": "SELL", "hash": "f50f055685af2d7b637c290bce1eacd0c35caa3c", "best_bid": "0.93", "best_ask": "0.94"}], "timestamp": "1769384149006", "event_type": "price_change"}}
{"_local_timestamp": "2026-01-25T23:35:56.448395+00:00", "data": {"market": "0x387abd33ec2706bf5e2d5089556962f899c76f2e53e72de416ee097f5e0cde5f", "price_changes": [{"asset_id": "92117937101612979995545967061706012469465044784784255337936477146012148388257", "price": "0.25", "size": "100", "side": "BUY", "hash": "f6a0e39f825b9b9cc78140fb757aebdc2d58c764", "best_bid": "0.93", "best_ask": "0.94"}, {"asset_id": "87834167452414513395250782274912164961953327877923232604083507081218756225485", "price": "0.75", "size": "100", "side": "SELL", "hash": "db551a585051784cc76efa197e6d10d8a2f86631", "best_bid": "0.06", "best_ask": "0.07"}], "timestamp": "1769384156293", "event_type": "price_change"}}
{"_local_timestamp": "2026-01-25T23:35:56.847431+00:00", "data": {"market": "0x387abd33ec2706bf5e2d5089556962f899c76f2e53e72de416ee097f5e0cde5f", "price_changes": [{"asset_id": "92117937101612979995545967061706012469465044784784255337936477146012148388257", "price": "0.24", "size": "100", "side": "BUY", "hash": "442555fc9fa1571ed44a20d43b794b90e297ad07", "best_bid": "0.93", "best_ask": "0.94"}, {"asset_id": "87834167452414513395250782274912164961953327877923232604083507081218756225485", "price": "0.76", "size": "100", "side": "SELL", "hash": "c4e924af5b65c55a0cb378d37a2acd02b6e7d5b6", "best_bid": "0.06", "best_ask": "0.07"}], "timestamp": "1769384156718", "event_type": "price_change"}}
{"_local_timestamp": "2026-01-25T23:36:02.375037+00:00", "data": {"market": "0x387abd33ec2706bf5e2d5089556962f899c76f2e53e72de416ee097f5e0cde5f", "price_changes": [{"asset_id": "92117937101612979995545967061706012469465044784784255337936477146012148388257", "price": "0.3", "size": "300", "side": "BUY", "hash": "e456481a795209b4b369a9897f047627d1a94d60", "best_bid": "0.93", "best_ask": "0.94"}, {"asset_id": "87834167452414513395250782274912164961953327877923232604083507081218756225485", "price": "0.7", "size": "300", "side": "SELL", "hash": "e572a6b3dcf8efa113ddc02d5e1a8bbd035d4061", "best_bid": "0.06", "best_ask": "0.07"}], "timestamp": "1769384162262", "event_type": "price_change"}}
{"_local_timestamp": "2026-01-25T23:36:02.689828+00:00", "data": {"market": "0x387abd33ec2706bf5e2d5089556962f899c76f2e53e72de416ee097f5e0cde5f", "price_changes": [{"asset_id": "92117937101612979995545967061706012469465044784784255337936477146012148388257", "price": "0.26", "size": "1664", "side": "BUY", "hash": "3f3df6df32487496f8dac4f2348fb828e6155fe8", "best_bid": "0.93", "best_ask": "0.94"}, {"asset_id": "87834167452414513395250782274912164961953327877923232604083507081218756225485", "price": "0.74", "size": "1664", "side": "SELL", "hash": "4e3f670f88fa15c7c6f1b6bc780a3ba6d109c525", "best_bid": "0.06", "best_ask": "0.07"}], "timestamp": "1769384162560", "event_type": "price_change"}}
{"_local_timestamp": "2026-01-25T23:36:05.545725+00:00", "data": {"market": "0x387abd33ec2706bf5e2d5089556962f899c76f2e53e72de416ee097f5e0cde5f", "price_changes": [{"asset_id": "87834167452414513395250782274912164961953327877923232604083507081218756225485", "price": "0.02", "size": "5267.5", "side": "BUY", "hash": "a824c05e96983ebd14f1d809d61c2104780dc800", "best_bid": "0.06", "best_ask": "0.07"}, {"asset_id": "92117937101612979995545967061706012469465044784784255337936477146012148388257", "price": "0.98", "size": "5267.5", "side": "SELL", "hash": "38a123322777961abd04570e1ace0d7d44ab38f7", "best_bid": "0.93", "best_ask": "0.94"}], "timestamp": "1769384165464", "event_type": "price_change"}}
{"_local_timestamp": "2026-01-25T23:36:05.550881+00:00", "data": {"market": "0x387abd33ec2706bf5e2d5089556962f899c76f2e53e72de416ee097f5e0cde5f", "price_changes": [{"asset_id": "87834167452414513395250782274912164961953327877923232604083507081218756225485", "price": "0.03", "size": "1739.1", "side": "BUY", "hash": "0e1e467a830fcbfb8e96b734a91565cb7033c65f", "best_bid": "0.06", "best_ask": "0.07"}, {"asset_id": "92117937101612979995545967061706012469465044784784255337936477146012148388257", "price": "0.97", "size": "1739.1", "side": "SELL", "hash": "5efcf1f6a2fb9c30e42d213257f3104a32b83b5b", "best_bid": "0.93", "best_ask": "0.94"}], "timestamp": "1769384165465", "event_type": "price_change"}}
{"_local_timestamp": "2026-01-25T23:36:55.289086+00:00", "data": {"market": "0x387abd33ec2706bf5e2d5089556962f899c76f2e53e72de416ee097f5e0cde5f", "price_changes": [{"asset_id": "92117937101612979995545967061706012469465044784784255337936477146012148388257", "price": "0.25", "size": "0", "side": "BUY", "hash": "86e56ef1439a1b28a700036b9887ecc2d413bcce", "best_bid": "0.93", "best_ask": "0.94"}, {"asset_id": "87834167452414513395250782274912164961953327877923232604083507081218756225485", "price": "0.75", "size": "0", "side": "SELL", "hash": "a287f45719bcb9204c0c6e742217cd9828de35b8", "best_bid": "0.06", "best_ask": "0.07"}], "timestamp": "1769384215217", "event_type": "price_change"}}
{"_local_timestamp": "2026-01-25T23:36:56.135304+00:00", "data": {"market": "0x387abd33ec2706bf5e2d5089556962f899c76f2e53e72de416ee097f5e0cde5f", "price_changes": [{"asset_id": "92117937101612979995545967061706012469465044784784255337936477146012148388257", "price": "0.23", "size": "1015.73", "side": "BUY", "hash": "2c1c01aca7c7eac1f152bef22eae6d7af795dd32", "best_bid": "0.93", "best_ask": "0.94"}, {"asset_id": "87834167452414513395250782274912164961953327877923232604083507081218756225485", "price": "0.77", "size": "1015.73", "side": "SELL", "hash": "ecbf068ae550d020adb47c978caeba1efe8f3212", "best_bid": "0.06", "best_ask": "0.07"}], "timestamp": "1769384215709", "event_type": "price_change"}}
{"_local_timestamp": "2026-01-25T23:37:12.872938+00:00", "data": {"market": "0x387abd33ec2706bf5e2d5089556962f899c76f2e53e72de416ee097f5e0cde5f", "price_changes": [{"asset_id": "92117937101612979995545967061706012469465044784784255337936477146012148388257", "price": "0.24", "size": "50", "side": "BUY", "hash": "9c1eaaee9e525b94ed48a28a39b72085e01ff2a9", "best_bid": "0.93", "best_ask": "0.94"}, {"asset_id": "87834167452414513395250782274912164961953327877923232604083507081218756225485", "price": "0.76", "size": "50", "side": "SELL", "hash": "91cef910d768b1738d4f679130e08c5f88e68a9d", "best_bid": "0.06", "best_ask": "0.07"}], "timestamp": "1769384232797", "event_type": "price_change"}}
{"_local_timestamp": "2026-01-25T23:37:13.422617+00:00", "data": {"market": "0x387abd33ec2706bf5e2d5089556962f899c76f2e53e72de416ee097f5e0cde5f", "price_changes": [{"asset_id": "92117937101612979995545967061706012469465044784784255337936477146012148388257", "price": "0.26", "size": "1714", "side": "BUY", "hash": "b2beb4fc3a4fb53bea918f04400014c78da61d41", "best_bid": "0.93", "best_ask": "0.94"}, {"asset_id": "87834167452414513395250782274912164961953327877923232604083507081218756225485", "price": "0.74", "size": "1714", "side": "SELL", "hash": "651c0ff90b8cae73f0d1b44e5caeeaf39dd39077", "best_bid": "0.06", "best_ask": "0.07"}], "timestamp": "1769384233350", "event_type": "price_change"}}
{"_local_timestamp": "2026-01-25T23:37:35.269716+00:00", "data": {"market": "0x387abd33ec2706bf5e2d5089556962f899c76f2e53e72de416ee097f5e0cde5f", "price_changes": [{"asset_id": "92117937101612979995545967061706012469465044784784255337936477146012148388257", "price": "0.26", "size": "100", "side": "BUY", "hash": "1d727d2775428bbfcbea01430ff02d605c4d88cc", "best_bid": "0.93", "best_ask": "0.94"}, {"asset_id": "87834167452414513395250782274912164961953327877923232604083507081218756225485", "price": "0.74", "size": "100", "side": "SELL", "hash": "52d897c6d279c8b07de986a83e1b93150c311e8f", "best_bid": "0.06", "best_ask": "0.07"}], "timestamp": "1769384255119", "event_type": "price_change"}}
{"_local_timestamp": "2026-01-25T23:38:21.276594+00:00", "data": {"market": "0x387abd33ec2706bf5e2d5089556962f899c76f2e53e72de416ee097f5e0cde5f", "price_changes": [{"asset_id": "92117937101612979995545967061706012469465044784784255337936477146012148388257", "price": "0.24", "size": "0", "side": "BUY", "hash": "e3714a962d82b609a9d4c2b34b9175c02a400c09", "best_bid": "0.93", "best_ask": "0.94"}, {"asset_id": "87834167452414513395250782274912164961953327877923232604083507081218756225485", "price": "0.76", "size": "0", "side": "SELL", "hash": "acf6f889bafaf092cf6b86c200445e2d2aa04aa8", "best_bid": "0.06", "best_ask": "0.07"}], "timestamp": "1769384301125", "event_type": "price_change"}}
{"_local_timestamp": "2026-01-25T23:38:21.680178+00:00", "data": {"market": "0x387abd33ec2706bf5e2d5089556962f899c76f2e53e72de416ee097f5e0cde5f", "price_changes": [{"asset_id": "92117937101612979995545967061706012469465044784784255337936477146012148388257", "price": "0.26", "size": "150", "side": "BUY", "hash": "5e26314dffa4df8d72c8b5fc6fd36faf163dad71", "best_bid": "0.93", "best_ask": "0.94"}, {"asset_id": "87834167452414513395250782274912164961953327877923232604083507081218756225485", "price": "0.74", "size": "150", "side": "SELL", "hash": "be1c02154baad2eb24a5c5c4c4733d23d8a0d330", "best_bid": "0.06", "best_ask": "0.07"}], "timestamp": "1769384301485", "event_type": "price_change"}}
{"_local_timestamp": "2026-01-25T23:38:38.125796+00:00", "data": {"market": "0x387abd33ec2706bf5e2d5089556962f899c76f2e53e72de416ee097f5e0cde5f", "price_changes": [{"asset_id": "92117937101612979995545967061706012469465044784784255337936477146012148388257", "price": "0.24", "size": "1748", "side": "BUY", "hash": "afd0d16aa9221fbb500ae2ffc1740a629a70ea35", "best_bid": "0.93", "best_ask": "0.94"}, {"asset_id": "87834167452414513395250782274912164961953327877923232604083507081218756225485", "price": "0.76", "size": "1748", "side": "SELL", "hash": "026b8984f5d7db76f895717f05e01fdc005584ae", "best_bid": "0.06", "best_ask": "0.07"}], "timestamp": "1769384318013", "event_type": "price_change"}}
{"_local_timestamp": "2026-01-25T23:38:41.468049+00:00", "data": {"market": "0x387abd33ec2706bf5e2d5089556962f899c76f2e53e72de416ee097f5e0cde5f", "price_changes": [{"asset_id": "92117937101612979995545967061706012469465044784784255337936477146012148388257", "price": "0.26", "size": "100", "side": "BUY", "hash": "2e67eeac21c85468a118883a31f0c9e483f822e5", "best_bid": "0.93", "best_ask": "0.94"}, {"asset_id": "87834167452414513395250782274912164961953327877923232604083507081218756225485", "price": "0.74", "size": "100", "side": "SELL", "hash": "a88e042b23861ae1781f678835137734e07a325a", "best_bid": "0.06", "best_ask": "0.07"}], "timestamp": "1769384321390", "event_type": "price_change"}}
{"_local_timestamp": "2026-01-25T23:38:41.577610+00:00", "data": {"market": "0x387abd33ec2706bf5e2d5089556962f899c76f2e53e72de416ee097f5e0cde5f", "price_changes": [{"asset_id": "87834167452414513395250782274912164961953327877923232604083507081218756225485", "price": "0.02", "size": "5250", "side": "BUY", "hash": "0119d9190e62fe17cc1adbd54dc4f1353d50011b", "best_bid": "0.06", "best_ask": "0.07"}, {"asset_id": "92117937101612979995545967061706012469465044784784255337936477146012148388257", "price": "0.98", "size": "5250", "side": "SELL", "hash": "b732a3c2e377371498e495bae3dfce7e25c815cb", "best_bid": "0.93", "best_ask": "0.94"}], "timestamp": "1769384321430", "event_type": "price_change"}}
{"_local_timestamp": "2026-01-25T23:38:41.578031+00:00", "data": {"market": "0x387abd33ec2706bf5e2d5089556962f899c76f2e53e72de416ee097f5e0cde5f", "price_changes": [{"asset_id": "87834167452414513395250782274912164961953327877923232604083507081218756225485", "price": "0.03", "size": "1728", "side": "BUY", "hash": "0119d9190e62fe17cc1adbd54dc4f1353d50011b", "best_bid": "0.06", "best_ask": "0.07"}, {"asset_id": "92117937101612979995545967061706012469465044784784255337936477146012148388257", "price": "0.97", "size": "1728", "side": "SELL", "hash": "b732a3c2e377371498e495bae3dfce7e25c815cb", "best_bid": "0.93", "best_ask": "0.94"}], "timestamp": "1769384321430", "event_type": "price_change"}}
{"_local_timestamp": "2026-01-25T23:38:41.578447+00:00", "data": {"market": "0x387abd33ec2706bf5e2d5089556962f899c76f2e53e72de416ee097f5e0cde5f", "price_changes": [{"asset_id": "87834167452414513395250782274912164961953327877923232604083507081218756225485", "price": "0.04", "size": "1224.95", "side": "BUY", "hash": "0119d9190e62fe17cc1adbd54dc4f1353d50011b", "best_bid": "0.06", "best_ask": "0.07"}, {"asset_id": "92117937101612979995545967061706012469465044784784255337936477146012148388257", "price": "0.96", "size": "1224.95", "side": "SELL", "hash": "b732a3c2e377371498e495bae3dfce7e25c815cb", "best_bid": "0.93", "best_ask": "0.94"}], "timestamp": "1769384321430", "event_type": "price_change"}}
{"_local_timestamp": "2026-01-25T23:38:41.832871+00:00", "data": {"market": "0x387abd33ec2706bf5e2d5089556962f899c76f2e53e72de416ee097f5e0cde5f", "price_changes": [{"asset_id": "92117937101612979995545967061706012469465044784784255337936477146012148388257", "price": "0.3", "size": "350", "side": "BUY", "hash": "137e99a17956e128e94905f80d191a4fb2475b87", "best_bid": "0.93", "best_ask": "0.94"}, {"asset_id": "87834167452414513395250782274912164961953327877923232604083507081218756225485", "price": "0.7", "size": "350", "side": "SELL", "hash": "3e5be1c0e83e3b8d9de88b2df71389aae6b0e5a6", "best_bid": "0.06", "best_ask": "0.07"}], "timestamp": "1769384321676", "event_type": "price_change"}}
{"_local_timestamp": "2026-01-25T23:38:42.031704+00:00", "data": {"market": "0x387abd33ec2706bf5e2d5089556962f899c76f2e53e72de416ee097f5e0cde5f", "price_changes": [{"asset_id": "87834167452414513395250782274912164961953327877923232604083507081218756225485", "price": "0.03", "size": "1739.1", "side": "BUY", "hash": "ace50ddd6767c6922aa04aedd015640239a454a9", "best_bid": "0.06", "best_ask": "0.07"}, {"asset_id": "92117937101612979995545967061706012469465044784784255337936477146012148388257", "price": "0.97", "size": "1739.1", "side": "SELL", "hash": "a68bd544df6ee35bf1fbdc75e14768b29709af40", "best_bid": "0.93", "best_ask": "0.94"}], "timestamp": "1769384321926", "event_type": "price_change"}}
{"_local_timestamp": "2026-01-25T23:38:42.052999+00:00", "data": {"market": "0x387abd33ec2706bf5e2d5089556962f899c76f2e53e72de416ee097f5e0cde5f", "price_changes": [{"asset_id": "87834167452414513395250782274912164961953327877923232604083507081218756225485", "price": "0.02", "size": "5267.5", "side": "BUY", "hash": "408597fd2bef7ac963f9c0fc4929167361b2259f", "best_bid": "0.06", "best_ask": "0.07"}, {"asset_id": "92117937101612979995545967061706012469465044784784255337936477146012148388257", "price": "0.98", "size": "5267.5", "side": "SELL", "hash": "7160ee89e174552d88d451bf4afefe590d372548", "best_bid": "0.93", "best_ask": "0.94"}], "timestamp": "1769384321928", "event_type": "price_change"}}
{"_local_timestamp": "2026-01-25T23:38:42.069095+00:00", "data": {"market": "0x387abd33ec2706bf5e2d5089556962f899c76f2e53e72de416ee097f5e0cde5f", "price_changes": [{"asset_id": "87834167452414513395250782274912164961953327877923232604083507081218756225485", "price": "0.04", "size": "1232.87", "side": "BUY", "hash": "238d9d843df34f85bc175d5babe8c15ccbea53ce", "best_bid": "0.06", "best_ask": "0.07"}, {"asset_id": "92117937101612979995545967061706012469465044784784255337936477146012148388257", "price": "0.96", "size": "1232.87", "side": "SELL", "hash": "ce28dea37112f14c081eb57432df8b03b81b8f1a", "best_bid": "0.93", "best_ask": "0.94"}], "timestamp": "1769384321931", "event_type": "price_change"}}
{"_local_timestamp": "2026-01-25T23:39:17.016790+00:00", "data": {"market": "0x387abd33ec2706bf5e2d5089556962f899c76f2e53e72de416ee097f5e0cde5f", "price_changes": [{"asset_id": "92117937101612979995545967061706012469465044784784255337936477146012148388257", "price": "0.23", "size": "915.73", "side": "BUY", "hash": "a100227e7261320e3db19b911f44f800fd5d2b0e", "best_bid": "0.93", "best_ask": "0.94"}, {"asset_id": "87834167452414513395250782274912164961953327877923232604083507081218756225485", "price": "0.77", "size": "915.73", "side": "SELL", "hash": "5a4f6520d98f7bceace572a44ab73980fc505d24", "best_bid": "0.06", "best_ask": "0.07"}], "timestamp": "1769384356920", "event_type": "price_change"}}
{"_local_timestamp": "2026-01-25T23:39:17.374280+00:00", "data": {"market": "0x387abd33ec2706bf5e2d5089556962f899c76f2e53e72de416ee097f5e0cde5f", "price_changes": [{"asset_id": "92117937101612979995545967061706012469465044784784255337936477146012148388257", "price": "0.24", "size": "1848", "side": "BUY", "hash": "70b504cb45c9a962c4b11eac35e9b87e4517ac49", "best_bid": "0.93", "best_ask": "0.94"}, {"asset_id": "87834167452414513395250782274912164961953327877923232604083507081218756225485", "price": "0.76", "size": "1848", "side": "SELL", "hash": "ba479ea8ec62dd405e3f560a7a0285d91a33c117", "best_bid": "0.06", "best_ask": "0.07"}], "timestamp": "1769384357179", "event_type": "price_change"}}
{"_local_timestamp": "2026-01-25T23:39:20.574503+00:00", "data": {"market": "0x387abd33ec2706bf5e2d5089556962f899c76f2e53e72de416ee097f5e0cde5f", "price_changes": [{"asset_id": "92117937101612979995545967061706012469465044784784255337936477146012148388257", "price": "0.24", "size": "100", "side": "BUY", "hash": "7bba3fcd25f1c9fb3c452622846bcc4bc21c6315", "best_bid": "0.93", "best_ask": "0.94"}, {"asset_id": "87834167452414513395250782274912164961953327877923232604083507081218756225485", "price": "0.76", "size": "100", "side": "SELL", "hash": "7173cd069aeeb692ffb5b36f5217c7193268fcfd", "best_bid": "0.06", "best_ask": "0.07"}], "timestamp": "1769384360340", "event_type": "price_change"}}
{"_local_timestamp": "2026-01-25T23:39:22.566783+00:00", "data": {"market": "0x387abd33ec2706bf5e2d5089556962f899c76f2e53e72de416ee097f5e0cde5f", "price_changes": [{"asset_id": "92117937101612979995545967061706012469465044784784255337936477146012148388257", "price": "0.23", "size": "815.73", "side": "BUY", "hash": "29a002b1f628351dce4477423e6e01ae09223c52", "best_bid": "0.93", "best_ask": "0.94"}, {"asset_id": "87834167452414513395250782274912164961953327877923232604083507081218756225485", "price": "0.77", "size": "815.73", "side": "SELL", "hash": "5a5782f5aabafda3b9a5f63fbc10cfdc982c4740", "best_bid": "0.06", "best_ask": "0.07"}], "timestamp": "1769384362222", "event_type": "price_change"}}
{"_local_timestamp": "2026-01-25T23:39:22.918097+00:00", "data": {"market": "0x387abd33ec2706bf5e2d5089556962f899c76f2e53e72de416ee097f5e0cde5f", "price_changes": [{"asset_id": "92117937101612979995545967061706012469465044784784255337936477146012148388257", "price": "0.26", "size": "200", "side": "BUY", "hash": "b6a1430b1e31135a87d36ed6359e3612c2a4a5d0", "best_bid": "0.93", "best_ask": "0.94"}, {"asset_id": "87834167452414513395250782274912164961953327877923232604083507081218756225485", "price": "0.74", "size": "200", "side": "SELL", "hash": "8f045b7242944a09c8dcc77fe30c65eb75cfbefe", "best_bid": "0.06", "best_ask": "0.07"}], "timestamp": "1769384362720", "event_type": "price_change"}}
{"_local_timestamp": "2026-01-25T23:39:54.516551+00:00", "data": {"market": "0x387abd33ec2706bf5e2d5089556962f899c76f2e53e72de416ee097f5e0cde5f", "price_changes": [{"asset_id": "92117937101612979995545967061706012469465044784784255337936477146012148388257", "price": "0.27", "size": "1554", "side": "BUY", "hash": "f357839ae9530cf9b46e5a23406fada0f4fd97d2", "best_bid": "0.93", "best_ask": "0.94"}, {"asset_id": "87834167452414513395250782274912164961953327877923232604083507081218756225485", "price": "0.73", "size": "1554", "side": "SELL", "hash": "fb6b20b425975bd7625db158df3e61c494fd1e3b", "best_bid": "0.06", "best_ask": "0.07"}], "timestamp": "1769384394444", "event_type": "price_change"}}
{"_local_timestamp": "2026-01-25T23:39:56.390979+00:00", "data": {"market": "0x387abd33ec2706bf5e2d5089556962f899c76f2e53e72de416ee097f5e0cde5f", "price_changes": [{"asset_id": "92117937101612979995545967061706012469465044784784255337936477146012148388257", "price": "0.24", "size": "0", "side": "BUY", "hash": "45568d66355c00616da0afe25b569eb2530c49fd", "best_bid": "0.93", "best_ask": "0.94"}, {"asset_id": "87834167452414513395250782274912164961953327877923232604083507081218756225485", "price": "0.76", "size": "0", "side": "SELL", "hash": "46a97521877ae780786f1d2730b08537d0725fbd", "best_bid": "0.06", "best_ask": "0.07"}], "timestamp": "1769384396317", "event_type": "price_change"}}
{"_local_timestamp": "2026-01-25T23:39:56.710788+00:00", "data": {"market": "0x387abd33ec2706bf5e2d5089556962f899c76f2e53e72de416ee097f5e0cde5f", "price_changes": [{"asset_id": "92117937101612979995545967061706012469465044784784255337936477146012148388257", "price": "0.23", "size": "915.73", "side": "BUY", "hash": "03def8581f1e06e10bee5d7c2f73629be4a71116", "best_bid": "0.93", "best_ask": "0.94"}, {"asset_id": "87834167452414513395250782274912164961953327877923232604083507081218756225485", "price": "0.77", "size": "915.73", "side": "SELL", "hash": "6efdc6cf827578694d7f1a3c2e732bc5337c84f6", "best_bid": "0.06", "best_ask": "0.07"}], "timestamp": "1769384396603", "event_type": "price_change"}}
